Workbook

Sheet Team View
C2: Team
C3: FOKUS
C5: Team Statistics | J5: All Rounds | M5: Pistols | P5: Gun | S5: Anti Eco | V5: Eco | AC5: Post Plant | AI5: Retake
C6: Maps | D6: Comp | I6: x | J6: Plays | K6: Win | L6: Loss | M6: rW% | N6: aW% | O6: dW% | P6: rW% | Q6: aW% | R6: dW% | S6: rW% | T6: aW% | U6: dW% | V6: rW% | W6: aW% | X6: dW% | AC6: Map | AD6: post scens | AE6: t rounds | AF6: post /Map | AG6: post rW% | AH6: rank | AI6: ret. scens | AJ6: ct rounds | AK6: ret. /Map | AL6: ret. rW% | AM6: rank
C7: Abyss | D7: =IFERROR(INDEX(doubles!$E$2:$E$431,MATCH(C7&"_"&$C$3,doubles!$S$2:$S$431&"_"&doubles!$C$2:$C$431,0)),"") | I7: =IFERROR(COUNTIFS(doubles!$C$2:$C$431,$C$3,doubles!$B$2:$B$431,C7,doubles!$E$2:$E$431,D7),"") | J7: =COUNTIFS(doubles!$C$2:$C$431,$C$3,doubles!$B$2:$B$431,C7) | K7: =COUNTIFS(doubles!$C$2:$C$431,$C$3,doubles!$B$2:$B$431,C7,doubles!$R$2:$R$431,$C$3) | L7: =J7-K7 | M7: =IFERROR((SUMIFS(doubles!$M$2:$M$431,doubles!$C$2:$C$431,$C$3,doubles!$B$2:$B$431,C7)+SUMIFS(doubles!$O$2:$O$431,doubles!$C$2:$C$431,$C$3,doubles!$B$2:$B$431,C7))/(SUMIFS(doubles!$M$2:$M$431,doubles!$C$2:$C$431,$C$3,doubles!$B$2:$B$431,C7)+SUMIFS(doubles!$N$2:$N$431,doubles!$C$2:$C$431,$C$3,doubles!$B$2:$B$431,C7)+SUMIFS(doubles!$O$2:$O$431,doubles!$C$2:$C$431,$C$3,doubles!$B$2:$B$431,C7)+SUMIFS(doubles!$P$2:$P$431,doubles!$C$2:$C$431,$C$3,doubles!$B$2:$B$431,C7)),"") | N7: =IFERROR(SUMIFS(doubles!$M$2:$M$431,doubles!$C$2:$C$431,$C$3,doubles!$B$2:$B$431,C7)/(SUMIFS(doubles!$M$2:$M$431,doubles!$C$2:$C$431,$C$3,doubles!$B$2:$B$431,C7)+SUMIFS(doubles!$N$2:$N$431,doubles!$C$2:$C$431,$C$3,doubles!$B$2:$B$431,C7)),"") | O7: =IFERROR(SUMIFS(doubles!$O$2:$O$431,doubles!$C$2:$C$431,$C$3,doubles!$B$2:$B$431,C7)/(SUMIFS(doubles!$O$2:$O$431,doubles!$C$2:$C$431,$C$3,doubles!$B$2:$B$431,C7)+SUMIFS(doubles!$P$2:$P$431,doubles!$C$2:$C$431,$C$3,doubles!$B$2:$B$431,C7)),"") | P7: =IFERROR((SUMIFS(doubles!$K$2:$K$431,doubles!$C$2:$C$431,$C$3,doubles!$B$2:$B$431,C7)+SUMIFS(doubles!$L$2:$L$431,doubles!$C$2:$C$431,$C$3,doubles!$B$2:$B$431,C7))/(2*COUNTIFS(doubles!$C$2:$C$431,$C$3,doubles!$B$2:$B$431,C7)),"") | Q7: =IFERROR(SUMIFS(doubles!$K$2:$K$431,doubles!$C$2:$C$431,$C$3,doubles!$B$2:$B$431,C7)/COUNTIFS(doubles!$C$2:$C$431,$C$3,doubles!$B$2:$B$431,C7),"") | R7: =IFERROR(SUMIFS(doubles!$L$2:$L$431,doubles!$C$2:$C$431,$C$3,doubles!$B$2:$B$431,C7)/COUNTIFS(doubles!$C$2:$C$431,$C$3,doubles!$B$2:$B$431,C7),"") | S7: =IFERROR((SUMIFS('Gun v Gun'!$C$2:$C$500,'Gun v Gun'!$A$2:$A$500,$C$3,'Gun v Gun'!$B$2:$B$500,C7,'Gun v Gun'!$F$2:$F$500,"atk")+SUMIFS('Gun v Gun'!$C$2:$C$500,'Gun v Gun'!$A$2:$A$500,$C$3,'Gun v Gun'!$B$2:$B$500,C7,'Gun v Gun'!$F$2:$F$500,"def"))/(SUMIFS('Gun v Gun'!$C$2:$C$500,'Gun v Gun'!$A$2:$A$500,$C$3,'Gun v Gun'!$B$2:$B$500,C7,'Gun v Gun'!$F$2:$F$500,"atk")+SUMIFS('Gun v Gun'!$D$2:$D$500,'Gun v Gun'!$A$2:$A$500,$C$3,'Gun v Gun'!$B$2:$B$500,C7,'Gun v Gun'!$F$2:$F$500,"atk")+SUMIFS('Gun v Gun'!$C$2:$C$500,'Gun v Gun'!$A$2:$A$500,$C$3,'Gun v Gun'!$B$2:$B$500,C7,'Gun v Gun'!$F$2:$F$500,"def")+SUMIFS('Gun v Gun'!$D$2:$D$500,'Gun v Gun'!$A$2:$A$500,$C$3,'Gun v Gun'!$B$2:$B$500,C7,'Gun v Gun'!$F$2:$F$500,"def")),"") | T7: =IFERROR(SUMIFS('Gun v Gun'!$C$2:$C$500,'Gun v Gun'!$A$2:$A$500,$C$3,'Gun v Gun'!$B$2:$B$500,C7,'Gun v Gun'!$F$2:$F$500,"atk")/(SUMIFS('Gun v Gun'!$C$2:$C$500,'Gun v Gun'!$A$2:$A$500,$C$3,'Gun v Gun'!$B$2:$B$500,C7,'Gun v Gun'!$F$2:$F$500,"atk")+SUMIFS('Gun v Gun'!$D$2:$D$500,'Gun v Gun'!$A$2:$A$500,$C$3,'Gun v Gun'!$B$2:$B$500,C7,'Gun v Gun'!$F$2:$F$500,"atk")),"") | U7: =IFERROR(SUMIFS('Gun v Gun'!$C$2:$C$500,'Gun v Gun'!$A$2:$A$500,$C$3,'Gun v Gun'!$B$2:$B$500,C7,'Gun v Gun'!$F$2:$F$500,"def")/(SUMIFS('Gun v Gun'!$C$2:$C$500,'Gun v Gun'!$A$2:$A$500,$C$3,'Gun v Gun'!$B$2:$B$500,C7,'Gun v Gun'!$F$2:$F$500,"def")+SUMIFS('Gun v Gun'!$D$2:$D$500,'Gun v Gun'!$A$2:$A$500,$C$3,'Gun v Gun'!$B$2:$B$500,C7,'Gun v Gun'!$F$2:$F$500,"def")),"") | V7: =IFERROR((SUMIFS('Antieco'!$C$2:$C$500,'Antieco'!$A$2:$A$500,$C$3,'Antieco'!$B$2:$B$500,C7,'Antieco'!$F$2:$F$500,"atk")+SUMIFS('Antieco'!$C$2:$C$500,'Antieco'!$A$2:$A$500,$C$3,'Antieco'!$B$2:$B$500,C7,'Antieco'!$F$2:$F$500,"def"))/(SUMIFS('Antieco'!$C$2:$C$500,'Antieco'!$A$2:$A$500,$C$3,'Antieco'!$B$2:$B$500,C7,'Antieco'!$F$2:$F$500,"atk")+SUMIFS('Antieco'!$D$2:$D$500,'Antieco'!$A$2:$A$500,$C$3,'Antieco'!$B$2:$B$500,C7,'Antieco'!$F$2:$F$500,"atk")+SUMIFS('Antieco'!$C$2:$C$500,'Antieco'!$A$2:$A$500,$C$3,'Antieco'!$B$2:$B$500,C7,'Antieco'!$F$2:$F$500,"def")+SUMIFS('Antieco'!$D$2:$D$500,'Antieco'!$A$2:$A$500,$C$3,'Antieco'!$B$2:$B$500,C7,'Antieco'!$F$2:$F$500,"def")),"") | W7: =IFERROR(SUMIFS('Antieco'!$C$2:$C$500,'Antieco'!$A$2:$A$500,$C$3,'Antieco'!$B$2:$B$500,C7,'Antieco'!$F$2:$F$500,"atk")/(SUMIFS('Antieco'!$C$2:$C$500,'Antieco'!$A$2:$A$500,$C$3,'Antieco'!$B$2:$B$500,C7,'Antieco'!$F$2:$F$500,"atk")+SUMIFS('Antieco'!$D$2:$D$500,'Antieco'!$A$2:$A$500,$C$3,'Antieco'!$B$2:$B$500,C7,'Antieco'!$F$2:$F$500,"atk")),"") | X7: =IFERROR(SUMIFS('Antieco'!$C$2:$C$500,'Antieco'!$A$2:$A$500,$C$3,'Antieco'!$B$2:$B$500,C7,'Antieco'!$F$2:$F$500,"def")/(SUMIFS('Antieco'!$C$2:$C$500,'Antieco'!$A$2:$A$500,$C$3,'Antieco'!$B$2:$B$500,C7,'Antieco'!$F$2:$F$500,"def")+SUMIFS('Antieco'!$D$2:$D$500,'Antieco'!$A$2:$A$500,$C$3,'Antieco'!$B$2:$B$500,C7,'Antieco'!$F$2:$F$500,"def")),"") | Y7: =IFERROR((SUMIFS('ecos'!$C$2:$C$500,'ecos'!$A$2:$A$500,$C$3,'ecos'!$B$2:$B$500,C7,'ecos'!$F$2:$F$500,"atk")+SUMIFS('ecos'!$C$2:$C$500,'ecos'!$A$2:$A$500,$C$3,'ecos'!$B$2:$B$500,C7,'ecos'!$F$2:$F$500,"def"))/(SUMIFS('ecos'!$C$2:$C$500,'ecos'!$A$2:$A$500,$C$3,'ecos'!$B$2:$B$500,C7,'ecos'!$F$2:$F$500,"atk")+SUMIFS('ecos'!$D$2:$D$500,'ecos'!$A$2:$A$500,$C$3,'ecos'!$B$2:$B$500,C7,'ecos'!$F$2:$F$500,"atk")+SUMIFS('ecos'!$C$2:$C$500,'ecos'!$A$2:$A$500,$C$3,'ecos'!$B$2:$B$500,C7,'ecos'!$F$2:$F$500,"def")+SUMIFS('ecos'!$D$2:$D$500,'ecos'!$A$2:$A$500,$C$3,'ecos'!$B$2:$B$500,C7,'ecos'!$F$2:$F$500,"def")),"") | Z7: =IFERROR(SUMIFS('ecos'!$C$2:$C$500,'ecos'!$A$2:$A$500,$C$3,'ecos'!$B$2:$B$500,C7,'ecos'!$F$2:$F$500,"atk")/(SUMIFS('ecos'!$C$2:$C$500,'ecos'!$A$2:$A$500,$C$3,'ecos'!$B$2:$B$500,C7,'ecos'!$F$2:$F$500,"atk")+SUMIFS('ecos'!$D$2:$D$500,'ecos'!$A$2:$A$500,$C$3,'ecos'!$B$2:$B$500,C7,'ecos'!$F$2:$F$500,"atk")),"") | AA7: =IFERROR(SUMIFS('ecos'!$C$2:$C$500,'ecos'!$A$2:$A$500,$C$3,'ecos'!$B$2:$B$500,C7,'ecos'!$F$2:$F$500,"def")/(SUMIFS('ecos'!$C$2:$C$500,'ecos'!$A$2:$A$500,$C$3,'ecos'!$B$2:$B$500,C7,'ecos'!$F$2:$F$500,"def")+SUMIFS('ecos'!$D$2:$D$500,'ecos'!$A$2:$A$500,$C$3,'ecos'!$B$2:$B$500,C7,'ecos'!$F$2:$F$500,"def")),"") | AC7: Abyss | AD7: =SUMIFS('Post Plants'!$E$2:$E$500,'Post Plants'!$A$2:$A$500,$C$3,'Post Plants'!$B$2:$B$500,C7,'Post Plants'!$D$2:$D$500,"atk") | AE7: =SUMIFS(doubles!$M$2:$M$431,doubles!$C$2:$C$431,$C$3,doubles!$B$2:$B$431,C7)+SUMIFS(doubles!$N$2:$N$431,doubles!$C$2:$C$431,$C$3,doubles!$B$2:$B$431,C7) | AF7: =IFERROR(AD7/J7,"") | AG7: =IFERROR(SUMIFS('Post Plants'!$F$2:$F$500,'Post Plants'!$A$2:$A$500,$C$3,'Post Plants'!$B$2:$B$500,C7,'Post Plants'!$D$2:$D$500,"atk")/SUMIFS('Post Plants'!$E$2:$E$500,'Post Plants'!$A$2:$A$500,$C$3,'Post Plants'!$B$2:$B$500,C7,'Post Plants'!$D$2:$D$500,"atk"),"") | AI7: =SUMIFS('Post Plants'!$E$2:$E$500,'Post Plants'!$A$2:$A$500,$C$3,'Post Plants'!$B$2:$B$500,C7,'Post Plants'!$D$2:$D$500,"def") | AJ7: =SUMIFS(doubles!$O$2:$O$431,doubles!$C$2:$C$431,$C$3,doubles!$B$2:$B$431,C7)+SUMIFS(doubles!$P$2:$P$431,doubles!$C$2:$C$431,$C$3,doubles!$B$2:$B$431,C7) | AK7: =IFERROR(AI7/J7,"") | AL7: =IFERROR(SUMIFS('Post Plants'!$F$2:$F$500,'Post Plants'!$A$2:$A$500,$C$3,'Post Plants'!$B$2:$B$500,C7,'Post Plants'!$D$2:$D$500,"def")/SUMIFS('Post Plants'!$E$2:$E$500,'Post Plants'!$A$2:$A$500,$C$3,'Post Plants'!$B$2:$B$500,C7,'Post Plants'!$D$2:$D$500,"def"),"")
C8: Bind | D8: =IFERROR(INDEX(doubles!$E$2:$E$431,MATCH(C8&"_"&$C$3,doubles!$S$2:$S$431&"_"&doubles!$C$2:$C$431,0)),"") | I8: =IFERROR(COUNTIFS(doubles!$C$2:$C$431,$C$3,doubles!$B$2:$B$431,C8,doubles!$E$2:$E$431,D8),"") | J8: =COUNTIFS(doubles!$C$2:$C$431,$C$3,doubles!$B$2:$B$431,C8) | K8: =COUNTIFS(doubles!$C$2:$C$431,$C$3,doubles!$B$2:$B$431,C8,doubles!$R$2:$R$431,$C$3) | L8: =J8-K8 | M8: =IFERROR((SUMIFS(doubles!$M$2:$M$431,doubles!$C$2:$C$431,$C$3,doubles!$B$2:$B$431,C8)+SUMIFS(doubles!$O$2:$O$431,doubles!$C$2:$C$431,$C$3,doubles!$B$2:$B$431,C8))/(SUMIFS(doubles!$M$2:$M$431,doubles!$C$2:$C$431,$C$3,doubles!$B$2:$B$431,C8)+SUMIFS(doubles!$N$2:$N$431,doubles!$C$2:$C$431,$C$3,doubles!$B$2:$B$431,C8)+SUMIFS(doubles!$O$2:$O$431,doubles!$C$2:$C$431,$C$3,doubles!$B$2:$B$431,C8)+SUMIFS(doubles!$P$2:$P$431,doubles!$C$2:$C$431,$C$3,doubles!$B$2:$B$431,C8)),"") | N8: =IFERROR(SUMIFS(doubles!$M$2:$M$431,doubles!$C$2:$C$431,$C$3,doubles!$B$2:$B$431,C8)/(SUMIFS(doubles!$M$2:$M$431,doubles!$C$2:$C$431,$C$3,doubles!$B$2:$B$431,C8)+SUMIFS(doubles!$N$2:$N$431,doubles!$C$2:$C$431,$C$3,doubles!$B$2:$B$431,C8)),"") | O8: =IFERROR(SUMIFS(doubles!$O$2:$O$431,doubles!$C$2:$C$431,$C$3,doubles!$B$2:$B$431,C8)/(SUMIFS(doubles!$O$2:$O$431,doubles!$C$2:$C$431,$C$3,doubles!$B$2:$B$431,C8)+SUMIFS(doubles!$P$2:$P$431,doubles!$C$2:$C$431,$C$3,doubles!$B$2:$B$431,C8)),"") | P8: =IFERROR((SUMIFS(doubles!$K$2:$K$431,doubles!$C$2:$C$431,$C$3,doubles!$B$2:$B$431,C8)+SUMIFS(doubles!$L$2:$L$431,doubles!$C$2:$C$431,$C$3,doubles!$B$2:$B$431,C8))/(2*COUNTIFS(doubles!$C$2:$C$431,$C$3,doubles!$B$2:$B$431,C8)),"") | Q8: =IFERROR(SUMIFS(doubles!$K$2:$K$431,doubles!$C$2:$C$431,$C$3,doubles!$B$2:$B$431,C8)/COUNTIFS(doubles!$C$2:$C$431,$C$3,doubles!$B$2:$B$431,C8),"") | R8: =IFERROR(SUMIFS(doubles!$L$2:$L$431,doubles!$C$2:$C$431,$C$3,doubles!$B$2:$B$431,C8)/COUNTIFS(doubles!$C$2:$C$431,$C$3,doubles!$B$2:$B$431,C8),"") | S8: =IFERROR((SUMIFS('Gun v Gun'!$C$2:$C$500,'Gun v Gun'!$A$2:$A$500,$C$3,'Gun v Gun'!$B$2:$B$500,C8,'Gun v Gun'!$F$2:$F$500,"atk")+SUMIFS('Gun v Gun'!$C$2:$C$500,'Gun v Gun'!$A$2:$A$500,$C$3,'Gun v Gun'!$B$2:$B$500,C8,'Gun v Gun'!$F$2:$F$500,"def"))/(SUMIFS('Gun v Gun'!$C$2:$C$500,'Gun v Gun'!$A$2:$A$500,$C$3,'Gun v Gun'!$B$2:$B$500,C8,'Gun v Gun'!$F$2:$F$500,"atk")+SUMIFS('Gun v Gun'!$D$2:$D$500,'Gun v Gun'!$A$2:$A$500,$C$3,'Gun v Gun'!$B$2:$B$500,C8,'Gun v Gun'!$F$2:$F$500,"atk")+SUMIFS('Gun v Gun'!$C$2:$C$500,'Gun v Gun'!$A$2:$A$500,$C$3,'Gun v Gun'!$B$2:$B$500,C8,'Gun v Gun'!$F$2:$F$500,"def")+SUMIFS('Gun v Gun'!$D$2:$D$500,'Gun v Gun'!$A$2:$A$500,$C$3,'Gun v Gun'!$B$2:$B$500,C8,'Gun v Gun'!$F$2:$F$500,"def")),"") | T8: =IFERROR(SUMIFS('Gun v Gun'!$C$2:$C$500,'Gun v Gun'!$A$2:$A$500,$C$3,'Gun v Gun'!$B$2:$B$500,C8,'Gun v Gun'!$F$2:$F$500,"atk")/(SUMIFS('Gun v Gun'!$C$2:$C$500,'Gun v Gun'!$A$2:$A$500,$C$3,'Gun v Gun'!$B$2:$B$500,C8,'Gun v Gun'!$F$2:$F$500,"atk")+SUMIFS('Gun v Gun'!$D$2:$D$500,'Gun v Gun'!$A$2:$A$500,$C$3,'Gun v Gun'!$B$2:$B$500,C8,'Gun v Gun'!$F$2:$F$500,"atk")),"") | U8: =IFERROR(SUMIFS('Gun v Gun'!$C$2:$C$500,'Gun v Gun'!$A$2:$A$500,$C$3,'Gun v Gun'!$B$2:$B$500,C8,'Gun v Gun'!$F$2:$F$500,"def")/(SUMIFS('Gun v Gun'!$C$2:$C$500,'Gun v Gun'!$A$2:$A$500,$C$3,'Gun v Gun'!$B$2:$B$500,C8,'Gun v Gun'!$F$2:$F$500,"def")+SUMIFS('Gun v Gun'!$D$2:$D$500,'Gun v Gun'!$A$2:$A$500,$C$3,'Gun v Gun'!$B$2:$B$500,C8,'Gun v Gun'!$F$2:$F$500,"def")),"") | V8: =IFERROR((SUMIFS('Antieco'!$C$2:$C$500,'Antieco'!$A$2:$A$500,$C$3,'Antieco'!$B$2:$B$500,C8,'Antieco'!$F$2:$F$500,"atk")+SUMIFS('Antieco'!$C$2:$C$500,'Antieco'!$A$2:$A$500,$C$3,'Antieco'!$B$2:$B$500,C8,'Antieco'!$F$2:$F$500,"def"))/(SUMIFS('Antieco'!$C$2:$C$500,'Antieco'!$A$2:$A$500,$C$3,'Antieco'!$B$2:$B$500,C8,'Antieco'!$F$2:$F$500,"atk")+SUMIFS('Antieco'!$D$2:$D$500,'Antieco'!$A$2:$A$500,$C$3,'Antieco'!$B$2:$B$500,C8,'Antieco'!$F$2:$F$500,"atk")+SUMIFS('Antieco'!$C$2:$C$500,'Antieco'!$A$2:$A$500,$C$3,'Antieco'!$B$2:$B$500,C8,'Antieco'!$F$2:$F$500,"def")+SUMIFS('Antieco'!$D$2:$D$500,'Antieco'!$A$2:$A$500,$C$3,'Antieco'!$B$2:$B$500,C8,'Antieco'!$F$2:$F$500,"def")),"") | W8: =IFERROR(SUMIFS('Antieco'!$C$2:$C$500,'Antieco'!$A$2:$A$500,$C$3,'Antieco'!$B$2:$B$500,C8,'Antieco'!$F$2:$F$500,"atk")/(SUMIFS('Antieco'!$C$2:$C$500,'Antieco'!$A$2:$A$500,$C$3,'Antieco'!$B$2:$B$500,C8,'Antieco'!$F$2:$F$500,"atk")+SUMIFS('Antieco'!$D$2:$D$500,'Antieco'!$A$2:$A$500,$C$3,'Antieco'!$B$2:$B$500,C8,'Antieco'!$F$2:$F$500,"atk")),"") | X8: =IFERROR(SUMIFS('Antieco'!$C$2:$C$500,'Antieco'!$A$2:$A$500,$C$3,'Antieco'!$B$2:$B$500,C8,'Antieco'!$F$2:$F$500,"def")/(SUMIFS('Antieco'!$C$2:$C$500,'Antieco'!$A$2:$A$500,$C$3,'Antieco'!$B$2:$B$500,C8,'Antieco'!$F$2:$F$500,"def")+SUMIFS('Antieco'!$D$2:$D$500,'Antieco'!$A$2:$A$500,$C$3,'Antieco'!$B$2:$B$500,C8,'Antieco'!$F$2:$F$500,"def")),"") | Y8: =IFERROR((SUMIFS('ecos'!$C$2:$C$500,'ecos'!$A$2:$A$500,$C$3,'ecos'!$B$2:$B$500,C8,'ecos'!$F$2:$F$500,"atk")+SUMIFS('ecos'!$C$2:$C$500,'ecos'!$A$2:$A$500,$C$3,'ecos'!$B$2:$B$500,C8,'ecos'!$F$2:$F$500,"def"))/(SUMIFS('ecos'!$C$2:$C$500,'ecos'!$A$2:$A$500,$C$3,'ecos'!$B$2:$B$500,C8,'ecos'!$F$2:$F$500,"atk")+SUMIFS('ecos'!$D$2:$D$500,'ecos'!$A$2:$A$500,$C$3,'ecos'!$B$2:$B$500,C8,'ecos'!$F$2:$F$500,"atk")+SUMIFS('ecos'!$C$2:$C$500,'ecos'!$A$2:$A$500,$C$3,'ecos'!$B$2:$B$500,C8,'ecos'!$F$2:$F$500,"def")+SUMIFS('ecos'!$D$2:$D$500,'ecos'!$A$2:$A$500,$C$3,'ecos'!$B$2:$B$500,C8,'ecos'!$F$2:$F$500,"def")),"") | Z8: =IFERROR(SUMIFS('ecos'!$C$2:$C$500,'ecos'!$A$2:$A$500,$C$3,'ecos'!$B$2:$B$500,C8,'ecos'!$F$2:$F$500,"atk")/(SUMIFS('ecos'!$C$2:$C$500,'ecos'!$A$2:$A$500,$C$3,'ecos'!$B$2:$B$500,C8,'ecos'!$F$2:$F$500,"atk")+SUMIFS('ecos'!$D$2:$D$500,'ecos'!$A$2:$A$500,$C$3,'ecos'!$B$2:$B$500,C8,'ecos'!$F$2:$F$500,"atk")),"") | AA8: =IFERROR(SUMIFS('ecos'!$C$2:$C$500,'ecos'!$A$2:$A$500,$C$3,'ecos'!$B$2:$B$500,C8,'ecos'!$F$2:$F$500,"def")/(SUMIFS('ecos'!$C$2:$C$500,'ecos'!$A$2:$A$500,$C$3,'ecos'!$B$2:$B$500,C8,'ecos'!$F$2:$F$500,"def")+SUMIFS('ecos'!$D$2:$D$500,'ecos'!$A$2:$A$500,$C$3,'ecos'!$B$2:$B$500,C8,'ecos'!$F$2:$F$500,"def")),"") | AC8: Bind | AD8: =SUMIFS('Post Plants'!$E$2:$E$500,'Post Plants'!$A$2:$A$500,$C$3,'Post Plants'!$B$2:$B$500,C8,'Post Plants'!$D$2:$D$500,"atk") | AE8: =SUMIFS(doubles!$M$2:$M$431,doubles!$C$2:$C$431,$C$3,doubles!$B$2:$B$431,C8)+SUMIFS(doubles!$N$2:$N$431,doubles!$C$2:$C$431,$C$3,doubles!$B$2:$B$431,C8) | AF8: =IFERROR(AD8/J8,"") | AG8: =IFERROR(SUMIFS('Post Plants'!$F$2:$F$500,'Post Plants'!$A$2:$A$500,$C$3,'Post Plants'!$B$2:$B$500,C8,'Post Plants'!$D$2:$D$500,"atk")/SUMIFS('Post Plants'!$E$2:$E$500,'Post Plants'!$A$2:$A$500,$C$3,'Post Plants'!$B$2:$B$500,C8,'Post Plants'!$D$2:$D$500,"atk"),"") | AI8: =SUMIFS('Post Plants'!$E$2:$E$500,'Post Plants'!$A$2:$A$500,$C$3,'Post Plants'!$B$2:$B$500,C8,'Post Plants'!$D$2:$D$500,"def") | AJ8: =SUMIFS(doubles!$O$2:$O$431,doubles!$C$2:$C$431,$C$3,doubles!$B$2:$B$431,C8)+SUMIFS(doubles!$P$2:$P$431,doubles!$C$2:$C$431,$C$3,doubles!$B$2:$B$431,C8) | AK8: =IFERROR(AI8/J8,"") | AL8: =IFERROR(SUMIFS('Post Plants'!$F$2:$F$500,'Post Plants'!$A$2:$A$500,$C$3,'Post Plants'!$B$2:$B$500,C8,'Post Plants'!$D$2:$D$500,"def")/SUMIFS('Post Plants'!$E$2:$E$500,'Post Plants'!$A$2:$A$500,$C$3,'Post Plants'!$B$2:$B$500,C8,'Post Plants'!$D$2:$D$500,"def"),"")
C9: Breeze | D9: =IFERROR(INDEX(doubles!$E$2:$E$431,MATCH(C9&"_"&$C$3,doubles!$S$2:$S$431&"_"&doubles!$C$2:$C$431,0)),"") | I9: =IFERROR(COUNTIFS(doubles!$C$2:$C$431,$C$3,doubles!$B$2:$B$431,C9,doubles!$E$2:$E$431,D9),"") | J9: =COUNTIFS(doubles!$C$2:$C$431,$C$3,doubles!$B$2:$B$431,C9) | K9: =COUNTIFS(doubles!$C$2:$C$431,$C$3,doubles!$B$2:$B$431,C9,doubles!$R$2:$R$431,$C$3) | L9: =J9-K9 | M9: =IFERROR((SUMIFS(doubles!$M$2:$M$431,doubles!$C$2:$C$431,$C$3,doubles!$B$2:$B$431,C9)+SUMIFS(doubles!$O$2:$O$431,doubles!$C$2:$C$431,$C$3,doubles!$B$2:$B$431,C9))/(SUMIFS(doubles!$M$2:$M$431,doubles!$C$2:$C$431,$C$3,doubles!$B$2:$B$431,C9)+SUMIFS(doubles!$N$2:$N$431,doubles!$C$2:$C$431,$C$3,doubles!$B$2:$B$431,C9)+SUMIFS(doubles!$O$2:$O$431,doubles!$C$2:$C$431,$C$3,doubles!$B$2:$B$431,C9)+SUMIFS(doubles!$P$2:$P$431,doubles!$C$2:$C$431,$C$3,doubles!$B$2:$B$431,C9)),"") | N9: =IFERROR(SUMIFS(doubles!$M$2:$M$431,doubles!$C$2:$C$431,$C$3,doubles!$B$2:$B$431,C9)/(SUMIFS(doubles!$M$2:$M$431,doubles!$C$2:$C$431,$C$3,doubles!$B$2:$B$431,C9)+SUMIFS(doubles!$N$2:$N$431,doubles!$C$2:$C$431,$C$3,doubles!$B$2:$B$431,C9)),"") | O9: =IFERROR(SUMIFS(doubles!$O$2:$O$431,doubles!$C$2:$C$431,$C$3,doubles!$B$2:$B$431,C9)/(SUMIFS(doubles!$O$2:$O$431,doubles!$C$2:$C$431,$C$3,doubles!$B$2:$B$431,C9)+SUMIFS(doubles!$P$2:$P$431,doubles!$C$2:$C$431,$C$3,doubles!$B$2:$B$431,C9)),"") | P9: =IFERROR((SUMIFS(doubles!$K$2:$K$431,doubles!$C$2:$C$431,$C$3,doubles!$B$2:$B$431,C9)+SUMIFS(doubles!$L$2:$L$431,doubles!$C$2:$C$431,$C$3,doubles!$B$2:$B$431,C9))/(2*COUNTIFS(doubles!$C$2:$C$431,$C$3,doubles!$B$2:$B$431,C9)),"") | Q9: =IFERROR(SUMIFS(doubles!$K$2:$K$431,doubles!$C$2:$C$431,$C$3,doubles!$B$2:$B$431,C9)/COUNTIFS(doubles!$C$2:$C$431,$C$3,doubles!$B$2:$B$431,C9),"") | R9: =IFERROR(SUMIFS(doubles!$L$2:$L$431,doubles!$C$2:$C$431,$C$3,doubles!$B$2:$B$431,C9)/COUNTIFS(doubles!$C$2:$C$431,$C$3,doubles!$B$2:$B$431,C9),"") | S9: =IFERROR((SUMIFS('Gun v Gun'!$C$2:$C$500,'Gun v Gun'!$A$2:$A$500,$C$3,'Gun v Gun'!$B$2:$B$500,C9,'Gun v Gun'!$F$2:$F$500,"atk")+SUMIFS('Gun v Gun'!$C$2:$C$500,'Gun v Gun'!$A$2:$A$500,$C$3,'Gun v Gun'!$B$2:$B$500,C9,'Gun v Gun'!$F$2:$F$500,"def"))/(SUMIFS('Gun v Gun'!$C$2:$C$500,'Gun v Gun'!$A$2:$A$500,$C$3,'Gun v Gun'!$B$2:$B$500,C9,'Gun v Gun'!$F$2:$F$500,"atk")+SUMIFS('Gun v Gun'!$D$2:$D$500,'Gun v Gun'!$A$2:$A$500,$C$3,'Gun v Gun'!$B$2:$B$500,C9,'Gun v Gun'!$F$2:$F$500,"atk")+SUMIFS('Gun v Gun'!$C$2:$C$500,'Gun v Gun'!$A$2:$A$500,$C$3,'Gun v Gun'!$B$2:$B$500,C9,'Gun v Gun'!$F$2:$F$500,"def")+SUMIFS('Gun v Gun'!$D$2:$D$500,'Gun v Gun'!$A$2:$A$500,$C$3,'Gun v Gun'!$B$2:$B$500,C9,'Gun v Gun'!$F$2:$F$500,"def")),"") | T9: =IFERROR(SUMIFS('Gun v Gun'!$C$2:$C$500,'Gun v Gun'!$A$2:$A$500,$C$3,'Gun v Gun'!$B$2:$B$500,C9,'Gun v Gun'!$F$2:$F$500,"atk")/(SUMIFS('Gun v Gun'!$C$2:$C$500,'Gun v Gun'!$A$2:$A$500,$C$3,'Gun v Gun'!$B$2:$B$500,C9,'Gun v Gun'!$F$2:$F$500,"atk")+SUMIFS('Gun v Gun'!$D$2:$D$500,'Gun v Gun'!$A$2:$A$500,$C$3,'Gun v Gun'!$B$2:$B$500,C9,'Gun v Gun'!$F$2:$F$500,"atk")),"") | U9: =IFERROR(SUMIFS('Gun v Gun'!$C$2:$C$500,'Gun v Gun'!$A$2:$A$500,$C$3,'Gun v Gun'!$B$2:$B$500,C9,'Gun v Gun'!$F$2:$F$500,"def")/(SUMIFS('Gun v Gun'!$C$2:$C$500,'Gun v Gun'!$A$2:$A$500,$C$3,'Gun v Gun'!$B$2:$B$500,C9,'Gun v Gun'!$F$2:$F$500,"def")+SUMIFS('Gun v Gun'!$D$2:$D$500,'Gun v Gun'!$A$2:$A$500,$C$3,'Gun v Gun'!$B$2:$B$500,C9,'Gun v Gun'!$F$2:$F$500,"def")),"") | V9: =IFERROR((SUMIFS('Antieco'!$C$2:$C$500,'Antieco'!$A$2:$A$500,$C$3,'Antieco'!$B$2:$B$500,C9,'Antieco'!$F$2:$F$500,"atk")+SUMIFS('Antieco'!$C$2:$C$500,'Antieco'!$A$2:$A$500,$C$3,'Antieco'!$B$2:$B$500,C9,'Antieco'!$F$2:$F$500,"def"))/(SUMIFS('Antieco'!$C$2:$C$500,'Antieco'!$A$2:$A$500,$C$3,'Antieco'!$B$2:$B$500,C9,'Antieco'!$F$2:$F$500,"atk")+SUMIFS('Antieco'!$D$2:$D$500,'Antieco'!$A$2:$A$500,$C$3,'Antieco'!$B$2:$B$500,C9,'Antieco'!$F$2:$F$500,"atk")+SUMIFS('Antieco'!$C$2:$C$500,'Antieco'!$A$2:$A$500,$C$3,'Antieco'!$B$2:$B$500,C9,'Antieco'!$F$2:$F$500,"def")+SUMIFS('Antieco'!$D$2:$D$500,'Antieco'!$A$2:$A$500,$C$3,'Antieco'!$B$2:$B$500,C9,'Antieco'!$F$2:$F$500,"def")),"") | W9: =IFERROR(SUMIFS('Antieco'!$C$2:$C$500,'Antieco'!$A$2:$A$500,$C$3,'Antieco'!$B$2:$B$500,C9,'Antieco'!$F$2:$F$500,"atk")/(SUMIFS('Antieco'!$C$2:$C$500,'Antieco'!$A$2:$A$500,$C$3,'Antieco'!$B$2:$B$500,C9,'Antieco'!$F$2:$F$500,"atk")+SUMIFS('Antieco'!$D$2:$D$500,'Antieco'!$A$2:$A$500,$C$3,'Antieco'!$B$2:$B$500,C9,'Antieco'!$F$2:$F$500,"atk")),"") | X9: =IFERROR(SUMIFS('Antieco'!$C$2:$C$500,'Antieco'!$A$2:$A$500,$C$3,'Antieco'!$B$2:$B$500,C9,'Antieco'!$F$2:$F$500,"def")/(SUMIFS('Antieco'!$C$2:$C$500,'Antieco'!$A$2:$A$500,$C$3,'Antieco'!$B$2:$B$500,C9,'Antieco'!$F$2:$F$500,"def")+SUMIFS('Antieco'!$D$2:$D$500,'Antieco'!$A$2:$A$500,$C$3,'Antieco'!$B$2:$B$500,C9,'Antieco'!$F$2:$F$500,"def")),"") | Y9: =IFERROR((SUMIFS('ecos'!$C$2:$C$500,'ecos'!$A$2:$A$500,$C$3,'ecos'!$B$2:$B$500,C9,'ecos'!$F$2:$F$500,"atk")+SUMIFS('ecos'!$C$2:$C$500,'ecos'!$A$2:$A$500,$C$3,'ecos'!$B$2:$B$500,C9,'ecos'!$F$2:$F$500,"def"))/(SUMIFS('ecos'!$C$2:$C$500,'ecos'!$A$2:$A$500,$C$3,'ecos'!$B$2:$B$500,C9,'ecos'!$F$2:$F$500,"atk")+SUMIFS('ecos'!$D$2:$D$500,'ecos'!$A$2:$A$500,$C$3,'ecos'!$B$2:$B$500,C9,'ecos'!$F$2:$F$500,"atk")+SUMIFS('ecos'!$C$2:$C$500,'ecos'!$A$2:$A$500,$C$3,'ecos'!$B$2:$B$500,C9,'ecos'!$F$2:$F$500,"def")+SUMIFS('ecos'!$D$2:$D$500,'ecos'!$A$2:$A$500,$C$3,'ecos'!$B$2:$B$500,C9,'ecos'!$F$2:$F$500,"def")),"") | Z9: =IFERROR(SUMIFS('ecos'!$C$2:$C$500,'ecos'!$A$2:$A$500,$C$3,'ecos'!$B$2:$B$500,C9,'ecos'!$F$2:$F$500,"atk")/(SUMIFS('ecos'!$C$2:$C$500,'ecos'!$A$2:$A$500,$C$3,'ecos'!$B$2:$B$500,C9,'ecos'!$F$2:$F$500,"atk")+SUMIFS('ecos'!$D$2:$D$500,'ecos'!$A$2:$A$500,$C$3,'ecos'!$B$2:$B$500,C9,'ecos'!$F$2:$F$500,"atk")),"") | AA9: =IFERROR(SUMIFS('ecos'!$C$2:$C$500,'ecos'!$A$2:$A$500,$C$3,'ecos'!$B$2:$B$500,C9,'ecos'!$F$2:$F$500,"def")/(SUMIFS('ecos'!$C$2:$C$500,'ecos'!$A$2:$A$500,$C$3,'ecos'!$B$2:$B$500,C9,'ecos'!$F$2:$F$500,"def")+SUMIFS('ecos'!$D$2:$D$500,'ecos'!$A$2:$A$500,$C$3,'ecos'!$B$2:$B$500,C9,'ecos'!$F$2:$F$500,"def")),"") | AC9: Breeze | AD9: =SUMIFS('Post Plants'!$E$2:$E$500,'Post Plants'!$A$2:$A$500,$C$3,'Post Plants'!$B$2:$B$500,C9,'Post Plants'!$D$2:$D$500,"atk") | AE9: =SUMIFS(doubles!$M$2:$M$431,doubles!$C$2:$C$431,$C$3,doubles!$B$2:$B$431,C9)+SUMIFS(doubles!$N$2:$N$431,doubles!$C$2:$C$431,$C$3,doubles!$B$2:$B$431,C9) | AF9: =IFERROR(AD9/J9,"") | AG9: =IFERROR(SUMIFS('Post Plants'!$F$2:$F$500,'Post Plants'!$A$2:$A$500,$C$3,'Post Plants'!$B$2:$B$500,C9,'Post Plants'!$D$2:$D$500,"atk")/SUMIFS('Post Plants'!$E$2:$E$500,'Post Plants'!$A$2:$A$500,$C$3,'Post Plants'!$B$2:$B$500,C9,'Post Plants'!$D$2:$D$500,"atk"),"") | AI9: =SUMIFS('Post Plants'!$E$2:$E$500,'Post Plants'!$A$2:$A$500,$C$3,'Post Plants'!$B$2:$B$500,C9,'Post Plants'!$D$2:$D$500,"def") | AJ9: =SUMIFS(doubles!$O$2:$O$431,doubles!$C$2:$C$431,$C$3,doubles!$B$2:$B$431,C9)+SUMIFS(doubles!$P$2:$P$431,doubles!$C$2:$C$431,$C$3,doubles!$B$2:$B$431,C9) | AK9: =IFERROR(AI9/J9,"") | AL9: =IFERROR(SUMIFS('Post Plants'!$F$2:$F$500,'Post Plants'!$A$2:$A$500,$C$3,'Post Plants'!$B$2:$B$500,C9,'Post Plants'!$D$2:$D$500,"def")/SUMIFS('Post Plants'!$E$2:$E$500,'Post Plants'!$A$2:$A$500,$C$3,'Post Plants'!$B$2:$B$500,C9,'Post Plants'!$D$2:$D$500,"def"),"")
C10: Corrode | D10: =IFERROR(INDEX(doubles!$E$2:$E$431,MATCH(C10&"_"&$C$3,doubles!$S$2:$S$431&"_"&doubles!$C$2:$C$431,0)),"") | I10: =IFERROR(COUNTIFS(doubles!$C$2:$C$431,$C$3,doubles!$B$2:$B$431,C10,doubles!$E$2:$E$431,D10),"") | J10: =COUNTIFS(doubles!$C$2:$C$431,$C$3,doubles!$B$2:$B$431,C10) | K10: =COUNTIFS(doubles!$C$2:$C$431,$C$3,doubles!$B$2:$B$431,C10,doubles!$R$2:$R$431,$C$3) | L10: =J10-K10 | M10: =IFERROR((SUMIFS(doubles!$M$2:$M$431,doubles!$C$2:$C$431,$C$3,doubles!$B$2:$B$431,C10)+SUMIFS(doubles!$O$2:$O$431,doubles!$C$2:$C$431,$C$3,doubles!$B$2:$B$431,C10))/(SUMIFS(doubles!$M$2:$M$431,doubles!$C$2:$C$431,$C$3,doubles!$B$2:$B$431,C10)+SUMIFS(doubles!$N$2:$N$431,doubles!$C$2:$C$431,$C$3,doubles!$B$2:$B$431,C10)+SUMIFS(doubles!$O$2:$O$431,doubles!$C$2:$C$431,$C$3,doubles!$B$2:$B$431,C10)+SUMIFS(doubles!$P$2:$P$431,doubles!$C$2:$C$431,$C$3,doubles!$B$2:$B$431,C10)),"") | N10: =IFERROR(SUMIFS(doubles!$M$2:$M$431,doubles!$C$2:$C$431,$C$3,doubles!$B$2:$B$431,C10)/(SUMIFS(doubles!$M$2:$M$431,doubles!$C$2:$C$431,$C$3,doubles!$B$2:$B$431,C10)+SUMIFS(doubles!$N$2:$N$431,doubles!$C$2:$C$431,$C$3,doubles!$B$2:$B$431,C10)),"") | O10: =IFERROR(SUMIFS(doubles!$O$2:$O$431,doubles!$C$2:$C$431,$C$3,doubles!$B$2:$B$431,C10)/(SUMIFS(doubles!$O$2:$O$431,doubles!$C$2:$C$431,$C$3,doubles!$B$2:$B$431,C10)+SUMIFS(doubles!$P$2:$P$431,doubles!$C$2:$C$431,$C$3,doubles!$B$2:$B$431,C10)),"") | P10: =IFERROR((SUMIFS(doubles!$K$2:$K$431,doubles!$C$2:$C$431,$C$3,doubles!$B$2:$B$431,C10)+SUMIFS(doubles!$L$2:$L$431,doubles!$C$2:$C$431,$C$3,doubles!$B$2:$B$431,C10))/(2*COUNTIFS(doubles!$C$2:$C$431,$C$3,doubles!$B$2:$B$431,C10)),"") | Q10: =IFERROR(SUMIFS(doubles!$K$2:$K$431,doubles!$C$2:$C$431,$C$3,doubles!$B$2:$B$431,C10)/COUNTIFS(doubles!$C$2:$C$431,$C$3,doubles!$B$2:$B$431,C10),"") | R10: =IFERROR(SUMIFS(doubles!$L$2:$L$431,doubles!$C$2:$C$431,$C$3,doubles!$B$2:$B$431,C10)/COUNTIFS(doubles!$C$2:$C$431,$C$3,doubles!$B$2:$B$431,C10),"") | S10: =IFERROR((SUMIFS('Gun v Gun'!$C$2:$C$500,'Gun v Gun'!$A$2:$A$500,$C$3,'Gun v Gun'!$B$2:$B$500,C10,'Gun v Gun'!$F$2:$F$500,"atk")+SUMIFS('Gun v Gun'!$C$2:$C$500,'Gun v Gun'!$A$2:$A$500,$C$3,'Gun v Gun'!$B$2:$B$500,C10,'Gun v Gun'!$F$2:$F$500,"def"))/(SUMIFS('Gun v Gun'!$C$2:$C$500,'Gun v Gun'!$A$2:$A$500,$C$3,'Gun v Gun'!$B$2:$B$500,C10,'Gun v Gun'!$F$2:$F$500,"atk")+SUMIFS('Gun v Gun'!$D$2:$D$500,'Gun v Gun'!$A$2:$A$500,$C$3,'Gun v Gun'!$B$2:$B$500,C10,'Gun v Gun'!$F$2:$F$500,"atk")+SUMIFS('Gun v Gun'!$C$2:$C$500,'Gun v Gun'!$A$2:$A$500,$C$3,'Gun v Gun'!$B$2:$B$500,C10,'Gun v Gun'!$F$2:$F$500,"def")+SUMIFS('Gun v Gun'!$D$2:$D$500,'Gun v Gun'!$A$2:$A$500,$C$3,'Gun v Gun'!$B$2:$B$500,C10,'Gun v Gun'!$F$2:$F$500,"def")),"") | T10: =IFERROR(SUMIFS('Gun v Gun'!$C$2:$C$500,'Gun v Gun'!$A$2:$A$500,$C$3,'Gun v Gun'!$B$2:$B$500,C10,'Gun v Gun'!$F$2:$F$500,"atk")/(SUMIFS('Gun v Gun'!$C$2:$C$500,'Gun v Gun'!$A$2:$A$500,$C$3,'Gun v Gun'!$B$2:$B$500,C10,'Gun v Gun'!$F$2:$F$500,"atk")+SUMIFS('Gun v Gun'!$D$2:$D$500,'Gun v Gun'!$A$2:$A$500,$C$3,'Gun v Gun'!$B$2:$B$500,C10,'Gun v Gun'!$F$2:$F$500,"atk")),"") | U10: =IFERROR(SUMIFS('Gun v Gun'!$C$2:$C$500,'Gun v Gun'!$A$2:$A$500,$C$3,'Gun v Gun'!$B$2:$B$500,C10,'Gun v Gun'!$F$2:$F$500,"def")/(SUMIFS('Gun v Gun'!$C$2:$C$500,'Gun v Gun'!$A$2:$A$500,$C$3,'Gun v Gun'!$B$2:$B$500,C10,'Gun v Gun'!$F$2:$F$500,"def")+SUMIFS('Gun v Gun'!$D$2:$D$500,'Gun v Gun'!$A$2:$A$500,$C$3,'Gun v Gun'!$B$2:$B$500,C10,'Gun v Gun'!$F$2:$F$500,"def")),"") | V10: =IFERROR((SUMIFS('Antieco'!$C$2:$C$500,'Antieco'!$A$2:$A$500,$C$3,'Antieco'!$B$2:$B$500,C10,'Antieco'!$F$2:$F$500,"atk")+SUMIFS('Antieco'!$C$2:$C$500,'Antieco'!$A$2:$A$500,$C$3,'Antieco'!$B$2:$B$500,C10,'Antieco'!$F$2:$F$500,"def"))/(SUMIFS('Antieco'!$C$2:$C$500,'Antieco'!$A$2:$A$500,$C$3,'Antieco'!$B$2:$B$500,C10,'Antieco'!$F$2:$F$500,"atk")+SUMIFS('Antieco'!$D$2:$D$500,'Antieco'!$A$2:$A$500,$C$3,'Antieco'!$B$2:$B$500,C10,'Antieco'!$F$2:$F$500,"atk")+SUMIFS('Antieco'!$C$2:$C$500,'Antieco'!$A$2:$A$500,$C$3,'Antieco'!$B$2:$B$500,C10,'Antieco'!$F$2:$F$500,"def")+SUMIFS('Antieco'!$D$2:$D$500,'Antieco'!$A$2:$A$500,$C$3,'Antieco'!$B$2:$B$500,C10,'Antieco'!$F$2:$F$500,"def")),"") | W10: =IFERROR(SUMIFS('Antieco'!$C$2:$C$500,'Antieco'!$A$2:$A$500,$C$3,'Antieco'!$B$2:$B$500,C10,'Antieco'!$F$2:$F$500,"atk")/(SUMIFS('Antieco'!$C$2:$C$500,'Antieco'!$A$2:$A$500,$C$3,'Antieco'!$B$2:$B$500,C10,'Antieco'!$F$2:$F$500,"atk")+SUMIFS('Antieco'!$D$2:$D$500,'Antieco'!$A$2:$A$500,$C$3,'Antieco'!$B$2:$B$500,C10,'Antieco'!$F$2:$F$500,"atk")),"") | X10: =IFERROR(SUMIFS('Antieco'!$C$2:$C$500,'Antieco'!$A$2:$A$500,$C$3,'Antieco'!$B$2:$B$500,C10,'Antieco'!$F$2:$F$500,"def")/(SUMIFS('Antieco'!$C$2:$C$500,'Antieco'!$A$2:$A$500,$C$3,'Antieco'!$B$2:$B$500,C10,'Antieco'!$F$2:$F$500,"def")+SUMIFS('Antieco'!$D$2:$D$500,'Antieco'!$A$2:$A$500,$C$3,'Antieco'!$B$2:$B$500,C10,'Antieco'!$F$2:$F$500,"def")),"") | Y10: =IFERROR((SUMIFS('ecos'!$C$2:$C$500,'ecos'!$A$2:$A$500,$C$3,'ecos'!$B$2:$B$500,C10,'ecos'!$F$2:$F$500,"atk")+SUMIFS('ecos'!$C$2:$C$500,'ecos'!$A$2:$A$500,$C$3,'ecos'!$B$2:$B$500,C10,'ecos'!$F$2:$F$500,"def"))/(SUMIFS('ecos'!$C$2:$C$500,'ecos'!$A$2:$A$500,$C$3,'ecos'!$B$2:$B$500,C10,'ecos'!$F$2:$F$500,"atk")+SUMIFS('ecos'!$D$2:$D$500,'ecos'!$A$2:$A$500,$C$3,'ecos'!$B$2:$B$500,C10,'ecos'!$F$2:$F$500,"atk")+SUMIFS('ecos'!$C$2:$C$500,'ecos'!$A$2:$A$500,$C$3,'ecos'!$B$2:$B$500,C10,'ecos'!$F$2:$F$500,"def")+SUMIFS('ecos'!$D$2:$D$500,'ecos'!$A$2:$A$500,$C$3,'ecos'!$B$2:$B$500,C10,'ecos'!$F$2:$F$500,"def")),"") | Z10: =IFERROR(SUMIFS('ecos'!$C$2:$C$500,'ecos'!$A$2:$A$500,$C$3,'ecos'!$B$2:$B$500,C10,'ecos'!$F$2:$F$500,"atk")/(SUMIFS('ecos'!$C$2:$C$500,'ecos'!$A$2:$A$500,$C$3,'ecos'!$B$2:$B$500,C10,'ecos'!$F$2:$F$500,"atk")+SUMIFS('ecos'!$D$2:$D$500,'ecos'!$A$2:$A$500,$C$3,'ecos'!$B$2:$B$500,C10,'ecos'!$F$2:$F$500,"atk")),"") | AA10: =IFERROR(SUMIFS('ecos'!$C$2:$C$500,'ecos'!$A$2:$A$500,$C$3,'ecos'!$B$2:$B$500,C10,'ecos'!$F$2:$F$500,"def")/(SUMIFS('ecos'!$C$2:$C$500,'ecos'!$A$2:$A$500,$C$3,'ecos'!$B$2:$B$500,C10,'ecos'!$F$2:$F$500,"def")+SUMIFS('ecos'!$D$2:$D$500,'ecos'!$A$2:$A$500,$C$3,'ecos'!$B$2:$B$500,C10,'ecos'!$F$2:$F$500,"def")),"") | AC10: Corrode | AD10: =SUMIFS('Post Plants'!$E$2:$E$500,'Post Plants'!$A$2:$A$500,$C$3,'Post Plants'!$B$2:$B$500,C10,'Post Plants'!$D$2:$D$500,"atk") | AE10: =SUMIFS(doubles!$M$2:$M$431,doubles!$C$2:$C$431,$C$3,doubles!$B$2:$B$431,C10)+SUMIFS(doubles!$N$2:$N$431,doubles!$C$2:$C$431,$C$3,doubles!$B$2:$B$431,C10) | AF10: =IFERROR(AD10/J10,"") | AG10: =IFERROR(SUMIFS('Post Plants'!$F$2:$F$500,'Post Plants'!$A$2:$A$500,$C$3,'Post Plants'!$B$2:$B$500,C10,'Post Plants'!$D$2:$D$500,"atk")/SUMIFS('Post Plants'!$E$2:$E$500,'Post Plants'!$A$2:$A$500,$C$3,'Post Plants'!$B$2:$B$500,C10,'Post Plants'!$D$2:$D$500,"atk"),"") | AI10: =SUMIFS('Post Plants'!$E$2:$E$500,'Post Plants'!$A$2:$A$500,$C$3,'Post Plants'!$B$2:$B$500,C10,'Post Plants'!$D$2:$D$500,"def") | AJ10: =SUMIFS(doubles!$O$2:$O$431,doubles!$C$2:$C$431,$C$3,doubles!$B$2:$B$431,C10)+SUMIFS(doubles!$P$2:$P$431,doubles!$C$2:$C$431,$C$3,doubles!$B$2:$B$431,C10) | AK10: =IFERROR(AI10/J10,"") | AL10: =IFERROR(SUMIFS('Post Plants'!$F$2:$F$500,'Post Plants'!$A$2:$A$500,$C$3,'Post Plants'!$B$2:$B$500,C10,'Post Plants'!$D$2:$D$500,"def")/SUMIFS('Post Plants'!$E$2:$E$500,'Post Plants'!$A$2:$A$500,$C$3,'Post Plants'!$B$2:$B$500,C10,'Post Plants'!$D$2:$D$500,"def"),"")
C11: Haven | D11: =IFERROR(INDEX(doubles!$E$2:$E$431,MATCH(C11&"_"&$C$3,doubles!$S$2:$S$431&"_"&doubles!$C$2:$C$431,0)),"") | I11: =IFERROR(COUNTIFS(doubles!$C$2:$C$431,$C$3,doubles!$B$2:$B$431,C11,doubles!$E$2:$E$431,D11),"") | J11: =COUNTIFS(doubles!$C$2:$C$431,$C$3,doubles!$B$2:$B$431,C11) | K11: =COUNTIFS(doubles!$C$2:$C$431,$C$3,doubles!$B$2:$B$431,C11,doubles!$R$2:$R$431,$C$3) | L11: =J11-K11 | M11: =IFERROR((SUMIFS(doubles!$M$2:$M$431,doubles!$C$2:$C$431,$C$3,doubles!$B$2:$B$431,C11)+SUMIFS(doubles!$O$2:$O$431,doubles!$C$2:$C$431,$C$3,doubles!$B$2:$B$431,C11))/(SUMIFS(doubles!$M$2:$M$431,doubles!$C$2:$C$431,$C$3,doubles!$B$2:$B$431,C11)+SUMIFS(doubles!$N$2:$N$431,doubles!$C$2:$C$431,$C$3,doubles!$B$2:$B$431,C11)+SUMIFS(doubles!$O$2:$O$431,doubles!$C$2:$C$431,$C$3,doubles!$B$2:$B$431,C11)+SUMIFS(doubles!$P$2:$P$431,doubles!$C$2:$C$431,$C$3,doubles!$B$2:$B$431,C11)),"") | N11: =IFERROR(SUMIFS(doubles!$M$2:$M$431,doubles!$C$2:$C$431,$C$3,doubles!$B$2:$B$431,C11)/(SUMIFS(doubles!$M$2:$M$431,doubles!$C$2:$C$431,$C$3,doubles!$B$2:$B$431,C11)+SUMIFS(doubles!$N$2:$N$431,doubles!$C$2:$C$431,$C$3,doubles!$B$2:$B$431,C11)),"") | O11: =IFERROR(SUMIFS(doubles!$O$2:$O$431,doubles!$C$2:$C$431,$C$3,doubles!$B$2:$B$431,C11)/(SUMIFS(doubles!$O$2:$O$431,doubles!$C$2:$C$431,$C$3,doubles!$B$2:$B$431,C11)+SUMIFS(doubles!$P$2:$P$431,doubles!$C$2:$C$431,$C$3,doubles!$B$2:$B$431,C11)),"") | P11: =IFERROR((SUMIFS(doubles!$K$2:$K$431,doubles!$C$2:$C$431,$C$3,doubles!$B$2:$B$431,C11)+SUMIFS(doubles!$L$2:$L$431,doubles!$C$2:$C$431,$C$3,doubles!$B$2:$B$431,C11))/(2*COUNTIFS(doubles!$C$2:$C$431,$C$3,doubles!$B$2:$B$431,C11)),"") | Q11: =IFERROR(SUMIFS(doubles!$K$2:$K$431,doubles!$C$2:$C$431,$C$3,doubles!$B$2:$B$431,C11)/COUNTIFS(doubles!$C$2:$C$431,$C$3,doubles!$B$2:$B$431,C11),"") | R11: =IFERROR(SUMIFS(doubles!$L$2:$L$431,doubles!$C$2:$C$431,$C$3,doubles!$B$2:$B$431,C11)/COUNTIFS(doubles!$C$2:$C$431,$C$3,doubles!$B$2:$B$431,C11),"") | S11: =IFERROR((SUMIFS('Gun v Gun'!$C$2:$C$500,'Gun v Gun'!$A$2:$A$500,$C$3,'Gun v Gun'!$B$2:$B$500,C11,'Gun v Gun'!$F$2:$F$500,"atk")+SUMIFS('Gun v Gun'!$C$2:$C$500,'Gun v Gun'!$A$2:$A$500,$C$3,'Gun v Gun'!$B$2:$B$500,C11,'Gun v Gun'!$F$2:$F$500,"def"))/(SUMIFS('Gun v Gun'!$C$2:$C$500,'Gun v Gun'!$A$2:$A$500,$C$3,'Gun v Gun'!$B$2:$B$500,C11,'Gun v Gun'!$F$2:$F$500,"atk")+SUMIFS('Gun v Gun'!$D$2:$D$500,'Gun v Gun'!$A$2:$A$500,$C$3,'Gun v Gun'!$B$2:$B$500,C11,'Gun v Gun'!$F$2:$F$500,"atk")+SUMIFS('Gun v Gun'!$C$2:$C$500,'Gun v Gun'!$A$2:$A$500,$C$3,'Gun v Gun'!$B$2:$B$500,C11,'Gun v Gun'!$F$2:$F$500,"def")+SUMIFS('Gun v Gun'!$D$2:$D$500,'Gun v Gun'!$A$2:$A$500,$C$3,'Gun v Gun'!$B$2:$B$500,C11,'Gun v Gun'!$F$2:$F$500,"def")),"") | T11: =IFERROR(SUMIFS('Gun v Gun'!$C$2:$C$500,'Gun v Gun'!$A$2:$A$500,$C$3,'Gun v Gun'!$B$2:$B$500,C11,'Gun v Gun'!$F$2:$F$500,"atk")/(SUMIFS('Gun v Gun'!$C$2:$C$500,'Gun v Gun'!$A$2:$A$500,$C$3,'Gun v Gun'!$B$2:$B$500,C11,'Gun v Gun'!$F$2:$F$500,"atk")+SUMIFS('Gun v Gun'!$D$2:$D$500,'Gun v Gun'!$A$2:$A$500,$C$3,'Gun v Gun'!$B$2:$B$500,C11,'Gun v Gun'!$F$2:$F$500,"atk")),"") | U11: =IFERROR(SUMIFS('Gun v Gun'!$C$2:$C$500,'Gun v Gun'!$A$2:$A$500,$C$3,'Gun v Gun'!$B$2:$B$500,C11,'Gun v Gun'!$F$2:$F$500,"def")/(SUMIFS('Gun v Gun'!$C$2:$C$500,'Gun v Gun'!$A$2:$A$500,$C$3,'Gun v Gun'!$B$2:$B$500,C11,'Gun v Gun'!$F$2:$F$500,"def")+SUMIFS('Gun v Gun'!$D$2:$D$500,'Gun v Gun'!$A$2:$A$500,$C$3,'Gun v Gun'!$B$2:$B$500,C11,'Gun v Gun'!$F$2:$F$500,"def")),"") | V11: =IFERROR((SUMIFS('Antieco'!$C$2:$C$500,'Antieco'!$A$2:$A$500,$C$3,'Antieco'!$B$2:$B$500,C11,'Antieco'!$F$2:$F$500,"atk")+SUMIFS('Antieco'!$C$2:$C$500,'Antieco'!$A$2:$A$500,$C$3,'Antieco'!$B$2:$B$500,C11,'Antieco'!$F$2:$F$500,"def"))/(SUMIFS('Antieco'!$C$2:$C$500,'Antieco'!$A$2:$A$500,$C$3,'Antieco'!$B$2:$B$500,C11,'Antieco'!$F$2:$F$500,"atk")+SUMIFS('Antieco'!$D$2:$D$500,'Antieco'!$A$2:$A$500,$C$3,'Antieco'!$B$2:$B$500,C11,'Antieco'!$F$2:$F$500,"atk")+SUMIFS('Antieco'!$C$2:$C$500,'Antieco'!$A$2:$A$500,$C$3,'Antieco'!$B$2:$B$500,C11,'Antieco'!$F$2:$F$500,"def")+SUMIFS('Antieco'!$D$2:$D$500,'Antieco'!$A$2:$A$500,$C$3,'Antieco'!$B$2:$B$500,C11,'Antieco'!$F$2:$F$500,"def")),"") | W11: =IFERROR(SUMIFS('Antieco'!$C$2:$C$500,'Antieco'!$A$2:$A$500,$C$3,'Antieco'!$B$2:$B$500,C11,'Antieco'!$F$2:$F$500,"atk")/(SUMIFS('Antieco'!$C$2:$C$500,'Antieco'!$A$2:$A$500,$C$3,'Antieco'!$B$2:$B$500,C11,'Antieco'!$F$2:$F$500,"atk")+SUMIFS('Antieco'!$D$2:$D$500,'Antieco'!$A$2:$A$500,$C$3,'Antieco'!$B$2:$B$500,C11,'Antieco'!$F$2:$F$500,"atk")),"") | X11: =IFERROR(SUMIFS('Antieco'!$C$2:$C$500,'Antieco'!$A$2:$A$500,$C$3,'Antieco'!$B$2:$B$500,C11,'Antieco'!$F$2:$F$500,"def")/(SUMIFS('Antieco'!$C$2:$C$500,'Antieco'!$A$2:$A$500,$C$3,'Antieco'!$B$2:$B$500,C11,'Antieco'!$F$2:$F$500,"def")+SUMIFS('Antieco'!$D$2:$D$500,'Antieco'!$A$2:$A$500,$C$3,'Antieco'!$B$2:$B$500,C11,'Antieco'!$F$2:$F$500,"def")),"") | Y11: =IFERROR((SUMIFS('ecos'!$C$2:$C$500,'ecos'!$A$2:$A$500,$C$3,'ecos'!$B$2:$B$500,C11,'ecos'!$F$2:$F$500,"atk")+SUMIFS('ecos'!$C$2:$C$500,'ecos'!$A$2:$A$500,$C$3,'ecos'!$B$2:$B$500,C11,'ecos'!$F$2:$F$500,"def"))/(SUMIFS('ecos'!$C$2:$C$500,'ecos'!$A$2:$A$500,$C$3,'ecos'!$B$2:$B$500,C11,'ecos'!$F$2:$F$500,"atk")+SUMIFS('ecos'!$D$2:$D$500,'ecos'!$A$2:$A$500,$C$3,'ecos'!$B$2:$B$500,C11,'ecos'!$F$2:$F$500,"atk")+SUMIFS('ecos'!$C$2:$C$500,'ecos'!$A$2:$A$500,$C$3,'ecos'!$B$2:$B$500,C11,'ecos'!$F$2:$F$500,"def")+SUMIFS('ecos'!$D$2:$D$500,'ecos'!$A$2:$A$500,$C$3,'ecos'!$B$2:$B$500,C11,'ecos'!$F$2:$F$500,"def")),"") | Z11: =IFERROR(SUMIFS('ecos'!$C$2:$C$500,'ecos'!$A$2:$A$500,$C$3,'ecos'!$B$2:$B$500,C11,'ecos'!$F$2:$F$500,"atk")/(SUMIFS('ecos'!$C$2:$C$500,'ecos'!$A$2:$A$500,$C$3,'ecos'!$B$2:$B$500,C11,'ecos'!$F$2:$F$500,"atk")+SUMIFS('ecos'!$D$2:$D$500,'ecos'!$A$2:$A$500,$C$3,'ecos'!$B$2:$B$500,C11,'ecos'!$F$2:$F$500,"atk")),"") | AA11: =IFERROR(SUMIFS('ecos'!$C$2:$C$500,'ecos'!$A$2:$A$500,$C$3,'ecos'!$B$2:$B$500,C11,'ecos'!$F$2:$F$500,"def")/(SUMIFS('ecos'!$C$2:$C$500,'ecos'!$A$2:$A$500,$C$3,'ecos'!$B$2:$B$500,C11,'ecos'!$F$2:$F$500,"def")+SUMIFS('ecos'!$D$2:$D$500,'ecos'!$A$2:$A$500,$C$3,'ecos'!$B$2:$B$500,C11,'ecos'!$F$2:$F$500,"def")),"") | AC11: Haven | AD11: =SUMIFS('Post Plants'!$E$2:$E$500,'Post Plants'!$A$2:$A$500,$C$3,'Post Plants'!$B$2:$B$500,C11,'Post Plants'!$D$2:$D$500,"atk") | AE11: =SUMIFS(doubles!$M$2:$M$431,doubles!$C$2:$C$431,$C$3,doubles!$B$2:$B$431,C11)+SUMIFS(doubles!$N$2:$N$431,doubles!$C$2:$C$431,$C$3,doubles!$B$2:$B$431,C11) | AF11: =IFERROR(AD11/J11,"") | AG11: =IFERROR(SUMIFS('Post Plants'!$F$2:$F$500,'Post Plants'!$A$2:$A$500,$C$3,'Post Plants'!$B$2:$B$500,C11,'Post Plants'!$D$2:$D$500,"atk")/SUMIFS('Post Plants'!$E$2:$E$500,'Post Plants'!$A$2:$A$500,$C$3,'Post Plants'!$B$2:$B$500,C11,'Post Plants'!$D$2:$D$500,"atk"),"") | AI11: =SUMIFS('Post Plants'!$E$2:$E$500,'Post Plants'!$A$2:$A$500,$C$3,'Post Plants'!$B$2:$B$500,C11,'Post Plants'!$D$2:$D$500,"def") | AJ11: =SUMIFS(doubles!$O$2:$O$431,doubles!$C$2:$C$431,$C$3,doubles!$B$2:$B$431,C11)+SUMIFS(doubles!$P$2:$P$431,doubles!$C$2:$C$431,$C$3,doubles!$B$2:$B$431,C11) | AK11: =IFERROR(AI11/J11,"") | AL11: =IFERROR(SUMIFS('Post Plants'!$F$2:$F$500,'Post Plants'!$A$2:$A$500,$C$3,'Post Plants'!$B$2:$B$500,C11,'Post Plants'!$D$2:$D$500,"def")/SUMIFS('Post Plants'!$E$2:$E$500,'Post Plants'!$A$2:$A$500,$C$3,'Post Plants'!$B$2:$B$500,C11,'Post Plants'!$D$2:$D$500,"def"),"")
C12: Pearl | D12: =IFERROR(INDEX(doubles!$E$2:$E$431,MATCH(C12&"_"&$C$3,doubles!$S$2:$S$431&"_"&doubles!$C$2:$C$431,0)),"") | I12: =IFERROR(COUNTIFS(doubles!$C$2:$C$431,$C$3,doubles!$B$2:$B$431,C12,doubles!$E$2:$E$431,D12),"") | J12: =COUNTIFS(doubles!$C$2:$C$431,$C$3,doubles!$B$2:$B$431,C12) | K12: =COUNTIFS(doubles!$C$2:$C$431,$C$3,doubles!$B$2:$B$431,C12,doubles!$R$2:$R$431,$C$3) | L12: =J12-K12 | M12: =IFERROR((SUMIFS(doubles!$M$2:$M$431,doubles!$C$2:$C$431,$C$3,doubles!$B$2:$B$431,C12)+SUMIFS(doubles!$O$2:$O$431,doubles!$C$2:$C$431,$C$3,doubles!$B$2:$B$431,C12))/(SUMIFS(doubles!$M$2:$M$431,doubles!$C$2:$C$431,$C$3,doubles!$B$2:$B$431,C12)+SUMIFS(doubles!$N$2:$N$431,doubles!$C$2:$C$431,$C$3,doubles!$B$2:$B$431,C12)+SUMIFS(doubles!$O$2:$O$431,doubles!$C$2:$C$431,$C$3,doubles!$B$2:$B$431,C12)+SUMIFS(doubles!$P$2:$P$431,doubles!$C$2:$C$431,$C$3,doubles!$B$2:$B$431,C12)),"") | N12: =IFERROR(SUMIFS(doubles!$M$2:$M$431,doubles!$C$2:$C$431,$C$3,doubles!$B$2:$B$431,C12)/(SUMIFS(doubles!$M$2:$M$431,doubles!$C$2:$C$431,$C$3,doubles!$B$2:$B$431,C12)+SUMIFS(doubles!$N$2:$N$431,doubles!$C$2:$C$431,$C$3,doubles!$B$2:$B$431,C12)),"") | O12: =IFERROR(SUMIFS(doubles!$O$2:$O$431,doubles!$C$2:$C$431,$C$3,doubles!$B$2:$B$431,C12)/(SUMIFS(doubles!$O$2:$O$431,doubles!$C$2:$C$431,$C$3,doubles!$B$2:$B$431,C12)+SUMIFS(doubles!$P$2:$P$431,doubles!$C$2:$C$431,$C$3,doubles!$B$2:$B$431,C12)),"") | P12: =IFERROR((SUMIFS(doubles!$K$2:$K$431,doubles!$C$2:$C$431,$C$3,doubles!$B$2:$B$431,C12)+SUMIFS(doubles!$L$2:$L$431,doubles!$C$2:$C$431,$C$3,doubles!$B$2:$B$431,C12))/(2*COUNTIFS(doubles!$C$2:$C$431,$C$3,doubles!$B$2:$B$431,C12)),"") | Q12: =IFERROR(SUMIFS(doubles!$K$2:$K$431,doubles!$C$2:$C$431,$C$3,doubles!$B$2:$B$431,C12)/COUNTIFS(doubles!$C$2:$C$431,$C$3,doubles!$B$2:$B$431,C12),"") | R12: =IFERROR(SUMIFS(doubles!$L$2:$L$431,doubles!$C$2:$C$431,$C$3,doubles!$B$2:$B$431,C12)/COUNTIFS(doubles!$C$2:$C$431,$C$3,doubles!$B$2:$B$431,C12),"") | S12: =IFERROR((SUMIFS('Gun v Gun'!$C$2:$C$500,'Gun v Gun'!$A$2:$A$500,$C$3,'Gun v Gun'!$B$2:$B$500,C12,'Gun v Gun'!$F$2:$F$500,"atk")+SUMIFS('Gun v Gun'!$C$2:$C$500,'Gun v Gun'!$A$2:$A$500,$C$3,'Gun v Gun'!$B$2:$B$500,C12,'Gun v Gun'!$F$2:$F$500,"def"))/(SUMIFS('Gun v Gun'!$C$2:$C$500,'Gun v Gun'!$A$2:$A$500,$C$3,'Gun v Gun'!$B$2:$B$500,C12,'Gun v Gun'!$F$2:$F$500,"atk")+SUMIFS('Gun v Gun'!$D$2:$D$500,'Gun v Gun'!$A$2:$A$500,$C$3,'Gun v Gun'!$B$2:$B$500,C12,'Gun v Gun'!$F$2:$F$500,"atk")+SUMIFS('Gun v Gun'!$C$2:$C$500,'Gun v Gun'!$A$2:$A$500,$C$3,'Gun v Gun'!$B$2:$B$500,C12,'Gun v Gun'!$F$2:$F$500,"def")+SUMIFS('Gun v Gun'!$D$2:$D$500,'Gun v Gun'!$A$2:$A$500,$C$3,'Gun v Gun'!$B$2:$B$500,C12,'Gun v Gun'!$F$2:$F$500,"def")),"") | T12: =IFERROR(SUMIFS('Gun v Gun'!$C$2:$C$500,'Gun v Gun'!$A$2:$A$500,$C$3,'Gun v Gun'!$B$2:$B$500,C12,'Gun v Gun'!$F$2:$F$500,"atk")/(SUMIFS('Gun v Gun'!$C$2:$C$500,'Gun v Gun'!$A$2:$A$500,$C$3,'Gun v Gun'!$B$2:$B$500,C12,'Gun v Gun'!$F$2:$F$500,"atk")+SUMIFS('Gun v Gun'!$D$2:$D$500,'Gun v Gun'!$A$2:$A$500,$C$3,'Gun v Gun'!$B$2:$B$500,C12,'Gun v Gun'!$F$2:$F$500,"atk")),"") | U12: =IFERROR(SUMIFS('Gun v Gun'!$C$2:$C$500,'Gun v Gun'!$A$2:$A$500,$C$3,'Gun v Gun'!$B$2:$B$500,C12,'Gun v Gun'!$F$2:$F$500,"def")/(SUMIFS('Gun v Gun'!$C$2:$C$500,'Gun v Gun'!$A$2:$A$500,$C$3,'Gun v Gun'!$B$2:$B$500,C12,'Gun v Gun'!$F$2:$F$500,"def")+SUMIFS('Gun v Gun'!$D$2:$D$500,'Gun v Gun'!$A$2:$A$500,$C$3,'Gun v Gun'!$B$2:$B$500,C12,'Gun v Gun'!$F$2:$F$500,"def")),"") | V12: =IFERROR((SUMIFS('Antieco'!$C$2:$C$500,'Antieco'!$A$2:$A$500,$C$3,'Antieco'!$B$2:$B$500,C12,'Antieco'!$F$2:$F$500,"atk")+SUMIFS('Antieco'!$C$2:$C$500,'Antieco'!$A$2:$A$500,$C$3,'Antieco'!$B$2:$B$500,C12,'Antieco'!$F$2:$F$500,"def"))/(SUMIFS('Antieco'!$C$2:$C$500,'Antieco'!$A$2:$A$500,$C$3,'Antieco'!$B$2:$B$500,C12,'Antieco'!$F$2:$F$500,"atk")+SUMIFS('Antieco'!$D$2:$D$500,'Antieco'!$A$2:$A$500,$C$3,'Antieco'!$B$2:$B$500,C12,'Antieco'!$F$2:$F$500,"atk")+SUMIFS('Antieco'!$C$2:$C$500,'Antieco'!$A$2:$A$500,$C$3,'Antieco'!$B$2:$B$500,C12,'Antieco'!$F$2:$F$500,"def")+SUMIFS('Antieco'!$D$2:$D$500,'Antieco'!$A$2:$A$500,$C$3,'Antieco'!$B$2:$B$500,C12,'Antieco'!$F$2:$F$500,"def")),"") | W12: =IFERROR(SUMIFS('Antieco'!$C$2:$C$500,'Antieco'!$A$2:$A$500,$C$3,'Antieco'!$B$2:$B$500,C12,'Antieco'!$F$2:$F$500,"atk")/(SUMIFS('Antieco'!$C$2:$C$500,'Antieco'!$A$2:$A$500,$C$3,'Antieco'!$B$2:$B$500,C12,'Antieco'!$F$2:$F$500,"atk")+SUMIFS('Antieco'!$D$2:$D$500,'Antieco'!$A$2:$A$500,$C$3,'Antieco'!$B$2:$B$500,C12,'Antieco'!$F$2:$F$500,"atk")),"") | X12: =IFERROR(SUMIFS('Antieco'!$C$2:$C$500,'Antieco'!$A$2:$A$500,$C$3,'Antieco'!$B$2:$B$500,C12,'Antieco'!$F$2:$F$500,"def")/(SUMIFS('Antieco'!$C$2:$C$500,'Antieco'!$A$2:$A$500,$C$3,'Antieco'!$B$2:$B$500,C12,'Antieco'!$F$2:$F$500,"def")+SUMIFS('Antieco'!$D$2:$D$500,'Antieco'!$A$2:$A$500,$C$3,'Antieco'!$B$2:$B$500,C12,'Antieco'!$F$2:$F$500,"def")),"") | Y12: =IFERROR((SUMIFS('ecos'!$C$2:$C$500,'ecos'!$A$2:$A$500,$C$3,'ecos'!$B$2:$B$500,C12,'ecos'!$F$2:$F$500,"atk")+SUMIFS('ecos'!$C$2:$C$500,'ecos'!$A$2:$A$500,$C$3,'ecos'!$B$2:$B$500,C12,'ecos'!$F$2:$F$500,"def"))/(SUMIFS('ecos'!$C$2:$C$500,'ecos'!$A$2:$A$500,$C$3,'ecos'!$B$2:$B$500,C12,'ecos'!$F$2:$F$500,"atk")+SUMIFS('ecos'!$D$2:$D$500,'ecos'!$A$2:$A$500,$C$3,'ecos'!$B$2:$B$500,C12,'ecos'!$F$2:$F$500,"atk")+SUMIFS('ecos'!$C$2:$C$500,'ecos'!$A$2:$A$500,$C$3,'ecos'!$B$2:$B$500,C12,'ecos'!$F$2:$F$500,"def")+SUMIFS('ecos'!$D$2:$D$500,'ecos'!$A$2:$A$500,$C$3,'ecos'!$B$2:$B$500,C12,'ecos'!$F$2:$F$500,"def")),"") | Z12: =IFERROR(SUMIFS('ecos'!$C$2:$C$500,'ecos'!$A$2:$A$500,$C$3,'ecos'!$B$2:$B$500,C12,'ecos'!$F$2:$F$500,"atk")/(SUMIFS('ecos'!$C$2:$C$500,'ecos'!$A$2:$A$500,$C$3,'ecos'!$B$2:$B$500,C12,'ecos'!$F$2:$F$500,"atk")+SUMIFS('ecos'!$D$2:$D$500,'ecos'!$A$2:$A$500,$C$3,'ecos'!$B$2:$B$500,C12,'ecos'!$F$2:$F$500,"atk")),"") | AA12: =IFERROR(SUMIFS('ecos'!$C$2:$C$500,'ecos'!$A$2:$A$500,$C$3,'ecos'!$B$2:$B$500,C12,'ecos'!$F$2:$F$500,"def")/(SUMIFS('ecos'!$C$2:$C$500,'ecos'!$A$2:$A$500,$C$3,'ecos'!$B$2:$B$500,C12,'ecos'!$F$2:$F$500,"def")+SUMIFS('ecos'!$D$2:$D$500,'ecos'!$A$2:$A$500,$C$3,'ecos'!$B$2:$B$500,C12,'ecos'!$F$2:$F$500,"def")),"") | AC12: Pearl | AD12: =SUMIFS('Post Plants'!$E$2:$E$500,'Post Plants'!$A$2:$A$500,$C$3,'Post Plants'!$B$2:$B$500,C12,'Post Plants'!$D$2:$D$500,"atk") | AE12: =SUMIFS(doubles!$M$2:$M$431,doubles!$C$2:$C$431,$C$3,doubles!$B$2:$B$431,C12)+SUMIFS(doubles!$N$2:$N$431,doubles!$C$2:$C$431,$C$3,doubles!$B$2:$B$431,C12) | AF12: =IFERROR(AD12/J12,"") | AG12: =IFERROR(SUMIFS('Post Plants'!$F$2:$F$500,'Post Plants'!$A$2:$A$500,$C$3,'Post Plants'!$B$2:$B$500,C12,'Post Plants'!$D$2:$D$500,"atk")/SUMIFS('Post Plants'!$E$2:$E$500,'Post Plants'!$A$2:$A$500,$C$3,'Post Plants'!$B$2:$B$500,C12,'Post Plants'!$D$2:$D$500,"atk"),"") | AI12: =SUMIFS('Post Plants'!$E$2:$E$500,'Post Plants'!$A$2:$A$500,$C$3,'Post Plants'!$B$2:$B$500,C12,'Post Plants'!$D$2:$D$500,"def") | AJ12: =SUMIFS(doubles!$O$2:$O$431,doubles!$C$2:$C$431,$C$3,doubles!$B$2:$B$431,C12)+SUMIFS(doubles!$P$2:$P$431,doubles!$C$2:$C$431,$C$3,doubles!$B$2:$B$431,C12) | AK12: =IFERROR(AI12/J12,"") | AL12: =IFERROR(SUMIFS('Post Plants'!$F$2:$F$500,'Post Plants'!$A$2:$A$500,$C$3,'Post Plants'!$B$2:$B$500,C12,'Post Plants'!$D$2:$D$500,"def")/SUMIFS('Post Plants'!$E$2:$E$500,'Post Plants'!$A$2:$A$500,$C$3,'Post Plants'!$B$2:$B$500,C12,'Post Plants'!$D$2:$D$500,"def"),"")
C13: Split | D13: =IFERROR(INDEX(doubles!$E$2:$E$431,MATCH(C13&"_"&$C$3,doubles!$S$2:$S$431&"_"&doubles!$C$2:$C$431,0)),"") | I13: =IFERROR(COUNTIFS(doubles!$C$2:$C$431,$C$3,doubles!$B$2:$B$431,C13,doubles!$E$2:$E$431,D13),"") | J13: =COUNTIFS(doubles!$C$2:$C$431,$C$3,doubles!$B$2:$B$431,C13) | K13: =COUNTIFS(doubles!$C$2:$C$431,$C$3,doubles!$B$2:$B$431,C13,doubles!$R$2:$R$431,$C$3) | L13: =J13-K13 | M13: =IFERROR((SUMIFS(doubles!$M$2:$M$431,doubles!$C$2:$C$431,$C$3,doubles!$B$2:$B$431,C13)+SUMIFS(doubles!$O$2:$O$431,doubles!$C$2:$C$431,$C$3,doubles!$B$2:$B$431,C13))/(SUMIFS(doubles!$M$2:$M$431,doubles!$C$2:$C$431,$C$3,doubles!$B$2:$B$431,C13)+SUMIFS(doubles!$N$2:$N$431,doubles!$C$2:$C$431,$C$3,doubles!$B$2:$B$431,C13)+SUMIFS(doubles!$O$2:$O$431,doubles!$C$2:$C$431,$C$3,doubles!$B$2:$B$431,C13)+SUMIFS(doubles!$P$2:$P$431,doubles!$C$2:$C$431,$C$3,doubles!$B$2:$B$431,C13)),"") | N13: =IFERROR(SUMIFS(doubles!$M$2:$M$431,doubles!$C$2:$C$431,$C$3,doubles!$B$2:$B$431,C13)/(SUMIFS(doubles!$M$2:$M$431,doubles!$C$2:$C$431,$C$3,doubles!$B$2:$B$431,C13)+SUMIFS(doubles!$N$2:$N$431,doubles!$C$2:$C$431,$C$3,doubles!$B$2:$B$431,C13)),"") | O13: =IFERROR(SUMIFS(doubles!$O$2:$O$431,doubles!$C$2:$C$431,$C$3,doubles!$B$2:$B$431,C13)/(SUMIFS(doubles!$O$2:$O$431,doubles!$C$2:$C$431,$C$3,doubles!$B$2:$B$431,C13)+SUMIFS(doubles!$P$2:$P$431,doubles!$C$2:$C$431,$C$3,doubles!$B$2:$B$431,C13)),"") | P13: =IFERROR((SUMIFS(doubles!$K$2:$K$431,doubles!$C$2:$C$431,$C$3,doubles!$B$2:$B$431,C13)+SUMIFS(doubles!$L$2:$L$431,doubles!$C$2:$C$431,$C$3,doubles!$B$2:$B$431,C13))/(2*COUNTIFS(doubles!$C$2:$C$431,$C$3,doubles!$B$2:$B$431,C13)),"") | Q13: =IFERROR(SUMIFS(doubles!$K$2:$K$431,doubles!$C$2:$C$431,$C$3,doubles!$B$2:$B$431,C13)/COUNTIFS(doubles!$C$2:$C$431,$C$3,doubles!$B$2:$B$431,C13),"") | R13: =IFERROR(SUMIFS(doubles!$L$2:$L$431,doubles!$C$2:$C$431,$C$3,doubles!$B$2:$B$431,C13)/COUNTIFS(doubles!$C$2:$C$431,$C$3,doubles!$B$2:$B$431,C13),"") | S13: =IFERROR((SUMIFS('Gun v Gun'!$C$2:$C$500,'Gun v Gun'!$A$2:$A$500,$C$3,'Gun v Gun'!$B$2:$B$500,C13,'Gun v Gun'!$F$2:$F$500,"atk")+SUMIFS('Gun v Gun'!$C$2:$C$500,'Gun v Gun'!$A$2:$A$500,$C$3,'Gun v Gun'!$B$2:$B$500,C13,'Gun v Gun'!$F$2:$F$500,"def"))/(SUMIFS('Gun v Gun'!$C$2:$C$500,'Gun v Gun'!$A$2:$A$500,$C$3,'Gun v Gun'!$B$2:$B$500,C13,'Gun v Gun'!$F$2:$F$500,"atk")+SUMIFS('Gun v Gun'!$D$2:$D$500,'Gun v Gun'!$A$2:$A$500,$C$3,'Gun v Gun'!$B$2:$B$500,C13,'Gun v Gun'!$F$2:$F$500,"atk")+SUMIFS('Gun v Gun'!$C$2:$C$500,'Gun v Gun'!$A$2:$A$500,$C$3,'Gun v Gun'!$B$2:$B$500,C13,'Gun v Gun'!$F$2:$F$500,"def")+SUMIFS('Gun v Gun'!$D$2:$D$500,'Gun v Gun'!$A$2:$A$500,$C$3,'Gun v Gun'!$B$2:$B$500,C13,'Gun v Gun'!$F$2:$F$500,"def")),"") | T13: =IFERROR(SUMIFS('Gun v Gun'!$C$2:$C$500,'Gun v Gun'!$A$2:$A$500,$C$3,'Gun v Gun'!$B$2:$B$500,C13,'Gun v Gun'!$F$2:$F$500,"atk")/(SUMIFS('Gun v Gun'!$C$2:$C$500,'Gun v Gun'!$A$2:$A$500,$C$3,'Gun v Gun'!$B$2:$B$500,C13,'Gun v Gun'!$F$2:$F$500,"atk")+SUMIFS('Gun v Gun'!$D$2:$D$500,'Gun v Gun'!$A$2:$A$500,$C$3,'Gun v Gun'!$B$2:$B$500,C13,'Gun v Gun'!$F$2:$F$500,"atk")),"") | U13: =IFERROR(SUMIFS('Gun v Gun'!$C$2:$C$500,'Gun v Gun'!$A$2:$A$500,$C$3,'Gun v Gun'!$B$2:$B$500,C13,'Gun v Gun'!$F$2:$F$500,"def")/(SUMIFS('Gun v Gun'!$C$2:$C$500,'Gun v Gun'!$A$2:$A$500,$C$3,'Gun v Gun'!$B$2:$B$500,C13,'Gun v Gun'!$F$2:$F$500,"def")+SUMIFS('Gun v Gun'!$D$2:$D$500,'Gun v Gun'!$A$2:$A$500,$C$3,'Gun v Gun'!$B$2:$B$500,C13,'Gun v Gun'!$F$2:$F$500,"def")),"") | V13: =IFERROR((SUMIFS('Antieco'!$C$2:$C$500,'Antieco'!$A$2:$A$500,$C$3,'Antieco'!$B$2:$B$500,C13,'Antieco'!$F$2:$F$500,"atk")+SUMIFS('Antieco'!$C$2:$C$500,'Antieco'!$A$2:$A$500,$C$3,'Antieco'!$B$2:$B$500,C13,'Antieco'!$F$2:$F$500,"def"))/(SUMIFS('Antieco'!$C$2:$C$500,'Antieco'!$A$2:$A$500,$C$3,'Antieco'!$B$2:$B$500,C13,'Antieco'!$F$2:$F$500,"atk")+SUMIFS('Antieco'!$D$2:$D$500,'Antieco'!$A$2:$A$500,$C$3,'Antieco'!$B$2:$B$500,C13,'Antieco'!$F$2:$F$500,"atk")+SUMIFS('Antieco'!$C$2:$C$500,'Antieco'!$A$2:$A$500,$C$3,'Antieco'!$B$2:$B$500,C13,'Antieco'!$F$2:$F$500,"def")+SUMIFS('Antieco'!$D$2:$D$500,'Antieco'!$A$2:$A$500,$C$3,'Antieco'!$B$2:$B$500,C13,'Antieco'!$F$2:$F$500,"def")),"") | W13: =IFERROR(SUMIFS('Antieco'!$C$2:$C$500,'Antieco'!$A$2:$A$500,$C$3,'Antieco'!$B$2:$B$500,C13,'Antieco'!$F$2:$F$500,"atk")/(SUMIFS('Antieco'!$C$2:$C$500,'Antieco'!$A$2:$A$500,$C$3,'Antieco'!$B$2:$B$500,C13,'Antieco'!$F$2:$F$500,"atk")+SUMIFS('Antieco'!$D$2:$D$500,'Antieco'!$A$2:$A$500,$C$3,'Antieco'!$B$2:$B$500,C13,'Antieco'!$F$2:$F$500,"atk")),"") | X13: =IFERROR(SUMIFS('Antieco'!$C$2:$C$500,'Antieco'!$A$2:$A$500,$C$3,'Antieco'!$B$2:$B$500,C13,'Antieco'!$F$2:$F$500,"def")/(SUMIFS('Antieco'!$C$2:$C$500,'Antieco'!$A$2:$A$500,$C$3,'Antieco'!$B$2:$B$500,C13,'Antieco'!$F$2:$F$500,"def")+SUMIFS('Antieco'!$D$2:$D$500,'Antieco'!$A$2:$A$500,$C$3,'Antieco'!$B$2:$B$500,C13,'Antieco'!$F$2:$F$500,"def")),"") | Y13: =IFERROR((SUMIFS('ecos'!$C$2:$C$500,'ecos'!$A$2:$A$500,$C$3,'ecos'!$B$2:$B$500,C13,'ecos'!$F$2:$F$500,"atk")+SUMIFS('ecos'!$C$2:$C$500,'ecos'!$A$2:$A$500,$C$3,'ecos'!$B$2:$B$500,C13,'ecos'!$F$2:$F$500,"def"))/(SUMIFS('ecos'!$C$2:$C$500,'ecos'!$A$2:$A$500,$C$3,'ecos'!$B$2:$B$500,C13,'ecos'!$F$2:$F$500,"atk")+SUMIFS('ecos'!$D$2:$D$500,'ecos'!$A$2:$A$500,$C$3,'ecos'!$B$2:$B$500,C13,'ecos'!$F$2:$F$500,"atk")+SUMIFS('ecos'!$C$2:$C$500,'ecos'!$A$2:$A$500,$C$3,'ecos'!$B$2:$B$500,C13,'ecos'!$F$2:$F$500,"def")+SUMIFS('ecos'!$D$2:$D$500,'ecos'!$A$2:$A$500,$C$3,'ecos'!$B$2:$B$500,C13,'ecos'!$F$2:$F$500,"def")),"") | Z13: =IFERROR(SUMIFS('ecos'!$C$2:$C$500,'ecos'!$A$2:$A$500,$C$3,'ecos'!$B$2:$B$500,C13,'ecos'!$F$2:$F$500,"atk")/(SUMIFS('ecos'!$C$2:$C$500,'ecos'!$A$2:$A$500,$C$3,'ecos'!$B$2:$B$500,C13,'ecos'!$F$2:$F$500,"atk")+SUMIFS('ecos'!$D$2:$D$500,'ecos'!$A$2:$A$500,$C$3,'ecos'!$B$2:$B$500,C13,'ecos'!$F$2:$F$500,"atk")),"") | AA13: =IFERROR(SUMIFS('ecos'!$C$2:$C$500,'ecos'!$A$2:$A$500,$C$3,'ecos'!$B$2:$B$500,C13,'ecos'!$F$2:$F$500,"def")/(SUMIFS('ecos'!$C$2:$C$500,'ecos'!$A$2:$A$500,$C$3,'ecos'!$B$2:$B$500,C13,'ecos'!$F$2:$F$500,"def")+SUMIFS('ecos'!$D$2:$D$500,'ecos'!$A$2:$A$500,$C$3,'ecos'!$B$2:$B$500,C13,'ecos'!$F$2:$F$500,"def")),"") | AC13: Split | AD13: =SUMIFS('Post Plants'!$E$2:$E$500,'Post Plants'!$A$2:$A$500,$C$3,'Post Plants'!$B$2:$B$500,C13,'Post Plants'!$D$2:$D$500,"atk") | AE13: =SUMIFS(doubles!$M$2:$M$431,doubles!$C$2:$C$431,$C$3,doubles!$B$2:$B$431,C13)+SUMIFS(doubles!$N$2:$N$431,doubles!$C$2:$C$431,$C$3,doubles!$B$2:$B$431,C13) | AF13: =IFERROR(AD13/J13,"") | AG13: =IFERROR(SUMIFS('Post Plants'!$F$2:$F$500,'Post Plants'!$A$2:$A$500,$C$3,'Post Plants'!$B$2:$B$500,C13,'Post Plants'!$D$2:$D$500,"atk")/SUMIFS('Post Plants'!$E$2:$E$500,'Post Plants'!$A$2:$A$500,$C$3,'Post Plants'!$B$2:$B$500,C13,'Post Plants'!$D$2:$D$500,"atk"),"") | AI13: =SUMIFS('Post Plants'!$E$2:$E$500,'Post Plants'!$A$2:$A$500,$C$3,'Post Plants'!$B$2:$B$500,C13,'Post Plants'!$D$2:$D$500,"def") | AJ13: =SUMIFS(doubles!$O$2:$O$431,doubles!$C$2:$C$431,$C$3,doubles!$B$2:$B$431,C13)+SUMIFS(doubles!$P$2:$P$431,doubles!$C$2:$C$431,$C$3,doubles!$B$2:$B$431,C13) | AK13: =IFERROR(AI13/J13,"") | AL13: =IFERROR(SUMIFS('Post Plants'!$F$2:$F$500,'Post Plants'!$A$2:$A$500,$C$3,'Post Plants'!$B$2:$B$500,C13,'Post Plants'!$D$2:$D$500,"def")/SUMIFS('Post Plants'!$E$2:$E$500,'Post Plants'!$A$2:$A$500,$C$3,'Post Plants'!$B$2:$B$500,C13,'Post Plants'!$D$2:$D$500,"def"),"")
C14: All Maps | J14: =COUNTIFS(doubles!$C$2:$C$431,$C$3) | K14: =COUNTIFS(doubles!$C$2:$C$431,$C$3,doubles!$R$2:$R$431,$C$3) | L14: =J14-K14 | M14: =IFERROR((SUMIFS(doubles!$M$2:$M$431,doubles!$C$2:$C$431,$C$3)+SUMIFS(doubles!$O$2:$O$431,doubles!$C$2:$C$431,$C$3))/(SUMIFS(doubles!$M$2:$M$431,doubles!$C$2:$C$431,$C$3)+SUMIFS(doubles!$N$2:$N$431,doubles!$C$2:$C$431,$C$3)+SUMIFS(doubles!$O$2:$O$431,doubles!$C$2:$C$431,$C$3)+SUMIFS(doubles!$P$2:$P$431,doubles!$C$2:$C$431,$C$3)),"") | N14: =IFERROR(SUMIFS(doubles!$M$2:$M$431,doubles!$C$2:$C$431,$C$3)/(SUMIFS(doubles!$M$2:$M$431,doubles!$C$2:$C$431,$C$3)+SUMIFS(doubles!$N$2:$N$431,doubles!$C$2:$C$431,$C$3)),"") | O14: =IFERROR(SUMIFS(doubles!$O$2:$O$431,doubles!$C$2:$C$431,$C$3)/(SUMIFS(doubles!$O$2:$O$431,doubles!$C$2:$C$431,$C$3)+SUMIFS(doubles!$P$2:$P$431,doubles!$C$2:$C$431,$C$3)),"") | P14: =IFERROR((SUMIFS(doubles!$K$2:$K$431,doubles!$C$2:$C$431,$C$3)+SUMIFS(doubles!$L$2:$L$431,doubles!$C$2:$C$431,$C$3))/(2*COUNTIFS(doubles!$C$2:$C$431,$C$3)),"") | Q14: =IFERROR(SUMIFS(doubles!$K$2:$K$431,doubles!$C$2:$C$431,$C$3)/COUNTIFS(doubles!$C$2:$C$431,$C$3),"") | R14: =IFERROR(SUMIFS(doubles!$L$2:$L$431,doubles!$C$2:$C$431,$C$3)/COUNTIFS(doubles!$C$2:$C$431,$C$3),"") | S14: =IFERROR((SUMIFS('Gun v Gun'!$C$2:$C$500,'Gun v Gun'!$A$2:$A$500,$C$3,'Gun v Gun'!$F$2:$F$500,"atk")+SUMIFS('Gun v Gun'!$C$2:$C$500,'Gun v Gun'!$A$2:$A$500,$C$3,'Gun v Gun'!$F$2:$F$500,"def"))/(SUMIFS('Gun v Gun'!$C$2:$C$500,'Gun v Gun'!$A$2:$A$500,$C$3,'Gun v Gun'!$F$2:$F$500,"atk")+SUMIFS('Gun v Gun'!$D$2:$D$500,'Gun v Gun'!$A$2:$A$500,$C$3,'Gun v Gun'!$F$2:$F$500,"atk")+SUMIFS('Gun v Gun'!$C$2:$C$500,'Gun v Gun'!$A$2:$A$500,$C$3,'Gun v Gun'!$F$2:$F$500,"def")+SUMIFS('Gun v Gun'!$D$2:$D$500,'Gun v Gun'!$A$2:$A$500,$C$3,'Gun v Gun'!$F$2:$F$500,"def")),"") | T14: =IFERROR(SUMIFS('Gun v Gun'!$C$2:$C$500,'Gun v Gun'!$A$2:$A$500,$C$3,'Gun v Gun'!$F$2:$F$500,"atk")/(SUMIFS('Gun v Gun'!$C$2:$C$500,'Gun v Gun'!$A$2:$A$500,$C$3,'Gun v Gun'!$F$2:$F$500,"atk")+SUMIFS('Gun v Gun'!$D$2:$D$500,'Gun v Gun'!$A$2:$A$500,$C$3,'Gun v Gun'!$F$2:$F$500,"atk")),"") | U14: =IFERROR(SUMIFS('Gun v Gun'!$C$2:$C$500,'Gun v Gun'!$A$2:$A$500,$C$3,'Gun v Gun'!$F$2:$F$500,"def")/(SUMIFS('Gun v Gun'!$C$2:$C$500,'Gun v Gun'!$A$2:$A$500,$C$3,'Gun v Gun'!$F$2:$F$500,"def")+SUMIFS('Gun v Gun'!$D$2:$D$500,'Gun v Gun'!$A$2:$A$500,$C$3,'Gun v Gun'!$F$2:$F$500,"def")),"") | V14: =IFERROR((SUMIFS('Antieco'!$C$2:$C$500,'Antieco'!$A$2:$A$500,$C$3,'Antieco'!$F$2:$F$500,"atk")+SUMIFS('Antieco'!$C$2:$C$500,'Antieco'!$A$2:$A$500,$C$3,'Antieco'!$F$2:$F$500,"def"))/(SUMIFS('Antieco'!$C$2:$C$500,'Antieco'!$A$2:$A$500,$C$3,'Antieco'!$F$2:$F$500,"atk")+SUMIFS('Antieco'!$D$2:$D$500,'Antieco'!$A$2:$A$500,$C$3,'Antieco'!$F$2:$F$500,"atk")+SUMIFS('Antieco'!$C$2:$C$500,'Antieco'!$A$2:$A$500,$C$3,'Antieco'!$F$2:$F$500,"def")+SUMIFS('Antieco'!$D$2:$D$500,'Antieco'!$A$2:$A$500,$C$3,'Antieco'!$F$2:$F$500,"def")),"") | W14: =IFERROR(SUMIFS('Antieco'!$C$2:$C$500,'Antieco'!$A$2:$A$500,$C$3,'Antieco'!$F$2:$F$500,"atk")/(SUMIFS('Antieco'!$C$2:$C$500,'Antieco'!$A$2:$A$500,$C$3,'Antieco'!$F$2:$F$500,"atk")+SUMIFS('Antieco'!$D$2:$D$500,'Antieco'!$A$2:$A$500,$C$3,'Antieco'!$F$2:$F$500,"atk")),"") | X14: =IFERROR(SUMIFS('Antieco'!$C$2:$C$500,'Antieco'!$A$2:$A$500,$C$3,'Antieco'!$F$2:$F$500,"def")/(SUMIFS('Antieco'!$C$2:$C$500,'Antieco'!$A$2:$A$500,$C$3,'Antieco'!$F$2:$F$500,"def")+SUMIFS('Antieco'!$D$2:$D$500,'Antieco'!$A$2:$A$500,$C$3,'Antieco'!$F$2:$F$500,"def")),"") | Y14: =IFERROR((SUMIFS('ecos'!$C$2:$C$500,'ecos'!$A$2:$A$500,$C$3,'ecos'!$F$2:$F$500,"atk")+SUMIFS('ecos'!$C$2:$C$500,'ecos'!$A$2:$A$500,$C$3,'ecos'!$F$2:$F$500,"def"))/(SUMIFS('ecos'!$C$2:$C$500,'ecos'!$A$2:$A$500,$C$3,'ecos'!$F$2:$F$500,"atk")+SUMIFS('ecos'!$D$2:$D$500,'ecos'!$A$2:$A$500,$C$3,'ecos'!$F$2:$F$500,"atk")+SUMIFS('ecos'!$C$2:$C$500,'ecos'!$A$2:$A$500,$C$3,'ecos'!$F$2:$F$500,"def")+SUMIFS('ecos'!$D$2:$D$500,'ecos'!$A$2:$A$500,$C$3,'ecos'!$F$2:$F$500,"def")),"") | Z14: =IFERROR(SUMIFS('ecos'!$C$2:$C$500,'ecos'!$A$2:$A$500,$C$3,'ecos'!$F$2:$F$500,"atk")/(SUMIFS('ecos'!$C$2:$C$500,'ecos'!$A$2:$A$500,$C$3,'ecos'!$F$2:$F$500,"atk")+SUMIFS('ecos'!$D$2:$D$500,'ecos'!$A$2:$A$500,$C$3,'ecos'!$F$2:$F$500,"atk")),"") | AA14: =IFERROR(SUMIFS('ecos'!$C$2:$C$500,'ecos'!$A$2:$A$500,$C$3,'ecos'!$F$2:$F$500,"def")/(SUMIFS('ecos'!$C$2:$C$500,'ecos'!$A$2:$A$500,$C$3,'ecos'!$F$2:$F$500,"def")+SUMIFS('ecos'!$D$2:$D$500,'ecos'!$A$2:$A$500,$C$3,'ecos'!$F$2:$F$500,"def")),"") | AC14: All Maps | AD14: =SUMIFS('Post Plants'!$E$2:$E$500,'Post Plants'!$A$2:$A$500,$C$3,'Post Plants'!$D$2:$D$500,"atk") | AE14: =SUMIFS(doubles!$M$2:$M$431,doubles!$C$2:$C$431,$C$3)+SUMIFS(doubles!$N$2:$N$431,doubles!$C$2:$C$431,$C$3) | AF14: =IFERROR(AD14/J14,"") | AG14: =IFERROR(SUMIFS('Post Plants'!$F$2:$F$500,'Post Plants'!$A$2:$A$500,$C$3,'Post Plants'!$D$2:$D$500,"atk")/SUMIFS('Post Plants'!$E$2:$E$500,'Post Plants'!$A$2:$A$500,$C$3,'Post Plants'!$D$2:$D$500,"atk"),"") | AI14: =SUMIFS('Post Plants'!$E$2:$E$500,'Post Plants'!$A$2:$A$500,$C$3,'Post Plants'!$D$2:$D$500,"def") | AJ14: =SUMIFS(doubles!$O$2:$O$431,doubles!$C$2:$C$431,$C$3)+SUMIFS(doubles!$P$2:$P$431,doubles!$C$2:$C$431,$C$3) | AK14: =IFERROR(AI14/J14,"") | AL14: =IFERROR(SUMIFS('Post Plants'!$F$2:$F$500,'Post Plants'!$A$2:$A$500,$C$3,'Post Plants'!$D$2:$D$500,"def")/SUMIFS('Post Plants'!$E$2:$E$500,'Post Plants'!$A$2:$A$500,$C$3,'Post Plants'!$D$2:$D$500,"def"),"")
C17: Statistics Per Player | S17: Team XvY
C18: Players | D18: Agents | I18: r | J18: K/D | K18: KA/D | L18: KAST | M18: fk/r | N18: fd/r | O18: fk/fd | P18: CL% | Q18: AWP% | S18: X v Y | T18: 5 | U18: 4 | V18: 3 | W18: 2 | X18: 1
C19: =IFERROR(INDEX('Player Stats'!$B$2:$B$200,MATCH(LARGE(IF('Player Stats'!$A$2:$A$200=$C$3,'Player Stats'!$E$2:$E$200),1),IF('Player Stats'!$A$2:$A$200=$C$3,'Player Stats'!$E$2:$E$200),0)),"") | I19: =IFERROR(INDEX('Player Stats'!$D$2:$D$200,MATCH(C19,'Player Stats'!$B$2:$B$200,0)),"") | J19: =IFERROR(INDEX('Player Stats'!$J$2:$J$200,MATCH(C19,'Player Stats'!$B$2:$B$200,0)),"") | K19: =IFERROR(INDEX('Player Stats'!$K$2:$K$200,MATCH(C19,'Player Stats'!$B$2:$B$200,0)),"") | L19: =IFERROR(INDEX('Player Stats'!$P$2:$P$200,MATCH(C19,'Player Stats'!$B$2:$B$200,0)),"") | M19: =IFERROR(INDEX('Player Stats'!$H$2:$H$200,MATCH(C19,'Player Stats'!$B$2:$B$200,0))/INDEX('Player Stats'!$D$2:$D$200,MATCH(C19,'Player Stats'!$B$2:$B$200,0)),"") | N19: =IFERROR(INDEX('Player Stats'!$I$2:$I$200,MATCH(C19,'Player Stats'!$B$2:$B$200,0))/INDEX('Player Stats'!$D$2:$D$200,MATCH(C19,'Player Stats'!$B$2:$B$200,0)),"") | O19: =IFERROR(INDEX('Player Stats'!$L$2:$L$200,MATCH(C19,'Player Stats'!$B$2:$B$200,0)),"") | P19: =IFERROR(INDEX('Player Stats'!$O$2:$O$200,MATCH(C19,'Player Stats'!$B$2:$B$200,0)),"") | Q19: =IFERROR(INDEX('Player Stats'!$Q$2:$Q$200,MATCH(C19,'Player Stats'!$B$2:$B$200,0)),"") | S19: 5 | T19: =IFERROR(SUMIFS(XvY!$F$2:$F$500,XvY!$A$2:$A$500,$C$3,XvY!$B$2:$B$500,"5v5")/(SUMIFS(XvY!$F$2:$F$500,XvY!$A$2:$A$500,$C$3,XvY!$B$2:$B$500,"5v5")+SUMIFS(XvY!$G$2:$G$500,XvY!$A$2:$A$500,$C$3,XvY!$B$2:$B$500,"5v5")),"") | U19: =IFERROR(SUMIFS(XvY!$F$2:$F$500,XvY!$A$2:$A$500,$C$3,XvY!$B$2:$B$500,"5v4")/(SUMIFS(XvY!$F$2:$F$500,XvY!$A$2:$A$500,$C$3,XvY!$B$2:$B$500,"5v4")+SUMIFS(XvY!$G$2:$G$500,XvY!$A$2:$A$500,$C$3,XvY!$B$2:$B$500,"5v4")),"") | V19: =IFERROR(SUMIFS(XvY!$F$2:$F$500,XvY!$A$2:$A$500,$C$3,XvY!$B$2:$B$500,"5v3")/(SUMIFS(XvY!$F$2:$F$500,XvY!$A$2:$A$500,$C$3,XvY!$B$2:$B$500,"5v3")+SUMIFS(XvY!$G$2:$G$500,XvY!$A$2:$A$500,$C$3,XvY!$B$2:$B$500,"5v3")),"") | W19: =IFERROR(SUMIFS(XvY!$F$2:$F$500,XvY!$A$2:$A$500,$C$3,XvY!$B$2:$B$500,"5v2")/(SUMIFS(XvY!$F$2:$F$500,XvY!$A$2:$A$500,$C$3,XvY!$B$2:$B$500,"5v2")+SUMIFS(XvY!$G$2:$G$500,XvY!$A$2:$A$500,$C$3,XvY!$B$2:$B$500,"5v2")),"") | X19: =IFERROR(SUMIFS(XvY!$F$2:$F$500,XvY!$A$2:$A$500,$C$3,XvY!$B$2:$B$500,"5v1")/(SUMIFS(XvY!$F$2:$F$500,XvY!$A$2:$A$500,$C$3,XvY!$B$2:$B$500,"5v1")+SUMIFS(XvY!$G$2:$G$500,XvY!$A$2:$A$500,$C$3,XvY!$B$2:$B$500,"5v1")),"")
