Workbook
Name teams: Assets!$H$2:$H$15

Sheet Team View
C2: Team
C3: Team Liquid Academy
C5: Team Statistics | J5: Map | M5: All Rounds | P5: Pistols | S5: Gun | V5: Anti Eco | Y5: Eco | AC5: Post Plant
C6: Maps | D6: Comp | I6: x | J6: Plays | K6: Win | L6: Loss | M6: rW% | N6: aW% | O6: dW% | P6: rW% | Q6: aW% | R6: dW% | S6: rW% | T6: aW% | U6: dW% | V6: rW% | W6: aW% | X6: dW% | Y6: rW% | Z6: aW% | AA6: dW% | AC6: Map | AE6: post scens | AF6: t rounds | AG6: post /Map | AH6: post rW% | AI6: post rW% event avg. | AJ6: post rank | AK6: ret. scens | AL6: ct rounds | AM6: ret. /Map | AN6: ret. rW% | AO6: ret. rW% event avg. | AP6: ret rank
B7: {=XLOOKUP(""&C3&"_"&C7:C15&"",SelectedTeamStats!Z2:Z27,SelectedTeamStats!G2:G27)} -> Sova,Omen,Yoru,Vyse,Waylay | C7: {=UNIQUE(doubles!D2:D27)} -> Ascent | D7: =IFERROR(__xludf.DUMMYFUNCTION("iferror(ARRAYFORMULA(xlookup(split(XLOOKUP(""""&C3&""_""&C7:C15&"""",SelectedTeamStats!Z2:Z27,SelectedTeamStats!G2:G27),"",""),Assets!A2:A27,Assets!C2:C27)))"),"") | E7: =IFERROR(__xludf.DUMMYFUNCTION("""COMPUTED_VALUE"""),"") | F7: =IFERROR(__xludf.DUMMYFUNCTION("""COMPUTED_VALUE"""),"") | G7: =IFERROR(__xludf.DUMMYFUNCTION("""COMPUTED_VALUE"""),"") | H7: =IFERROR(__xludf.DUMMYFUNCTION("""COMPUTED_VALUE"""),"") | I7: {=COUNTIF(SelectedTeamStats!AB2:AB27 ,""&C7:C15&"_"&B7:B15&"")} -> 6 | J7: {=COUNTIF(SelectedTeamStats!D2:D27,C7:C15)} -> 6 | K7: {=COUNTIFS(SelectedTeamStats!$D$2:$D27,C7:C15,SelectedTeamStats!$AA$2:$AA27,$C$3)} -> 4 | L7: {=J7:J15-K7:K15} -> 2 | M7: {=iferror(SUMIF(SelectedTeamStats!$D$2:$D27,C7:C15,SelectedTeamStats!$I$2:$I27)/(SUMIF(SelectedTeamStats!$D$2:$D27,C7:C15,SelectedTeamStats!$I$2:$I27)+SUMIF(SelectedTeamStats!$D$2:$D27,C7:C15,SelectedTeamStats!$J$2:$J27)),)} -> 0.6146789 | N7: {=iferror(SUMIF(SelectedTeamStats!$D$2:$D27,C7:C15,SelectedTeamStats!$O$2:$O27)/(SUMIF(SelectedTeamStats!$D$2:$D27,C7:C15,SelectedTeamStats!$O$2:$O27)+SUMIF(SelectedTeamStats!$D$2:$D27,C7:C15,SelectedTeamStats!$P$2:$P27)),)} -> 0.53703704 | O7: {=iferror(SUMIF(SelectedTeamStats!$D$2:$D27,C7:C15,SelectedTeamStats!$Q$2:$Q27)/(SUMIF(SelectedTeamStats!$D$2:$D27,C7:C15,SelectedTeamStats!$Q$2:$Q27)+SUMIF(SelectedTeamStats!$D$2:$D27,C7:C15,SelectedTeamStats!$R$2:$R27)),)} -> 0.69090909 | P7: {=iferror((SUMIF(SelectedTeamStats!$D$2:$D27,C7:C15,SelectedTeamStats!$M$2:$M27)+ SUMIF(SelectedTeamStats!$D$2:$D27,C7:C15,SelectedTeamStats!$N$2:$N27)) / ( SUMIF(SelectedTeamStats!$D$2:$D27,C7:C15,SelectedTeamStats!$M$2:$M27)+ SUMIF(SelectedTeamStats!$D$2:$D27,C7:C15,SelectedTeamStats!$T$2:$T27)+ SUMIF(SelectedTeamStats!$D$2:$D27,C7:C15,SelectedTeamStats!$N$2:$N27)+ SUMIF(SelectedTeamStats!$D$2:$D27,C7:C15,SelectedTeamStats!$S$2:$S27) ),)} -> 0.83333333 | Q7: {=iferror(SUMIF(SelectedTeamStats!$D$2:$D27,C7:C15,SelectedTeamStats!$M$2:$M27)/(SUMIF(SelectedTeamStats!$D$2:$D27,C7:C15,SelectedTeamStats!$M$2:$M27)+SUMIF(SelectedTeamStats!$D$2:$D27,C7:C15,SelectedTeamStats!$T$2:$T27)),)} -> 0.66666667 | R7: {=iferror(SUMIF(SelectedTeamStats!$D$2:$D27,C7:C15,SelectedTeamStats!$N$2:$N27)/(SUMIF(SelectedTeamStats!$D$2:$D27,C7:C15,SelectedTeamStats!$N$2:$N27)+SUMIF(SelectedTeamStats!$D$2:$D27,C7:C15,SelectedTeamStats!$S$2:$S27)),)} -> 1 | S7: =iferror(SUMIFS('Gun v Gun'!$C$2:$C27,'Gun v Gun'!$A$2:$A27,$C$3,'Gun v Gun'!$B$2:$B27,C7)/(SUMIFS('Gun v Gun'!$C$2:$C27,'Gun v Gun'!$A$2:$A27,$C$3,'Gun v Gun'!$B$2:$B27,C7)+SUMIFS('Gun v Gun'!$D$2:$D27,'Gun v Gun'!$A$2:$A27,$C$3,'Gun v Gun'!$B$2:$B27,C7)),) -> 0.625 | T7: =iferror(SUMIFS('Gun v Gun'!$C$2:$C27,'Gun v Gun'!$A$2:$A27,$C$3,'Gun v Gun'!$B$2:$B27,C7,'Gun v Gun'!$F$2:$F27,"atk")/(SUMIFS('Gun v Gun'!$C$2:$C27,'Gun v Gun'!$A$2:$A27,$C$3,'Gun v Gun'!$B$2:$B27,C7,'Gun v Gun'!$F$2:$F27,"atk")+SUMIFS('Gun v Gun'!$D$2:$D27,'Gun v Gun'!$A$2:$A27,$C$3,'Gun v Gun'!$B$2:$B27,C7,'Gun v Gun'!$F$2:$F27,"atk")),) -> 0.55555556 | U7: =iferror(SUMIFS('Gun v Gun'!$C$2:$C27,'Gun v Gun'!$A$2:$A27,$C$3,'Gun v Gun'!$B$2:$B27,C7,'Gun v Gun'!$F$2:$F27,"def")/(SUMIFS('Gun v Gun'!$C$2:$C27,'Gun v Gun'!$A$2:$A27,$C$3,'Gun v Gun'!$B$2:$B27,C7,'Gun v Gun'!$F$2:$F27,"def")+SUMIFS('Gun v Gun'!$D$2:$D27,'Gun v Gun'!$A$2:$A27,$C$3,'Gun v Gun'!$B$2:$B27,C7,'Gun v Gun'!$F$2:$F27,"def")),) -> 0.69444444 | V7: =iferror(SUMIFS(Antieco!$C$2:$C27,Antieco!$A$2:$A27,$C$3,Antieco!$B$2:$B27,C7)/(SUMIFS(Antieco!$C$2:$C27,Antieco!$A$2:$A27,$C$3,Antieco!$B$2:$B27,C7)+SUMIFS(Antieco!$D$2:$D27,Antieco!$A$2:$A27,$C$3,Antieco!$B$2:$B27,C7)),) -> 0.6875 | W7: =iferror(SUMIFS(Antieco!$C$2:$C27,Antieco!$A$2:$A27,$C$3,Antieco!$B$2:$B27,C7,Antieco!$F$2:$F27,"atk")/(SUMIFS(Antieco!$C$2:$C27,Antieco!$A$2:$A27,$C$3,Antieco!$B$2:$B27,C7,Antieco!$F$2:$F27,"atk")+SUMIFS(Antieco!$D$2:$D27,Antieco!$A$2:$A27,$C$3,Antieco!$B$2:$B27,C7,Antieco!$F$2:$F27,"atk")),) -> 0.77777778 | X7: =iferror(SUMIFS(Antieco!$C$2:$C27,Antieco!$A$2:$A27,$C$3,Antieco!$B$2:$B27,C7,Antieco!$F$2:$F27,"def")/(SUMIFS(Antieco!$C$2:$C27,Antieco!$A$2:$A27,$C$3,Antieco!$B$2:$B27,C7,Antieco!$F$2:$F27,"def")+SUMIFS(Antieco!$D$2:$D27,Antieco!$A$2:$A27,$C$3,Antieco!$B$2:$B27,C7,Antieco!$F$2:$F27,"def")),) -> 0.57142857 | Y7: =iferror(SUMIFS(ecos!$C$2:$C27,ecos!$A$2:$A27,$C$3,ecos!$B$2:$B27,C7)/(SUMIFS(ecos!$C$2:$C27,ecos!$A$2:$A27,$C$3,ecos!$B$2:$B27,C7)+SUMIFS(ecos!$D$2:$D27,ecos!$A$2:$A27,$C$3,ecos!$B$2:$B27,C7)),) -> 0.11111111 | Z7: =iferror(SUMIFS(ecos!$C$2:$C27,ecos!$A$2:$A27,$C$3,ecos!$B$2:$B27,C7,ecos!$F$2:$F27,"atk")/(SUMIFS(ecos!$C$2:$C27,ecos!$A$2:$A27,$C$3,ecos!$B$2:$B27,C7,ecos!$F$2:$F27,"atk")+SUMIFS(ecos!$D$2:$D27,ecos!$A$2:$A27,$C$3,ecos!$B$2:$B27,C7,ecos!$F$2:$F27,"atk")),) -> 0.2 | AA7: =iferror(SUMIFS(ecos!$C$2:$C27,ecos!$A$2:$A27,$C$3,ecos!$B$2:$B27,C7,ecos!$F$2:$F27,"def")/(SUMIFS(ecos!$C$2:$C27,ecos!$A$2:$A27,$C$3,ecos!$B$2:$B27,C7,ecos!$F$2:$F27,"def")+SUMIFS(ecos!$D$2:$D27,ecos!$A$2:$A27,$C$3,ecos!$B$2:$B27,C7,ecos!$F$2:$F27,"def")),) -> 0 | AC7: {=UNIQUE(doubles!D2:D27)} -> Ascent | AE7: {=SUMIFS('Post Plants'!$D$2:$D27,'Post Plants'!$B$2:$B27,AC7:AC15,'Post Plants'!$A$2:$A27,$C$3)} -> 30 | AF7: {=iferror(0+(SUMIF(SelectedTeamStats!$D$2:$D27,C7:C15,SelectedTeamStats!$O$2:$O27)+SUMIF(SelectedTeamStats!$D$2:$D27,C7:C15,SelectedTeamStats!$P$2:$P27)),)} -> 54 | AG7: {=iferror(AE7:AE15/J7:J15,0)} -> 5 | AH7: =iferror(SUMIFS('Post Plants'!$F$2:$F27,'Post Plants'!$B$2:$B27,AC7:AC15,'Post Plants'!$A$2:$A27,$C$3)/SUMIFS('Post Plants'!$D$2:$D27,'Post Plants'!$B$2:$B27,AC7:AC15,'Post Plants'!$A$2:$A27,$C$3),) -> 0.76666667 | AI7: =iferror(SUMIFS('Post Plants'!$F$2:$F27,'Post Plants'!$B$2:$B27,AC7:AC15)/SUMIFS('Post Plants'!$D$2:$D27,'Post Plants'!$B$2:$B27,AC7:AC15),) -> 0.76150628 | AJ7: {=XLOOKUP(C3,'Post Ranking'!G3:G27,'Post Ranking'!F3:F27)} -> 7 | AK7: {=SUMIFS('Post Plants'!$J$2:$J27,'Post Plants'!$B$2:$B27,AC7:AC15,'Post Plants'!$A$2:$A27,$C$3)} -> 26 | AL7: {=iferror(0+(SUMIF(SelectedTeamStats!$D$2:$D27,C7:C15,SelectedTeamStats!$Q$2:$Q27)+SUMIF(SelectedTeamStats!$D$2:$D27,C7:C15,SelectedTeamStats!$R$2:$R27)),)} -> 55 | AM7: {=iferror(AK7:AK15/J7:J15,0)} -> 4.3333333 | AN7: =iferror(SUMIFS('Post Plants'!$L$2:$L27,'Post Plants'!$B$2:$B27,AC7:AC15,'Post Plants'!$A$2:$A27,$C$3)/SUMIFS('Post Plants'!$J$2:$J27,'Post Plants'!$B$2:$B27,AC7:AC15,'Post Plants'!$A$2:$A27,$C$3),) -> 0.46153846 | AO7: =iferror(SUMIFS('Post Plants'!$L$2:$L27,'Post Plants'!$B$2:$B27,AC7:AC15)/SUMIFS('Post Plants'!$J$2:$J27,'Post Plants'!$B$2:$B27,AC7:AC15),) -> 0.35080645 | AP7: {=XLOOKUP(C3,'Post Ranking'!R3:R27,'Post Ranking'!F3:F27)} -> 2
B8: Cypher,Sova,Omen,Yoru,Iso | C8: Haven | D8: =IFERROR(__xludf.DUMMYFUNCTION("""COMPUTED_VALUE"""),"") | E8: =IFERROR(__xludf.DUMMYFUNCTION("""COMPUTED_VALUE"""),"") | F8: =IFERROR(__xludf.DUMMYFUNCTION("""COMPUTED_VALUE"""),"") | G8: =IFERROR(__xludf.DUMMYFUNCTION("""COMPUTED_VALUE"""),"") | H8: =IFERROR(__xludf.DUMMYFUNCTION("""COMPUTED_VALUE"""),"") | I8: 4 | J8: 4 | K8: 2 | L8: 2 | M8: 0.4875 | N8: 0.4375 | O8: 0.52083333 | P8: 0.375 | Q8: 0.25 | R8: 0.5 | S8: =iferror(SUMIFS('Gun v Gun'!$C$2:$C27,'Gun v Gun'!$A$2:$A27,$C$3,'Gun v Gun'!$B$2:$B27,C8)/(SUMIFS('Gun v Gun'!$C$2:$C27,'Gun v Gun'!$A$2:$A27,$C$3,'Gun v Gun'!$B$2:$B27,C8)+SUMIFS('Gun v Gun'!$D$2:$D27,'Gun v Gun'!$A$2:$A27,$C$3,'Gun v Gun'!$B$2:$B27,C8)),) -> 0.50877193 | T8: =iferror(SUMIFS('Gun v Gun'!$C$2:$C27,'Gun v Gun'!$A$2:$A27,$C$3,'Gun v Gun'!$B$2:$B27,C8,'Gun v Gun'!$F$2:$F27,"atk")/(SUMIFS('Gun v Gun'!$C$2:$C27,'Gun v Gun'!$A$2:$A27,$C$3,'Gun v Gun'!$B$2:$B27,C8,'Gun v Gun'!$F$2:$F27,"atk")+SUMIFS('Gun v Gun'!$D$2:$D27,'Gun v Gun'!$A$2:$A27,$C$3,'Gun v Gun'!$B$2:$B27,C8,'Gun v Gun'!$F$2:$F27,"atk")),) -> 0.47826087 | U8: =iferror(SUMIFS('Gun v Gun'!$C$2:$C27,'Gun v Gun'!$A$2:$A27,$C$3,'Gun v Gun'!$B$2:$B27,C8,'Gun v Gun'!$F$2:$F27,"def")/(SUMIFS('Gun v Gun'!$C$2:$C27,'Gun v Gun'!$A$2:$A27,$C$3,'Gun v Gun'!$B$2:$B27,C8,'Gun v Gun'!$F$2:$F27,"def")+SUMIFS('Gun v Gun'!$D$2:$D27,'Gun v Gun'!$A$2:$A27,$C$3,'Gun v Gun'!$B$2:$B27,C8,'Gun v Gun'!$F$2:$F27,"def")),) -> 0.52941176 | V8: =iferror(SUMIFS(Antieco!$C$2:$C27,Antieco!$A$2:$A27,$C$3,Antieco!$B$2:$B27,C8)/(SUMIFS(Antieco!$C$2:$C27,Antieco!$A$2:$A27,$C$3,Antieco!$B$2:$B27,C8)+SUMIFS(Antieco!$D$2:$D27,Antieco!$A$2:$A27,$C$3,Antieco!$B$2:$B27,C8)),) -> 0.66666667 | W8: =iferror(SUMIFS(Antieco!$C$2:$C27,Antieco!$A$2:$A27,$C$3,Antieco!$B$2:$B27,C8,Antieco!$F$2:$F27,"atk")/(SUMIFS(Antieco!$C$2:$C27,Antieco!$A$2:$A27,$C$3,Antieco!$B$2:$B27,C8,Antieco!$F$2:$F27,"atk")+SUMIFS(Antieco!$D$2:$D27,Antieco!$A$2:$A27,$C$3,Antieco!$B$2:$B27,C8,Antieco!$F$2:$F27,"atk")),) -> 0.75 | X8: =iferror(SUMIFS(Antieco!$C$2:$C27,Antieco!$A$2:$A27,$C$3,Antieco!$B$2:$B27,C8,Antieco!$F$2:$F27,"def")/(SUMIFS(Antieco!$C$2:$C27,Antieco!$A$2:$A27,$C$3,Antieco!$B$2:$B27,C8,Antieco!$F$2:$F27,"def")+SUMIFS(Antieco!$D$2:$D27,Antieco!$A$2:$A27,$C$3,Antieco!$B$2:$B27,C8,Antieco!$F$2:$F27,"def")),) -> 0.5 | Y8: =iferror(SUMIFS(ecos!$C$2:$C27,ecos!$A$2:$A27,$C$3,ecos!$B$2:$B27,C8)/(SUMIFS(ecos!$C$2:$C27,ecos!$A$2:$A27,$C$3,ecos!$B$2:$B27,C8)+SUMIFS(ecos!$D$2:$D27,ecos!$A$2:$A27,$C$3,ecos!$B$2:$B27,C8)),) -> 0.33333333 | Z8: =iferror(SUMIFS(ecos!$C$2:$C27,ecos!$A$2:$A27,$C$3,ecos!$B$2:$B27,C8,ecos!$F$2:$F27,"atk")/(SUMIFS(ecos!$C$2:$C27,ecos!$A$2:$A27,$C$3,ecos!$B$2:$B27,C8,ecos!$F$2:$F27,"atk")+SUMIFS(ecos!$D$2:$D27,ecos!$A$2:$A27,$C$3,ecos!$B$2:$B27,C8,ecos!$F$2:$F27,"atk")),) -> 0.33333333 | AA8: =iferror(SUMIFS(ecos!$C$2:$C27,ecos!$A$2:$A27,$C$3,ecos!$B$2:$B27,C8,ecos!$F$2:$F27,"def")/(SUMIFS(ecos!$C$2:$C27,ecos!$A$2:$A27,$C$3,ecos!$B$2:$B27,C8,ecos!$F$2:$F27,"def")+SUMIFS(ecos!$D$2:$D27,ecos!$A$2:$A27,$C$3,ecos!$B$2:$B27,C8,ecos!$F$2:$F27,"def")),) -> 0.33333333 | AC8: Haven | AE8: {=SUMIFS('Post Plants'!$D$2:$D27,'Post Plants'!$B$2:$B27,AC8:AC16,'Post Plants'!$A$2:$A27,$C$3)} -> 19 | AF8: 32 | AG8: 4.75 | AH8: =iferror(SUMIFS('Post Plants'!$F$2:$F27,'Post Plants'!$B$2:$B27,AC8:AC16,'Post Plants'!$A$2:$A27,$C$3)/SUMIFS('Post Plants'!$D$2:$D27,'Post Plants'!$B$2:$B27,AC8:AC16,'Post Plants'!$A$2:$A27,$C$3),) -> 0.52631579 | AI8: =iferror(SUMIFS('Post Plants'!$F$2:$F27,'Post Plants'!$B$2:$B27,AC8:AC16)/SUMIFS('Post Plants'!$D$2:$D27,'Post Plants'!$B$2:$B27,AC8:AC16),) -> 0.73291925 | AJ8: {=XLOOKUP($C$3,'Post Ranking'!H3:H27,'Post Ranking'!$F$3:$F27)} -> 14 | AK8: {=SUMIFS('Post Plants'!$J$2:$J27,'Post Plants'!$B$2:$B27,AC8:AC16,'Post Plants'!$A$2:$A27,$C$3)} -> 26 | AL8: 48 | AM8: 6.5 | AN8: =iferror(SUMIFS('Post Plants'!$L$2:$L27,'Post Plants'!$B$2:$B27,AC8:AC16,'Post Plants'!$A$2:$A27,$C$3)/SUMIFS('Post Plants'!$J$2:$J27,'Post Plants'!$B$2:$B27,AC8:AC16,'Post Plants'!$A$2:$A27,$C$3),) -> 0.34615385 | AO8: =iferror(SUMIFS('Post Plants'!$L$2:$L27,'Post Plants'!$B$2:$B27,AC8:AC16)/SUMIFS('Post Plants'!$J$2:$J27,'Post Plants'!$B$2:$B27,AC8:AC16),) -> 0.36829268 | AP8: {=XLOOKUP(C3,'Post Ranking'!S3:S27,'Post Ranking'!F3:F27)} -> 9
B9: Yoru,Astra,Gekko,Deadlock,Waylay | C9: Bind | D9: =IFERROR(__xludf.DUMMYFUNCTION("""COMPUTED_VALUE"""),"") | E9: =IFERROR(__xludf.DUMMYFUNCTION("""COMPUTED_VALUE"""),"") | F9: =IFERROR(__xludf.DUMMYFUNCTION("""COMPUTED_VALUE"""),"") | G9: =IFERROR(__xludf.DUMMYFUNCTION("""COMPUTED_VALUE"""),"") | H9: =IFERROR(__xludf.DUMMYFUNCTION("""COMPUTED_VALUE"""),"") | I9: 1 | J9: 1 | K9: 1 | L9: 0 | M9: 0.61904762 | N9: 0.88888889 | O9: 0.41666667 | P9: 0.5 | Q9: 1 | R9: 0 | S9: =iferror(SUMIFS('Gun v Gun'!$C$2:$C27,'Gun v Gun'!$A$2:$A27,$C$3,'Gun v Gun'!$B$2:$B27,C9)/(SUMIFS('Gun v Gun'!$C$2:$C27,'Gun v Gun'!$A$2:$A27,$C$3,'Gun v Gun'!$B$2:$B27,C9)+SUMIFS('Gun v Gun'!$D$2:$D27,'Gun v Gun'!$A$2:$A27,$C$3,'Gun v Gun'!$B$2:$B27,C9)),) -> 0.64705882 | T9: =iferror(SUMIFS('Gun v Gun'!$C$2:$C27,'Gun v Gun'!$A$2:$A27,$C$3,'Gun v Gun'!$B$2:$B27,C9,'Gun v Gun'!$F$2:$F27,"atk")/(SUMIFS('Gun v Gun'!$C$2:$C27,'Gun v Gun'!$A$2:$A27,$C$3,'Gun v Gun'!$B$2:$B27,C9,'Gun v Gun'!$F$2:$F27,"atk")+SUMIFS('Gun v Gun'!$D$2:$D27,'Gun v Gun'!$A$2:$A27,$C$3,'Gun v Gun'!$B$2:$B27,C9,'Gun v Gun'!$F$2:$F27,"atk")),) -> 0.85714286 | U9: =iferror(SUMIFS('Gun v Gun'!$C$2:$C27,'Gun v Gun'!$A$2:$A27,$C$3,'Gun v Gun'!$B$2:$B27,C9,'Gun v Gun'!$F$2:$F27,"def")/(SUMIFS('Gun v Gun'!$C$2:$C27,'Gun v Gun'!$A$2:$A27,$C$3,'Gun v Gun'!$B$2:$B27,C9,'Gun v Gun'!$F$2:$F27,"def")+SUMIFS('Gun v Gun'!$D$2:$D27,'Gun v Gun'!$A$2:$A27,$C$3,'Gun v Gun'!$B$2:$B27,C9,'Gun v Gun'!$F$2:$F27,"def")),) -> 0.5 | V9: =iferror(SUMIFS(Antieco!$C$2:$C27,Antieco!$A$2:$A27,$C$3,Antieco!$B$2:$B27,C9)/(SUMIFS(Antieco!$C$2:$C27,Antieco!$A$2:$A27,$C$3,Antieco!$B$2:$B27,C9)+SUMIFS(Antieco!$D$2:$D27,Antieco!$A$2:$A27,$C$3,Antieco!$B$2:$B27,C9)),) -> 1 | W9: =iferror(SUMIFS(Antieco!$C$2:$C27,Antieco!$A$2:$A27,$C$3,Antieco!$B$2:$B27,C9,Antieco!$F$2:$F27,"atk")/(SUMIFS(Antieco!$C$2:$C27,Antieco!$A$2:$A27,$C$3,Antieco!$B$2:$B27,C9,Antieco!$F$2:$F27,"atk")+SUMIFS(Antieco!$D$2:$D27,Antieco!$A$2:$A27,$C$3,Antieco!$B$2:$B27,C9,Antieco!$F$2:$F27,"atk")),) | X9: =iferror(SUMIFS(Antieco!$C$2:$C27,Antieco!$A$2:$A27,$C$3,Antieco!$B$2:$B27,C9,Antieco!$F$2:$F27,"def")/(SUMIFS(Antieco!$C$2:$C27,Antieco!$A$2:$A27,$C$3,Antieco!$B$2:$B27,C9,Antieco!$F$2:$F27,"def")+SUMIFS(Antieco!$D$2:$D27,Antieco!$A$2:$A27,$C$3,Antieco!$B$2:$B27,C9,Antieco!$F$2:$F27,"def")),) -> 1 | Y9: =iferror(SUMIFS(ecos!$C$2:$C27,ecos!$A$2:$A27,$C$3,ecos!$B$2:$B27,C9)/(SUMIFS(ecos!$C$2:$C27,ecos!$A$2:$A27,$C$3,ecos!$B$2:$B27,C9)+SUMIFS(ecos!$D$2:$D27,ecos!$A$2:$A27,$C$3,ecos!$B$2:$B27,C9)),) -> 0 | Z9: =iferror(SUMIFS(ecos!$C$2:$C27,ecos!$A$2:$A27,$C$3,ecos!$B$2:$B27,C9,ecos!$F$2:$F27,"atk")/(SUMIFS(ecos!$C$2:$C27,ecos!$A$2:$A27,$C$3,ecos!$B$2:$B27,C9,ecos!$F$2:$F27,"atk")+SUMIFS(ecos!$D$2:$D27,ecos!$A$2:$A27,$C$3,ecos!$B$2:$B27,C9,ecos!$F$2:$F27,"atk")),) | AA9: =iferror(SUMIFS(ecos!$C$2:$C27,ecos!$A$2:$A27,$C$3,ecos!$B$2:$B27,C9,ecos!$F$2:$F27,"def")/(SUMIFS(ecos!$C$2:$C27,ecos!$A$2:$A27,$C$3,ecos!$B$2:$B27,C9,ecos!$F$2:$F27,"def")+SUMIFS(ecos!$D$2:$D27,ecos!$A$2:$A27,$C$3,ecos!$B$2:$B27,C9,ecos!$F$2:$F27,"def")),) -> 0 | AC9: Bind | AE9: {=SUMIFS('Post Plants'!$D$2:$D27,'Post Plants'!$B$2:$B27,AC9:AC17,'Post Plants'!$A$2:$A27,$C$3)} -> 9 | AF9: 9 | AG9: 9 | AH9: =iferror(SUMIFS('Post Plants'!$F$2:$F27,'Post Plants'!$B$2:$B27,AC9:AC17,'Post Plants'!$A$2:$A27,$C$3)/SUMIFS('Post Plants'!$D$2:$D27,'Post Plants'!$B$2:$B27,AC9:AC17,'Post Plants'!$A$2:$A27,$C$3),) -> 0.88888889 | AI9: =iferror(SUMIFS('Post Plants'!$F$2:$F27,'Post Plants'!$B$2:$B27,AC9:AC17)/SUMIFS('Post Plants'!$D$2:$D27,'Post Plants'!$B$2:$B27,AC9:AC17),) -> 0.77722772 | AJ9: {=XLOOKUP($C$3,'Post Ranking'!I3:I27,'Post Ranking'!$F$3:$F27)} -> 3 | AK9: {=SUMIFS('Post Plants'!$J$2:$J27,'Post Plants'!$B$2:$B27,AC9:AC17,'Post Plants'!$A$2:$A27,$C$3)} -> 10 | AL9: 12 | AM9: 10 | AN9: =iferror(SUMIFS('Post Plants'!$L$2:$L27,'Post Plants'!$B$2:$B27,AC9:AC17,'Post Plants'!$A$2:$A27,$C$3)/SUMIFS('Post Plants'!$J$2:$J27,'Post Plants'!$B$2:$B27,AC9:AC17,'Post Plants'!$A$2:$A27,$C$3),) -> 0.3 | AO9: =iferror(SUMIFS('Post Plants'!$L$2:$L27,'Post Plants'!$B$2:$B27,AC9:AC17)/SUMIFS('Post Plants'!$J$2:$J27,'Post Plants'!$B$2:$B27,AC9:AC17),) -> 0.32386364 | AP9: {=XLOOKUP(C3,'Post Ranking'!T3:T27,'Post Ranking'!F3:F27)} -> 8
B10: Sova,Killjoy,Viper,Sage,Gekko | C10: Icebox | D10: =IFERROR(__xludf.DUMMYFUNCTION("""COMPUTED_VALUE"""),"") | E10: =IFERROR(__xludf.DUMMYFUNCTION("""COMPUTED_VALUE"""),"") | F10: =IFERROR(__xludf.DUMMYFUNCTION("""COMPUTED_VALUE"""),"") | G10: =IFERROR(__xludf.DUMMYFUNCTION("""COMPUTED_VALUE"""),"") | H10: =IFERROR(__xludf.DUMMYFUNCTION("""COMPUTED_VALUE"""),"") | I10: 1 | J10: 1 | K10: 1 | L10: 0 | M10: 0.59090909 | N10: 0.41666667 | O10: 0.8 | P10: 0.5 | Q10: 0 | R10: 1 | S10: =iferror(SUMIFS('Gun v Gun'!$C$2:$C27,'Gun v Gun'!$A$2:$A27,$C$3,'Gun v Gun'!$B$2:$B27,C10)/(SUMIFS('Gun v Gun'!$C$2:$C27,'Gun v Gun'!$A$2:$A27,$C$3,'Gun v Gun'!$B$2:$B27,C10)+SUMIFS('Gun v Gun'!$D$2:$D27,'Gun v Gun'!$A$2:$A27,$C$3,'Gun v Gun'!$B$2:$B27,C10)),) -> 0.625 | T10: =iferror(SUMIFS('Gun v Gun'!$C$2:$C27,'Gun v Gun'!$A$2:$A27,$C$3,'Gun v Gun'!$B$2:$B27,C10,'Gun v Gun'!$F$2:$F27,"atk")/(SUMIFS('Gun v Gun'!$C$2:$C27,'Gun v Gun'!$A$2:$A27,$C$3,'Gun v Gun'!$B$2:$B27,C10,'Gun v Gun'!$F$2:$F27,"atk")+SUMIFS('Gun v Gun'!$D$2:$D27,'Gun v Gun'!$A$2:$A27,$C$3,'Gun v Gun'!$B$2:$B27,C10,'Gun v Gun'!$F$2:$F27,"atk")),) -> 0.55555556 | U10: =iferror(SUMIFS('Gun v Gun'!$C$2:$C27,'Gun v Gun'!$A$2:$A27,$C$3,'Gun v Gun'!$B$2:$B27,C10,'Gun v Gun'!$F$2:$F27,"def")/(SUMIFS('Gun v Gun'!$C$2:$C27,'Gun v Gun'!$A$2:$A27,$C$3,'Gun v Gun'!$B$2:$B27,C10,'Gun v Gun'!$F$2:$F27,"def")+SUMIFS('Gun v Gun'!$D$2:$D27,'Gun v Gun'!$A$2:$A27,$C$3,'Gun v Gun'!$B$2:$B27,C10,'Gun v Gun'!$F$2:$F27,"def")),) -> 0.71428571 | V10: =iferror(SUMIFS(Antieco!$C$2:$C27,Antieco!$A$2:$A27,$C$3,Antieco!$B$2:$B27,C10)/(SUMIFS(Antieco!$C$2:$C27,Antieco!$A$2:$A27,$C$3,Antieco!$B$2:$B27,C10)+SUMIFS(Antieco!$D$2:$D27,Antieco!$A$2:$A27,$C$3,Antieco!$B$2:$B27,C10)),) -> 1 | W10: =iferror(SUMIFS(Antieco!$C$2:$C27,Antieco!$A$2:$A27,$C$3,Antieco!$B$2:$B27,C10,Antieco!$F$2:$F27,"atk")/(SUMIFS(Antieco!$C$2:$C27,Antieco!$A$2:$A27,$C$3,Antieco!$B$2:$B27,C10,Antieco!$F$2:$F27,"atk")+SUMIFS(Antieco!$D$2:$D27,Antieco!$A$2:$A27,$C$3,Antieco!$B$2:$B27,C10,Antieco!$F$2:$F27,"atk")),) -> 1 | X10: =iferror(SUMIFS(Antieco!$C$2:$C27,Antieco!$A$2:$A27,$C$3,Antieco!$B$2:$B27,C10,Antieco!$F$2:$F27,"def")/(SUMIFS(Antieco!$C$2:$C27,Antieco!$A$2:$A27,$C$3,Antieco!$B$2:$B27,C10,Antieco!$F$2:$F27,"def")+SUMIFS(Antieco!$D$2:$D27,Antieco!$A$2:$A27,$C$3,Antieco!$B$2:$B27,C10,Antieco!$F$2:$F27,"def")),) | Y10: =iferror(SUMIFS(ecos!$C$2:$C27,ecos!$A$2:$A27,$C$3,ecos!$B$2:$B27,C10)/(SUMIFS(ecos!$C$2:$C27,ecos!$A$2:$A27,$C$3,ecos!$B$2:$B27,C10)+SUMIFS(ecos!$D$2:$D27,ecos!$A$2:$A27,$C$3,ecos!$B$2:$B27,C10)),) -> 0.33333333 | Z10: =iferror(SUMIFS(ecos!$C$2:$C27,ecos!$A$2:$A27,$C$3,ecos!$B$2:$B27,C10,ecos!$F$2:$F27,"atk")/(SUMIFS(ecos!$C$2:$C27,ecos!$A$2:$A27,$C$3,ecos!$B$2:$B27,C10,ecos!$F$2:$F27,"atk")+SUMIFS(ecos!$D$2:$D27,ecos!$A$2:$A27,$C$3,ecos!$B$2:$B27,C10,ecos!$F$2:$F27,"atk")),) -> 0 | AA10: =iferror(SUMIFS(ecos!$C$2:$C27,ecos!$A$2:$A27,$C$3,ecos!$B$2:$B27,C10,ecos!$F$2:$F27,"def")/(SUMIFS(ecos!$C$2:$C27,ecos!$A$2:$A27,$C$3,ecos!$B$2:$B27,C10,ecos!$F$2:$F27,"def")+SUMIFS(ecos!$D$2:$D27,ecos!$A$2:$A27,$C$3,ecos!$B$2:$B27,C10,ecos!$F$2:$F27,"def")),) -> 1 | AC10: Icebox | AE10: {=SUMIFS('Post Plants'!$D$2:$D27,'Post Plants'!$B$2:$B27,AC10:AC18,'Post Plants'!$A$2:$A27,$C$3)} -> 7 | AF10: 12 | AG10: 7 | AH10: =iferror(SUMIFS('Post Plants'!$F$2:$F27,'Post Plants'!$B$2:$B27,AC10:AC18,'Post Plants'!$A$2:$A27,$C$3)/SUMIFS('Post Plants'!$D$2:$D27,'Post Plants'!$B$2:$B27,AC10:AC18,'Post Plants'!$A$2:$A27,$C$3),) -> 0.71428571 | AI10: =iferror(SUMIFS('Post Plants'!$F$2:$F27,'Post Plants'!$B$2:$B27,AC10:AC18)/SUMIFS('Post Plants'!$D$2:$D27,'Post Plants'!$B$2:$B27,AC10:AC18),) -> 0.65948276 | AJ10: {=XLOOKUP($C$3,'Post Ranking'!J3:J27,'Post Ranking'!$F$3:$F27)} -> 5 | AK10: {=SUMIFS('Post Plants'!$J$2:$J27,'Post Plants'!$B$2:$B27,AC10:AC18,'Post Plants'!$A$2:$A27,$C$3)} -> 7 | AL10: 10 | AM10: 7 | AN10: =iferror(SUMIFS('Post Plants'!$L$2:$L27,'Post Plants'!$B$2:$B27,AC10:AC18,'Post Plants'!$A$2:$A27,$C$3)/SUMIFS('Post Plants'!$J$2:$J27,'Post Plants'!$B$2:$B27,AC10:AC18,'Post Plants'!$A$2:$A27,$C$3),) -> 0.71428571 | AO10: =iferror(SUMIFS('Post Plants'!$L$2:$L27,'Post Plants'!$B$2:$B27,AC10:AC18)/SUMIFS('Post Plants'!$J$2:$J27,'Post Plants'!$B$2:$B27,AC10:AC18),) -> 0.39484979 | AP10: {=XLOOKUP(C3,'Post Ranking'!U3:U27,'Post Ranking'!F3:F27)} -> 1
B11: Sova,Omen,Yoru,Vyse,Waylay | C11: Sunset | D11: =IFERROR(__xludf.DUMMYFUNCTION("""COMPUTED_VALUE"""),"") | E11: =IFERROR(__xludf.DUMMYFUNCTION("""COMPUTED_VALUE"""),"") | F11: =IFERROR(__xludf.DUMMYFUNCTION("""COMPUTED_VALUE"""),"") | G11: =IFERROR(__xludf.DUMMYFUNCTION("""COMPUTED_VALUE"""),"") | H11: =IFERROR(__xludf.DUMMYFUNCTION("""COMPUTED_VALUE"""),"") | I11: 2 | J11: 2 | K11: 1 | L11: 1 | M11: 0.56818182 | N11: 0.56 | O11: 0.57894737 | P11: 1 | Q11: 1 | R11: 1 | S11: =iferror(SUMIFS('Gun v Gun'!$C$2:$C27,'Gun v Gun'!$A$2:$A27,$C$3,'Gun v Gun'!$B$2:$B27,C11)/(SUMIFS('Gun v Gun'!$C$2:$C27,'Gun v Gun'!$A$2:$A27,$C$3,'Gun v Gun'!$B$2:$B27,C11)+SUMIFS('Gun v Gun'!$D$2:$D27,'Gun v Gun'!$A$2:$A27,$C$3,'Gun v Gun'!$B$2:$B27,C11)),) -> 0.4375 | T11: =iferror(SUMIFS('Gun v Gun'!$C$2:$C27,'Gun v Gun'!$A$2:$A27,$C$3,'Gun v Gun'!$B$2:$B27,C11,'Gun v Gun'!$F$2:$F27,"atk")/(SUMIFS('Gun v Gun'!$C$2:$C27,'Gun v Gun'!$A$2:$A27,$C$3,'Gun v Gun'!$B$2:$B27,C11,'Gun v Gun'!$F$2:$F27,"atk")+SUMIFS('Gun v Gun'!$D$2:$D27,'Gun v Gun'!$A$2:$A27,$C$3,'Gun v Gun'!$B$2:$B27,C11,'Gun v Gun'!$F$2:$F27,"atk")),) -> 0.44444444 | U11: =iferror(SUMIFS('Gun v Gun'!$C$2:$C27,'Gun v Gun'!$A$2:$A27,$C$3,'Gun v Gun'!$B$2:$B27,C11,'Gun v Gun'!$F$2:$F27,"def")/(SUMIFS('Gun v Gun'!$C$2:$C27,'Gun v Gun'!$A$2:$A27,$C$3,'Gun v Gun'!$B$2:$B27,C11,'Gun v Gun'!$F$2:$F27,"def")+SUMIFS('Gun v Gun'!$D$2:$D27,'Gun v Gun'!$A$2:$A27,$C$3,'Gun v Gun'!$B$2:$B27,C11,'Gun v Gun'!$F$2:$F27,"def")),) -> 0.42857143 | V11: =iferror(SUMIFS(Antieco!$C$2:$C27,Antieco!$A$2:$A27,$C$3,Antieco!$B$2:$B27,C11)/(SUMIFS(Antieco!$C$2:$C27,Antieco!$A$2:$A27,$C$3,Antieco!$B$2:$B27,C11)+SUMIFS(Antieco!$D$2:$D27,Antieco!$A$2:$A27,$C$3,Antieco!$B$2:$B27,C11)),) -> 1 | W11: =iferror(SUMIFS(Antieco!$C$2:$C27,Antieco!$A$2:$A27,$C$3,Antieco!$B$2:$B27,C11,Antieco!$F$2:$F27,"atk")/(SUMIFS(Antieco!$C$2:$C27,Antieco!$A$2:$A27,$C$3,Antieco!$B$2:$B27,C11,Antieco!$F$2:$F27,"atk")+SUMIFS(Antieco!$D$2:$D27,Antieco!$A$2:$A27,$C$3,Antieco!$B$2:$B27,C11,Antieco!$F$2:$F27,"atk")),) -> 1 | X11: =iferror(SUMIFS(Antieco!$C$2:$C27,Antieco!$A$2:$A27,$C$3,Antieco!$B$2:$B27,C11,Antieco!$F$2:$F27,"def")/(SUMIFS(Antieco!$C$2:$C27,Antieco!$A$2:$A27,$C$3,Antieco!$B$2:$B27,C11,Antieco!$F$2:$F27,"def")+SUMIFS(Antieco!$D$2:$D27,Antieco!$A$2:$A27,$C$3,Antieco!$B$2:$B27,C11,Antieco!$F$2:$F27,"def")),) -> 1 | Y11: =iferror(SUMIFS(ecos!$C$2:$C27,ecos!$A$2:$A27,$C$3,ecos!$B$2:$B27,C11)/(SUMIFS(ecos!$C$2:$C27,ecos!$A$2:$A27,$C$3,ecos!$B$2:$B27,C11)+SUMIFS(ecos!$D$2:$D27,ecos!$A$2:$A27,$C$3,ecos!$B$2:$B27,C11)),) -> 0 | Z11: =iferror(SUMIFS(ecos!$C$2:$C27,ecos!$A$2:$A27,$C$3,ecos!$B$2:$B27,C11,ecos!$F$2:$F27,"atk")/(SUMIFS(ecos!$C$2:$C27,ecos!$A$2:$A27,$C$3,ecos!$B$2:$B27,C11,ecos!$F$2:$F27,"atk")+SUMIFS(ecos!$D$2:$D27,ecos!$A$2:$A27,$C$3,ecos!$B$2:$B27,C11,ecos!$F$2:$F27,"atk")),) -> 0 | AA11: =iferror(SUMIFS(ecos!$C$2:$C27,ecos!$A$2:$A27,$C$3,ecos!$B$2:$B27,C11,ecos!$F$2:$F27,"def")/(SUMIFS(ecos!$C$2:$C27,ecos!$A$2:$A27,$C$3,ecos!$B$2:$B27,C11,ecos!$F$2:$F27,"def")+SUMIFS(ecos!$D$2:$D27,ecos!$A$2:$A27,$C$3,ecos!$B$2:$B27,C11,ecos!$F$2:$F27,"def")),) | AC11: Sunset | AE11: {=SUMIFS('Post Plants'!$D$2:$D27,'Post Plants'!$B$2:$B27,AC11:AC19,'Post Plants'!$A$2:$A27,$C$3)} -> 19 | AF11: 25 | AG11: 9.5 | AH11: =iferror(SUMIFS('Post Plants'!$F$2:$F27,'Post Plants'!$B$2:$B27,AC11:AC19,'Post Plants'!$A$2:$A27,$C$3)/SUMIFS('Post Plants'!$D$2:$D27,'Post Plants'!$B$2:$B27,AC11:AC19,'Post Plants'!$A$2:$A27,$C$3),) -> 0.63157895 | AI11: =iferror(SUMIFS('Post Plants'!$F$2:$F27,'Post Plants'!$B$2:$B27,AC11:AC19)/SUMIFS('Post Plants'!$D$2:$D27,'Post Plants'!$B$2:$B27,AC11:AC19),) -> 0.68489583 | AJ11: {=XLOOKUP($C$3,'Post Ranking'!K3:K27,'Post Ranking'!$F$3:$F27)} -> 9 | AK11: {=SUMIFS('Post Plants'!$J$2:$J27,'Post Plants'!$B$2:$B27,AC11:AC19,'Post Plants'!$A$2:$A27,$C$3)} -> 9 | AL11: 19 | AM11: 4.5 | AN11: =iferror(SUMIFS('Post Plants'!$L$2:$L27,'Post Plants'!$B$2:$B27,AC11:AC19,'Post Plants'!$A$2:$A27,$C$3)/SUMIFS('Post Plants'!$J$2:$J27,'Post Plants'!$B$2:$B27,AC11:AC19,'Post Plants'!$A$2:$A27,$C$3),) -> 0.22222222 | AO11: =iferror(SUMIFS('Post Plants'!$L$2:$L27,'Post Plants'!$B$2:$B27,AC11:AC19)/SUMIFS('Post Plants'!$J$2:$J27,'Post Plants'!$B$2:$B27,AC11:AC19),) -> 0.31596091 | AP11: {=XLOOKUP(C3,'Post Ranking'!V3:V27,'Post Ranking'!F3:F27)} -> 13
B12: Cypher,Omen,Neon,Fade,Iso | C12: Lotus | D12: =IFERROR(__xludf.DUMMYFUNCTION("""COMPUTED_VALUE"""),"") | E12: =IFERROR(__xludf.DUMMYFUNCTION("""COMPUTED_VALUE"""),"") | F12: =IFERROR(__xludf.DUMMYFUNCTION("""COMPUTED_VALUE"""),"") | G12: =IFERROR(__xludf.DUMMYFUNCTION("""COMPUTED_VALUE"""),"") | H12: =IFERROR(__xludf.DUMMYFUNCTION("""COMPUTED_VALUE"""),"") | I12: 3 | J12: 10 | K12: 5 | L12: 5 | M12: 0.53917051 | N12: 0.49074074 | O12: 0.58715596 | P12: 0.5 | Q12: 0.4 | R12: 0.6 | S12: =iferror(SUMIFS('Gun v Gun'!$C$2:$C27,'Gun v Gun'!$A$2:$A27,$C$3,'Gun v Gun'!$B$2:$B27,C12)/(SUMIFS('Gun v Gun'!$C$2:$C27,'Gun v Gun'!$A$2:$A27,$C$3,'Gun v Gun'!$B$2:$B27,C12)+SUMIFS('Gun v Gun'!$D$2:$D27,'Gun v Gun'!$A$2:$A27,$C$3,'Gun v Gun'!$B$2:$B27,C12)),) -> 0.54362416 | T12: =iferror(SUMIFS('Gun v Gun'!$C$2:$C27,'Gun v Gun'!$A$2:$A27,$C$3,'Gun v Gun'!$B$2:$B27,C12,'Gun v Gun'!$F$2:$F27,"atk")/(SUMIFS('Gun v Gun'!$C$2:$C27,'Gun v Gun'!$A$2:$A27,$C$3,'Gun v Gun'!$B$2:$B27,C12,'Gun v Gun'!$F$2:$F27,"atk")+SUMIFS('Gun v Gun'!$D$2:$D27,'Gun v Gun'!$A$2:$A27,$C$3,'Gun v Gun'!$B$2:$B27,C12,'Gun v Gun'!$F$2:$F27,"atk")),) -> 0.49315068 | U12: =iferror(SUMIFS('Gun v Gun'!$C$2:$C27,'Gun v Gun'!$A$2:$A27,$C$3,'Gun v Gun'!$B$2:$B27,C12,'Gun v Gun'!$F$2:$F27,"def")/(SUMIFS('Gun v Gun'!$C$2:$C27,'Gun v Gun'!$A$2:$A27,$C$3,'Gun v Gun'!$B$2:$B27,C12,'Gun v Gun'!$F$2:$F27,"def")+SUMIFS('Gun v Gun'!$D$2:$D27,'Gun v Gun'!$A$2:$A27,$C$3,'Gun v Gun'!$B$2:$B27,C12,'Gun v Gun'!$F$2:$F27,"def")),) -> 0.59210526 | V12: =iferror(SUMIFS(Antieco!$C$2:$C27,Antieco!$A$2:$A27,$C$3,Antieco!$B$2:$B27,C12)/(SUMIFS(Antieco!$C$2:$C27,Antieco!$A$2:$A27,$C$3,Antieco!$B$2:$B27,C12)+SUMIFS(Antieco!$D$2:$D27,Antieco!$A$2:$A27,$C$3,Antieco!$B$2:$B27,C12)),) -> 0.89285714 | W12: =iferror(SUMIFS(Antieco!$C$2:$C27,Antieco!$A$2:$A27,$C$3,Antieco!$B$2:$B27,C12,Antieco!$F$2:$F27,"atk")/(SUMIFS(Antieco!$C$2:$C27,Antieco!$A$2:$A27,$C$3,Antieco!$B$2:$B27,C12,Antieco!$F$2:$F27,"atk")+SUMIFS(Antieco!$D$2:$D27,Antieco!$A$2:$A27,$C$3,Antieco!$B$2:$B27,C12,Antieco!$F$2:$F27,"atk")),) -> 0.85714286 | X12: =iferror(SUMIFS(Antieco!$C$2:$C27,Antieco!$A$2:$A27,$C$3,Antieco!$B$2:$B27,C12,Antieco!$F$2:$F27,"def")/(SUMIFS(Antieco!$C$2:$C27,Antieco!$A$2:$A27,$C$3,Antieco!$B$2:$B27,C12,Antieco!$F$2:$F27,"def")+SUMIFS(Antieco!$D$2:$D27,Antieco!$A$2:$A27,$C$3,Antieco!$B$2:$B27,C12,Antieco!$F$2:$F27,"def")),) -> 0.92857143 | Y12: =iferror(SUMIFS(ecos!$C$2:$C27,ecos!$A$2:$A27,$C$3,ecos!$B$2:$B27,C12)/(SUMIFS(ecos!$C$2:$C27,ecos!$A$2:$A27,$C$3,ecos!$B$2:$B27,C12)+SUMIFS(ecos!$D$2:$D27,ecos!$A$2:$A27,$C$3,ecos!$B$2:$B27,C12)),) -> 0.05 | Z12: =iferror(SUMIFS(ecos!$C$2:$C27,ecos!$A$2:$A27,$C$3,ecos!$B$2:$B27,C12,ecos!$F$2:$F27,"atk")/(SUMIFS(ecos!$C$2:$C27,ecos!$A$2:$A27,$C$3,ecos!$B$2:$B27,C12,ecos!$F$2:$F27,"atk")+SUMIFS(ecos!$D$2:$D27,ecos!$A$2:$A27,$C$3,ecos!$B$2:$B27,C12,ecos!$F$2:$F27,"atk")),) -> 0 | AA12: =iferror(SUMIFS(ecos!$C$2:$C27,ecos!$A$2:$A27,$C$3,ecos!$B$2:$B27,C12,ecos!$F$2:$F27,"def")/(SUMIFS(ecos!$C$2:$C27,ecos!$A$2:$A27,$C$3,ecos!$B$2:$B27,C12,ecos!$F$2:$F27,"def")+SUMIFS(ecos!$D$2:$D27,ecos!$A$2:$A27,$C$3,ecos!$B$2:$B27,C12,ecos!$F$2:$F27,"def")),) -> 0.11111111 | AC12: Lotus | AE12: {=SUMIFS('Post Plants'!$D$2:$D27,'Post Plants'!$B$2:$B27,AC12:AC20,'Post Plants'!$A$2:$A27,$C$3)} -> 73 | AF12: 108 | AG12: 7.3 | AH12: =iferror(SUMIFS('Post Plants'!$F$2:$F27,'Post Plants'!$B$2:$B27,AC12:AC20,'Post Plants'!$A$2:$A27,$C$3)/SUMIFS('Post Plants'!$D$2:$D27,'Post Plants'!$B$2:$B27,AC12:AC20,'Post Plants'!$A$2:$A27,$C$3),) -> 0.64383562 | AI12: =iferror(SUMIFS('Post Plants'!$F$2:$F27,'Post Plants'!$B$2:$B27,AC12:AC20)/SUMIFS('Post Plants'!$D$2:$D27,'Post Plants'!$B$2:$B27,AC12:AC20),) -> 0.7020649 | AJ12: {=XLOOKUP($C$3,'Post Ranking'!L3:L27,'Post Ranking'!$F$3:$F27)} -> 12 | AK12: {=SUMIFS('Post Plants'!$J$2:$J27,'Post Plants'!$B$2:$B27,AC12:AC20,'Post Plants'!$A$2:$A27,$C$3)} -> 68 | AL12: 109 | AM12: 6.8 | AN12: =iferror(SUMIFS('Post Plants'!$L$2:$L27,'Post Plants'!$B$2:$B27,AC12:AC20,'Post Plants'!$A$2:$A27,$C$3)/SUMIFS('Post Plants'!$J$2:$J27,'Post Plants'!$B$2:$B27,AC12:AC20,'Post Plants'!$A$2:$A27,$C$3),) -> 0.36764706 | AO12: =iferror(SUMIFS('Post Plants'!$L$2:$L27,'Post Plants'!$B$2:$B27,AC12:AC20)/SUMIFS('Post Plants'!$J$2:$J27,'Post Plants'!$B$2:$B27,AC12:AC20),) -> 0.36349206 | AP12: {=XLOOKUP(C3,'Post Ranking'!W3:W27,'Post Ranking'!F3:F27)} -> 8
B13: Cypher,Phoenix,Omen,Yoru,Fade | C13: Corrode | D13: =IFERROR(__xludf.DUMMYFUNCTION("""COMPUTED_VALUE"""),"") | E13: =IFERROR(__xludf.DUMMYFUNCTION("""COMPUTED_VALUE"""),"") | F13: =IFERROR(__xludf.DUMMYFUNCTION("""COMPUTED_VALUE"""),"") | G13: =IFERROR(__xludf.DUMMYFUNCTION("""COMPUTED_VALUE"""),"") | H13: =IFERROR(__xludf.DUMMYFUNCTION("""COMPUTED_VALUE"""),"") | I13: 6 | J13: 6 | K13: 4 | L13: 2 | M13: 0.56349206 | N13: 0.45 | O13: 0.66666667 | P13: 0.41666667 | Q13: 0.33333333 | R13: 0.5 | S13: =iferror(SUMIFS('Gun v Gun'!$C$2:$C27,'Gun v Gun'!$A$2:$A27,$C$3,'Gun v Gun'!$B$2:$B27,C13)/(SUMIFS('Gun v Gun'!$C$2:$C27,'Gun v Gun'!$A$2:$A27,$C$3,'Gun v Gun'!$B$2:$B27,C13)+SUMIFS('Gun v Gun'!$D$2:$D27,'Gun v Gun'!$A$2:$A27,$C$3,'Gun v Gun'!$B$2:$B27,C13)),) -> 0.62921348 | T13: =iferror(SUMIFS('Gun v Gun'!$C$2:$C27,'Gun v Gun'!$A$2:$A27,$C$3,'Gun v Gun'!$B$2:$B27,C13,'Gun v Gun'!$F$2:$F27,"atk")/(SUMIFS('Gun v Gun'!$C$2:$C27,'Gun v Gun'!$A$2:$A27,$C$3,'Gun v Gun'!$B$2:$B27,C13,'Gun v Gun'!$F$2:$F27,"atk")+SUMIFS('Gun v Gun'!$D$2:$D27,'Gun v Gun'!$A$2:$A27,$C$3,'Gun v Gun'!$B$2:$B27,C13,'Gun v Gun'!$F$2:$F27,"atk")),) -> 0.575 | U13: =iferror(SUMIFS('Gun v Gun'!$C$2:$C27,'Gun v Gun'!$A$2:$A27,$C$3,'Gun v Gun'!$B$2:$B27,C13,'Gun v Gun'!$F$2:$F27,"def")/(SUMIFS('Gun v Gun'!$C$2:$C27,'Gun v Gun'!$A$2:$A27,$C$3,'Gun v Gun'!$B$2:$B27,C13,'Gun v Gun'!$F$2:$F27,"def")+SUMIFS('Gun v Gun'!$D$2:$D27,'Gun v Gun'!$A$2:$A27,$C$3,'Gun v Gun'!$B$2:$B27,C13,'Gun v Gun'!$F$2:$F27,"def")),) -> 0.67346939 | V13: =iferror(SUMIFS(Antieco!$C$2:$C27,Antieco!$A$2:$A27,$C$3,Antieco!$B$2:$B27,C13)/(SUMIFS(Antieco!$C$2:$C27,Antieco!$A$2:$A27,$C$3,Antieco!$B$2:$B27,C13)+SUMIFS(Antieco!$D$2:$D27,Antieco!$A$2:$A27,$C$3,Antieco!$B$2:$B27,C13)),) -> 0.77777778 | W13: =iferror(SUMIFS(Antieco!$C$2:$C27,Antieco!$A$2:$A27,$C$3,Antieco!$B$2:$B27,C13,Antieco!$F$2:$F27,"atk")/(SUMIFS(Antieco!$C$2:$C27,Antieco!$A$2:$A27,$C$3,Antieco!$B$2:$B27,C13,Antieco!$F$2:$F27,"atk")+SUMIFS(Antieco!$D$2:$D27,Antieco!$A$2:$A27,$C$3,Antieco!$B$2:$B27,C13,Antieco!$F$2:$F27,"atk")),) -> 0.83333333 | X13: =iferror(SUMIFS(Antieco!$C$2:$C27,Antieco!$A$2:$A27,$C$3,Antieco!$B$2:$B27,C13,Antieco!$F$2:$F27,"def")/(SUMIFS(Antieco!$C$2:$C27,Antieco!$A$2:$A27,$C$3,Antieco!$B$2:$B27,C13,Antieco!$F$2:$F27,"def")+SUMIFS(Antieco!$D$2:$D27,Antieco!$A$2:$A27,$C$3,Antieco!$B$2:$B27,C13,Antieco!$F$2:$F27,"def")),) -> 0.66666667 | Y13: =iferror(SUMIFS(ecos!$C$2:$C27,ecos!$A$2:$A27,$C$3,ecos!$B$2:$B27,C13)/(SUMIFS(ecos!$C$2:$C27,ecos!$A$2:$A27,$C$3,ecos!$B$2:$B27,C13)+SUMIFS(ecos!$D$2:$D27,ecos!$A$2:$A27,$C$3,ecos!$B$2:$B27,C13)),) -> 0.1875 | Z13: =iferror(SUMIFS(ecos!$C$2:$C27,ecos!$A$2:$A27,$C$3,ecos!$B$2:$B27,C13,ecos!$F$2:$F27,"atk")/(SUMIFS(ecos!$C$2:$C27,ecos!$A$2:$A27,$C$3,ecos!$B$2:$B27,C13,ecos!$F$2:$F27,"atk")+SUMIFS(ecos!$D$2:$D27,ecos!$A$2:$A27,$C$3,ecos!$B$2:$B27,C13,ecos!$F$2:$F27,"atk")),) -> 0 | AA13: =iferror(SUMIFS(ecos!$C$2:$C27,ecos!$A$2:$A27,$C$3,ecos!$B$2:$B27,C13,ecos!$F$2:$F27,"def")/(SUMIFS(ecos!$C$2:$C27,ecos!$A$2:$A27,$C$3,ecos!$B$2:$B27,C13,ecos!$F$2:$F27,"def")+SUMIFS(ecos!$D$2:$D27,ecos!$A$2:$A27,$C$3,ecos!$B$2:$B27,C13,ecos!$F$2:$F27,"def")),) -> 0.6 | AC13: Corrode | AE13: {=SUMIFS('Post Plants'!$D$2:$D27,'Post Plants'!$B$2:$B27,AC13:AC21,'Post Plants'!$A$2:$A27,$C$3)} -> 35 | AF13: 60 | AG13: 5.8333333 | AH13: =iferror(SUMIFS('Post Plants'!$F$2:$F27,'Post Plants'!$B$2:$B27,AC13:AC21,'Post Plants'!$A$2:$A27,$C$3)/SUMIFS('Post Plants'!$D$2:$D27,'Post Plants'!$B$2:$B27,AC13:AC21,'Post Plants'!$A$2:$A27,$C$3),) -> 0.62857143 | AI13: =iferror(SUMIFS('Post Plants'!$F$2:$F27,'Post Plants'!$B$2:$B27,AC13:AC21)/SUMIFS('Post Plants'!$D$2:$D27,'Post Plants'!$B$2:$B27,AC13:AC21),) -> 0.68778281 | AJ13: {=XLOOKUP($C$3,'Post Ranking'!M3:M27,'Post Ranking'!$F$3:$F27)} -> 9 | AK13: {=SUMIFS('Post Plants'!$J$2:$J27,'Post Plants'!$B$2:$B27,AC13:AC21,'Post Plants'!$A$2:$A27,$C$3)} -> 38 | AL13: 66 | AM13: 6.3333333 | AN13: =iferror(SUMIFS('Post Plants'!$L$2:$L27,'Post Plants'!$B$2:$B27,AC13:AC21,'Post Plants'!$A$2:$A27,$C$3)/SUMIFS('Post Plants'!$J$2:$J27,'Post Plants'!$B$2:$B27,AC13:AC21,'Post Plants'!$A$2:$A27,$C$3),) -> 0.47368421 | AO13: =iferror(SUMIFS('Post Plants'!$L$2:$L27,'Post Plants'!$B$2:$B27,AC13:AC21)/SUMIFS('Post Plants'!$J$2:$J27,'Post Plants'!$B$2:$B27,AC13:AC21),) -> 0.41588785 | AP13: {=XLOOKUP(C3,'Post Ranking'!X3:X27,'Post Ranking'!F3:F27)} -> 4
B14: #N/A | C14: Pearl | I14: 0 | J14: 0 | K14: 0 | L14: 0 | S14: =iferror(SUMIFS('Gun v Gun'!$C$2:$C27,'Gun v Gun'!$A$2:$A27,$C$3,'Gun v Gun'!$B$2:$B27,C14)/(SUMIFS('Gun v Gun'!$C$2:$C27,'Gun v Gun'!$A$2:$A27,$C$3,'Gun v Gun'!$B$2:$B27,C14)+SUMIFS('Gun v Gun'!$D$2:$D27,'Gun v Gun'!$A$2:$A27,$C$3,'Gun v Gun'!$B$2:$B27,C14)),) | T14: =iferror(SUMIFS('Gun v Gun'!$C$2:$C27,'Gun v Gun'!$A$2:$A27,$C$3,'Gun v Gun'!$B$2:$B27,C14,'Gun v Gun'!$F$2:$F27,"atk")/(SUMIFS('Gun v Gun'!$C$2:$C27,'Gun v Gun'!$A$2:$A27,$C$3,'Gun v Gun'!$B$2:$B27,C14,'Gun v Gun'!$F$2:$F27,"atk")+SUMIFS('Gun v Gun'!$D$2:$D27,'Gun v Gun'!$A$2:$A27,$C$3,'Gun v Gun'!$B$2:$B27,C14,'Gun v Gun'!$F$2:$F27,"atk")),) | U14: =iferror(SUMIFS('Gun v Gun'!$C$2:$C27,'Gun v Gun'!$A$2:$A27,$C$3,'Gun v Gun'!$B$2:$B27,C14,'Gun v Gun'!$F$2:$F27,"def")/(SUMIFS('Gun v Gun'!$C$2:$C27,'Gun v Gun'!$A$2:$A27,$C$3,'Gun v Gun'!$B$2:$B27,C14,'Gun v Gun'!$F$2:$F27,"def")+SUMIFS('Gun v Gun'!$D$2:$D27,'Gun v Gun'!$A$2:$A27,$C$3,'Gun v Gun'!$B$2:$B27,C14,'Gun v Gun'!$F$2:$F27,"def")),) | V14: =iferror(SUMIFS(Antieco!$C$2:$C27,Antieco!$A$2:$A27,$C$3,Antieco!$B$2:$B27,C14)/(SUMIFS(Antieco!$C$2:$C27,Antieco!$A$2:$A27,$C$3,Antieco!$B$2:$B27,C14)+SUMIFS(Antieco!$D$2:$D27,Antieco!$A$2:$A27,$C$3,Antieco!$B$2:$B27,C14)),) | W14: =iferror(SUMIFS(Antieco!$C$2:$C27,Antieco!$A$2:$A27,$C$3,Antieco!$B$2:$B27,C14,Antieco!$F$2:$F27,"atk")/(SUMIFS(Antieco!$C$2:$C27,Antieco!$A$2:$A27,$C$3,Antieco!$B$2:$B27,C14,Antieco!$F$2:$F27,"atk")+SUMIFS(Antieco!$D$2:$D27,Antieco!$A$2:$A27,$C$3,Antieco!$B$2:$B27,C14,Antieco!$F$2:$F27,"atk")),) | X14: =iferror(SUMIFS(Antieco!$C$2:$C27,Antieco!$A$2:$A27,$C$3,Antieco!$B$2:$B27,C14,Antieco!$F$2:$F27,"def")/(SUMIFS(Antieco!$C$2:$C27,Antieco!$A$2:$A27,$C$3,Antieco!$B$2:$B27,C14,Antieco!$F$2:$F27,"def")+SUMIFS(Antieco!$D$2:$D27,Antieco!$A$2:$A27,$C$3,Antieco!$B$2:$B27,C14,Antieco!$F$2:$F27,"def")),) | Y14: =iferror(SUMIFS(ecos!$C$2:$C27,ecos!$A$2:$A27,$C$3,ecos!$B$2:$B27,C14)/(SUMIFS(ecos!$C$2:$C27,ecos!$A$2:$A27,$C$3,ecos!$B$2:$B27,C14)+SUMIFS(ecos!$D$2:$D27,ecos!$A$2:$A27,$C$3,ecos!$B$2:$B27,C14)),) | Z14: =iferror(SUMIFS(ecos!$C$2:$C27,ecos!$A$2:$A27,$C$3,ecos!$B$2:$B27,C14,ecos!$F$2:$F27,"atk")/(SUMIFS(ecos!$C$2:$C27,ecos!$A$2:$A27,$C$3,ecos!$B$2:$B27,C14,ecos!$F$2:$F27,"atk")+SUMIFS(ecos!$D$2:$D27,ecos!$A$2:$A27,$C$3,ecos!$B$2:$B27,C14,ecos!$F$2:$F27,"atk")),) | AA14: =iferror(SUMIFS(ecos!$C$2:$C27,ecos!$A$2:$A27,$C$3,ecos!$B$2:$B27,C14,ecos!$F$2:$F27,"def")/(SUMIFS(ecos!$C$2:$C27,ecos!$A$2:$A27,$C$3,ecos!$B$2:$B27,C14,ecos!$F$2:$F27,"def")+SUMIFS(ecos!$D$2:$D27,ecos!$A$2:$A27,$C$3,ecos!$B$2:$B27,C14,ecos!$F$2:$F27,"def")),) | AC14: Pearl | AE14: {=SUMIFS('Post Plants'!$D$2:$D27,'Post Plants'!$B$2:$B27,AC14:AC22,'Post Plants'!$A$2:$A27,$C$3)} -> 0 | AF14: 0 | AG14: 0 | AH14: =iferror(SUMIFS('Post Plants'!$F$2:$F27,'Post Plants'!$B$2:$B27,AC14:AC22,'Post Plants'!$A$2:$A27,$C$3)/SUMIFS('Post Plants'!$D$2:$D27,'Post Plants'!$B$2:$B27,AC14:AC22,'Post Plants'!$A$2:$A27,$C$3),) | AI14: =iferror(SUMIFS('Post Plants'!$F$2:$F27,'Post Plants'!$B$2:$B27,AC14:AC22)/SUMIFS('Post Plants'!$D$2:$D27,'Post Plants'!$B$2:$B27,AC14:AC22),) -> 0.82051282 | AJ14: {=XLOOKUP($C$3,'Post Ranking'!N3:N27,'Post Ranking'!$F$3:$F27)} -> #N/A | AK14: {=SUMIFS('Post Plants'!$J$2:$J27,'Post Plants'!$B$2:$B27,AC14:AC22,'Post Plants'!$A$2:$A27,$C$3)} -> 0 | AL14: 0 | AM14: 0 | AN14: =iferror(SUMIFS('Post Plants'!$L$2:$L27,'Post Plants'!$B$2:$B27,AC14:AC22,'Post Plants'!$A$2:$A27,$C$3)/SUMIFS('Post Plants'!$J$2:$J27,'Post Plants'!$B$2:$B27,AC14:AC22,'Post Plants'!$A$2:$A27,$C$3),) | AO14: =iferror(SUMIFS('Post Plants'!$L$2:$L27,'Post Plants'!$B$2:$B27,AC14:AC22)/SUMIFS('Post Plants'!$J$2:$J27,'Post Plants'!$B$2:$B27,AC14:AC22),) -> 0.53571429 | AP14: {=XLOOKUP(C3,'Post Ranking'!Y3:Y27,'Post Ranking'!F3:F27)} -> #N/A
B15: Viper,Yoru,Astra,Fade,Vyse | C15: Split | D15: =IFERROR(__xludf.DUMMYFUNCTION("""COMPUTED_VALUE"""),"") | E15: =IFERROR(__xludf.DUMMYFUNCTION("""COMPUTED_VALUE"""),"") | F15: =IFERROR(__xludf.DUMMYFUNCTION("""COMPUTED_VALUE"""),"") | G15: =IFERROR(__xludf.DUMMYFUNCTION("""COMPUTED_VALUE"""),"") | H15: =IFERROR(__xludf.DUMMYFUNCTION("""COMPUTED_VALUE"""),"") | I15: 1 | J15: 1 | K15: 0 | L15: 1 | M15: 0.40909091 | N15: 0.16666667 | O15: 0.7 | P15: 0.5 | Q15: 0 | R15: 1 | S15: =iferror(SUMIFS('Gun v Gun'!$C$2:$C27,'Gun v Gun'!$A$2:$A27,$C$3,'Gun v Gun'!$B$2:$B27,C15)/(SUMIFS('Gun v Gun'!$C$2:$C27,'Gun v Gun'!$A$2:$A27,$C$3,'Gun v Gun'!$B$2:$B27,C15)+SUMIFS('Gun v Gun'!$D$2:$D27,'Gun v Gun'!$A$2:$A27,$C$3,'Gun v Gun'!$B$2:$B27,C15)),) -> 0.375 | T15: =iferror(SUMIFS('Gun v Gun'!$C$2:$C27,'Gun v Gun'!$A$2:$A27,$C$3,'Gun v Gun'!$B$2:$B27,C15,'Gun v Gun'!$F$2:$F27,"atk")/(SUMIFS('Gun v Gun'!$C$2:$C27,'Gun v Gun'!$A$2:$A27,$C$3,'Gun v Gun'!$B$2:$B27,C15,'Gun v Gun'!$F$2:$F27,"atk")+SUMIFS('Gun v Gun'!$D$2:$D27,'Gun v Gun'!$A$2:$A27,$C$3,'Gun v Gun'!$B$2:$B27,C15,'Gun v Gun'!$F$2:$F27,"atk")),0) -> 0.22222222 | U15: =iferror(SUMIFS('Gun v Gun'!$C$2:$C27,'Gun v Gun'!$A$2:$A27,$C$3,'Gun v Gun'!$B$2:$B27,C15,'Gun v Gun'!$F$2:$F27,"def")/(SUMIFS('Gun v Gun'!$C$2:$C27,'Gun v Gun'!$A$2:$A27,$C$3,'Gun v Gun'!$B$2:$B27,C15,'Gun v Gun'!$F$2:$F27,"def")+SUMIFS('Gun v Gun'!$D$2:$D27,'Gun v Gun'!$A$2:$A27,$C$3,'Gun v Gun'!$B$2:$B27,C15,'Gun v Gun'!$F$2:$F27,"def")),) -> 0.57142857 | V15: =iferror(SUMIFS(Antieco!$C$2:$C27,Antieco!$A$2:$A27,$C$3,Antieco!$B$2:$B27,C15)/(SUMIFS(Antieco!$C$2:$C27,Antieco!$A$2:$A27,$C$3,Antieco!$B$2:$B27,C15)+SUMIFS(Antieco!$D$2:$D27,Antieco!$A$2:$A27,$C$3,Antieco!$B$2:$B27,C15)),) -> 1 | W15: =iferror(SUMIFS(Antieco!$C$2:$C27,Antieco!$A$2:$A27,$C$3,Antieco!$B$2:$B27,C15,Antieco!$F$2:$F27,"atk")/(SUMIFS(Antieco!$C$2:$C27,Antieco!$A$2:$A27,$C$3,Antieco!$B$2:$B27,C15,Antieco!$F$2:$F27,"atk")+SUMIFS(Antieco!$D$2:$D27,Antieco!$A$2:$A27,$C$3,Antieco!$B$2:$B27,C15,Antieco!$F$2:$F27,"atk")),) -> 1 | X15: =iferror(SUMIFS(Antieco!$C$2:$C27,Antieco!$A$2:$A27,$C$3,Antieco!$B$2:$B27,C15,Antieco!$F$2:$F27,"def")/(SUMIFS(Antieco!$C$2:$C27,Antieco!$A$2:$A27,$C$3,Antieco!$B$2:$B27,C15,Antieco!$F$2:$F27,"def")+SUMIFS(Antieco!$D$2:$D27,Antieco!$A$2:$A27,$C$3,Antieco!$B$2:$B27,C15,Antieco!$F$2:$F27,"def")),) | Y15: =iferror(SUMIFS(ecos!$C$2:$C27,ecos!$A$2:$A27,$C$3,ecos!$B$2:$B27,C15)/(SUMIFS(ecos!$C$2:$C27,ecos!$A$2:$A27,$C$3,ecos!$B$2:$B27,C15)+SUMIFS(ecos!$D$2:$D27,ecos!$A$2:$A27,$C$3,ecos!$B$2:$B27,C15)),) -> 0 | Z15: =iferror(SUMIFS(ecos!$C$2:$C27,ecos!$A$2:$A27,$C$3,ecos!$B$2:$B27,C15,ecos!$F$2:$F27,"atk")/(SUMIFS(ecos!$C$2:$C27,ecos!$A$2:$A27,$C$3,ecos!$B$2:$B27,C15,ecos!$F$2:$F27,"atk")+SUMIFS(ecos!$D$2:$D27,ecos!$A$2:$A27,$C$3,ecos!$B$2:$B27,C15,ecos!$F$2:$F27,"atk")),) -> 0 | AA15: =iferror(SUMIFS(ecos!$C$2:$C27,ecos!$A$2:$A27,$C$3,ecos!$B$2:$B27,C15,ecos!$F$2:$F27,"def")/(SUMIFS(ecos!$C$2:$C27,ecos!$A$2:$A27,$C$3,ecos!$B$2:$B27,C15,ecos!$F$2:$F27,"def")+SUMIFS(ecos!$D$2:$D27,ecos!$A$2:$A27,$C$3,ecos!$B$2:$B27,C15,ecos!$F$2:$F27,"def")),) | AC15: Split | AE15: {=SUMIFS('Post Plants'!$D$2:$D27,'Post Plants'!$B$2:$B27,AC15:AC23,'Post Plants'!$A$2:$A27,$C$3)} -> 6 | AF15: 12 | AG15: 6 | AH15: =iferror(SUMIFS('Post Plants'!$F$2:$F27,'Post Plants'!$B$2:$B27,AC15:AC23,'Post Plants'!$A$2:$A27,$C$3)/SUMIFS('Post Plants'!$D$2:$D27,'Post Plants'!$B$2:$B27,AC15:AC23,'Post Plants'!$A$2:$A27,$C$3),) -> 0.33333333 | AI15: =iferror(SUMIFS('Post Plants'!$F$2:$F27,'Post Plants'!$B$2:$B27,AC15:AC23)/SUMIFS('Post Plants'!$D$2:$D27,'Post Plants'!$B$2:$B27,AC15:AC23),) -> 0.75221239 | AJ15: {=XLOOKUP($C$3,'Post Ranking'!O3:O27,'Post Ranking'!$F$3:$F27)} -> 10 | AK15: {=SUMIFS('Post Plants'!$J$2:$J27,'Post Plants'!$B$2:$B27,AC15:AC23,'Post Plants'!$A$2:$A27,$C$3)} -> 6 | AL15: 10 | AM15: 6 | AN15: =iferror(SUMIFS('Post Plants'!$L$2:$L27,'Post Plants'!$B$2:$B27,AC15:AC23,'Post Plants'!$A$2:$A27,$C$3)/SUMIFS('Post Plants'!$J$2:$J27,'Post Plants'!$B$2:$B27,AC15:AC23,'Post Plants'!$A$2:$A27,$C$3),) -> 0.5 | AO15: =iferror(SUMIFS('Post Plants'!$L$2:$L27,'Post Plants'!$B$2:$B27,AC15:AC23)/SUMIFS('Post Plants'!$J$2:$J27,'Post Plants'!$B$2:$B27,AC15:AC23),) -> 0.32291667 | AP15: {=XLOOKUP(C3,'Post Ranking'!Z3:Z27,'Post Ranking'!F3:F27)} -> 2
C16: All Maps | J16: =SUM(J7:J15) -> 31 | K16: =SUM(K7:K15) -> 18 | L16: =SUM(L7:L15) -> 13 | M16: =SUM(SelectedTeamStats!I2:I27)/(SUM(SelectedTeamStats!I2:I27)+sum(SelectedTeamStats!J2:J27)) -> 0.55226209 | N16: =SUM(SelectedTeamStats!O2:O27)/(SUM(SelectedTeamStats!O2:O27)+sum(SelectedTeamStats!P2:P27)) -> 0.48717949 | O16: =SUM(SelectedTeamStats!Q2:Q27)/(SUM(SelectedTeamStats!Q2:Q27)+sum(SelectedTeamStats!R2:R27)) -> 0.61398176 | P16: =sum(SelectedTeamStats!M2:N27)/(SUM(SelectedTeamStats!M2:N27)+SUM(SelectedTeamStats!S2:T27)) -> 0.56451613 | Q16: =sum(SelectedTeamStats!M2:M27)/(SUM(SelectedTeamStats!M2:M27)+SUM(SelectedTeamStats!T2:T27)) -> 0.4516129 | R16: =sum(SelectedTeamStats!N2:N27)/(SUM(SelectedTeamStats!N2:N27)+SUM(SelectedTeamStats!S2:S27)) -> 0.67741935 | S16: =SUMIFS('Gun v Gun'!$C$2:$C27,'Gun v Gun'!$A$2:$A27,$C$3)/(SUMIFS('Gun v Gun'!$C$2:$C27,'Gun v Gun'!$A$2:$A27,$C$3)+SUMIFS('Gun v Gun'!$D$2:$D27,'Gun v Gun'!$A$2:$A27,$C$3)) -> 0.5625 | T16: =SUMIFS('Gun v Gun'!$C$2:$C27,'Gun v Gun'!$A$2:$A27,$C$3,'Gun v Gun'!$F$2:$F27,"atk")/(SUMIFS('Gun v Gun'!$C$2:$C27,'Gun v Gun'!$A$2:$A27,$C$3,'Gun v Gun'!$F$2:$F27,"atk")+SUMIFS('Gun v Gun'!$D$2:$D27,'Gun v Gun'!$A$2:$A27,$C$3,'Gun v Gun'!$F$2:$F27,"atk")) -> 0.51627907 | U16: =SUMIFS('Gun v Gun'!$C$2:$C27,'Gun v Gun'!$A$2:$A27,$C$3,'Gun v Gun'!$F$2:$F27,"def")/(SUMIFS('Gun v Gun'!$C$2:$C27,'Gun v Gun'!$A$2:$A27,$C$3,'Gun v Gun'!$F$2:$F27,"def")+SUMIFS('Gun v Gun'!$D$2:$D27,'Gun v Gun'!$A$2:$A27,$C$3,'Gun v Gun'!$F$2:$F27,"def")) -> 0.60515021 | V16: =SUMIFS(Antieco!$C$2:$C27,Antieco!$A$2:$A27,$C$3)/(SUMIFS(Antieco!$C$2:$C27,Antieco!$A$2:$A27,$C$3)+SUMIFS(Antieco!$D$2:$D27,Antieco!$A$2:$A27,$C$3)) -> 0.82857143 | W16: =SUMIFS(Antieco!$C$2:$C27,Antieco!$A$2:$A27,$C$3,Antieco!$F$2:$F27,"atk")/(SUMIFS(Antieco!$C$2:$C27,Antieco!$A$2:$A27,$C$3,Antieco!$F$2:$F27,"atk")+SUMIFS(Antieco!$D$2:$D27,Antieco!$A$2:$A27,$C$3,Antieco!$F$2:$F27,"atk")) -> 0.84615385 | X16: =SUMIFS(Antieco!$C$2:$C27,Antieco!$A$2:$A27,$C$3,Antieco!$F$2:$F27,"def")/(SUMIFS(Antieco!$C$2:$C27,Antieco!$A$2:$A27,$C$3,Antieco!$F$2:$F27,"def")+SUMIFS(Antieco!$D$2:$D27,Antieco!$A$2:$A27,$C$3,Antieco!$F$2:$F27,"def")) -> 0.80645161 | Y16: =SUMIFS(ecos!$C$2:$C27,ecos!$A$2:$A27,$C$3)/(SUMIFS(ecos!$C$2:$C27,ecos!$A$2:$A27,$C$3)+SUMIFS(ecos!$D$2:$D27,ecos!$A$2:$A27,$C$3)) -> 0.14754098 | Z16: =SUMIFS(ecos!$C$2:$C27,ecos!$A$2:$A27,$C$3,ecos!$F$2:$F27,"atk")/(SUMIFS(ecos!$C$2:$C27,ecos!$A$2:$A27,$C$3,ecos!$F$2:$F27,"atk")+SUMIFS(ecos!$D$2:$D27,ecos!$A$2:$A27,$C$3,ecos!$F$2:$F27,"atk")) -> 0.057142857 | AA16: =SUMIFS(ecos!$C$2:$C27,ecos!$A$2:$A27,$C$3,ecos!$F$2:$F27,"def")/(SUMIFS(ecos!$C$2:$C27,ecos!$A$2:$A27,$C$3,ecos!$F$2:$F27,"def")+SUMIFS(ecos!$D$2:$D27,ecos!$A$2:$A27,$C$3,ecos!$F$2:$F27,"def")) -> 0.26923077 | AC16: All Maps | AE16: =SUM(AE7:AE15) -> 198 | AF16: =SUM(AF7:AF15) -> 312 | AG16: =AE16/J16 -> 6.3870968 | AH16: =SUMIF('Post Plants'!A2:A27,C3,'Post Plants'!F2:F27)/SUMIF('Post Plants'!A2:A27,C3,'Post Plants'!D2:D27) -> 0.65151515 | AI16: =SUM('Post Plants'!F2:F27)/SUM('Post Plants'!D2:D27) -> 0.71555384 | AJ16: {=XLOOKUP(C3,'Post Rank General'!F2:F27,'Post Rank General'!E2:E27)} -> 13 | AK16: =SUM(AK7:AK15) -> 190 | AL16: =SUM(AL7:AL15) -> 329 | AM16: =AK16/J16 -> 6.1290323 | AN16: =SUMIF('Post Plants'!A2:A27,C3,'Post Plants'!L2:L27)/SUMIF('Post Plants'!A2:A27,C3,'Post Plants'!J2:J27) -> 0.40526316 | AO16: =SUM('Post Plants'!L2:L27)/SUM('Post Plants'!J2:J27) -> 0.36208369 | AP16: {=XLOOKUP(C3,'Post Rank General'!G2:G27,'Post Rank General'!E2:E27)} -> 3
C18: Statistics Per Player | S18: Team XvY | Z18: Team XvY vs Attending Average | AG18: Attending Team Average
C19: Players | D19: Agents | I19: r | J19: K/D | K19: KA/D | L19: KAST | M19: fk/r | N19: fd/r | O19: fk/fd | P19: CL% | Q19: AWP% | S19: X v Y | T19: 5 | U19: 4 | V19: 3 | W19: 2 | X19: 1 | Z19: X v Y | AA19: 5 | AB19: 4 | AC19: 3 | AD19: 2 | AE19: 1 | AG19: X v Y | AH19: 5 | AI19: 4 | AJ19: 3 | AK19: 2 | AL19: 1
C20: =IFERROR(__xludf.DUMMYFUNCTION("FILTER('Player Stats'!B2:B27,REGEXMATCH('Player Stats'!A2:A27,C3))"),"GSR") -> GSR | D20: =IFERROR(__xludf.DUMMYFUNCTION("arrayformula(xlookup(split(JOIN("","",QUERY(Picks!$A$2:$F27, ""select C where A = '""&C20&""' order by F desc limit 5"")),"",""),Assets!$A$2:$A$28,Assets!$C$2:$C$28,))"),"") | E20: =IFERROR(__xludf.DUMMYFUNCTION("""COMPUTED_VALUE"""),"") | F20: =IFERROR(__xludf.DUMMYFUNCTION("""COMPUTED_VALUE"""),"") | G20: =IFERROR(__xludf.DUMMYFUNCTION("""COMPUTED_VALUE"""),"") | H20: =IFERROR(__xludf.DUMMYFUNCTION("""COMPUTED_VALUE"""),"") | I20: {=XLOOKUP(C20:C26,'Player Stats'!B2:B27,'Player Stats'!E2:E27,)} -> 641 | J20: {=XLOOKUP(C20:C26,'Player Stats'!B2:B27,'Player Stats'!K2:K27,)} -> 1.2273782 | K20: {=XLOOKUP(C20:C26,'Player Stats'!B2:B27,'Player Stats'!L2:L27,)} -> 1.6542923 | L20: {=XLOOKUP(C20:C27,'Player Stats'!B2:B27,'Player Stats'!T2:T27,)} -> 0.75 | M20: {=XLOOKUP(C20:C26,'Player Stats'!B2:B27,'Player Stats'!N2:N27,)} -> 0.15132605 | N20: {=XLOOKUP(C20:C26,'Player Stats'!B2:B27,'Player Stats'!O2:O27,)} -> 0.12636505 | O20: {=XLOOKUP(C20:C26,'Player Stats'!B2:B27,'Player Stats'!P2:P27,)} -> 0.54494382 | P20: {=XLOOKUP(C20:C26,'Player Stats'!B2:B27,'Player Stats'!S2:S27,)} -> 0.17777778 | Q20: {=iferror(XLOOKUP(C20:C26,Guns!G2:G27,Guns!L2:L27)/100,"")} -> 0.0546 | S20: 5 | T20: =SUM(SelectedTeamStats!I2:I27)/(SUM(SelectedTeamStats!I2:I27)+sum(SelectedTeamStats!J2:J27)) -> 0.55226209 | U20: =SUMIFS(XvY!$F$2:$F27,XvY!$A$2:$A27,$C$3,XvY!$C$2:$C27,$S20,XvY!$D$2:$D27,U$19)/(SUMIFS(XvY!$F$2:$F27,XvY!$A$2:$A27,$C$3,XvY!$C$2:$C27,$S20,XvY!$D$2:$D27,U$19)+SUMIFS(XvY!$G$2:$G27,XvY!$A$2:$A27,$C$3,XvY!$C$2:$C27,$S20,XvY!$D$2:$D27,U$19)) -> 0.79032258 | V20: =SUMIFS(XvY!$F$2:$F27,XvY!$A$2:$A27,$C$3,XvY!$C$2:$C27,$S20,XvY!$D$2:$D27,V$19)/(SUMIFS(XvY!$F$2:$F27,XvY!$A$2:$A27,$C$3,XvY!$C$2:$C27,$S20,XvY!$D$2:$D27,V$19)+SUMIFS(XvY!$G$2:$G27,XvY!$A$2:$A27,$C$3,XvY!$C$2:$C27,$S20,XvY!$D$2:$D27,V$19)) -> 0.97777778 | W20: =SUMIFS(XvY!$F$2:$F27,XvY!$A$2:$A27,$C$3,XvY!$C$2:$C27,$S20,XvY!$D$2:$D27,W$19)/(SUMIFS(XvY!$F$2:$F27,XvY!$A$2:$A27,$C$3,XvY!$C$2:$C27,$S20,XvY!$D$2:$D27,W$19)+SUMIFS(XvY!$G$2:$G27,XvY!$A$2:$A27,$C$3,XvY!$C$2:$C27,$S20,XvY!$D$2:$D27,W$19)) -> 1 | X20: =SUMIFS(XvY!$F$2:$F27,XvY!$A$2:$A27,$C$3,XvY!$C$2:$C27,$S20,XvY!$D$2:$D27,X$19)/(SUMIFS(XvY!$F$2:$F27,XvY!$A$2:$A27,$C$3,XvY!$C$2:$C27,$S20,XvY!$D$2:$D27,X$19)+SUMIFS(XvY!$G$2:$G27,XvY!$A$2:$A27,$C$3,XvY!$C$2:$C27,$S20,XvY!$D$2:$D27,X$19)) -> 1 | Z20: 5 | AA20: =T20-AH20 -> 0.0042257594 | AB20: =U20-AI20 -> 0.024481204 | AC20: =V20-AJ20 -> 0.067842773 | AD20: =W20-AK20 -> 0.017175573 | AE20: =X20-AL20 -> 0 | AG20: 5 | AH20: =SUM('5v5'!I2:I27)/(SUM('5v5'!I2:J27)) -> 0.54803633 | AI20: =SUMIFS(XvY!$F$2:$F27,XvY!$C$2:$C27,$S20,XvY!$D$2:$D27,U$19)/(SUMIFS(XvY!$F$2:$F27,XvY!$C$2:$C27,$S20,XvY!$D$2:$D27,U$19)+SUMIFS(XvY!$G$2:$G27,XvY!$C$2:$C27,$S20,XvY!$D$2:$D27,U$19)) -> 0.76584138 | AJ20: =SUMIFS(XvY!$F$2:$F27,XvY!$C$2:$C27,$S20,XvY!$D$2:$D27,V$19)/(SUMIFS(XvY!$F$2:$F27,XvY!$C$2:$C27,$S20,XvY!$D$2:$D27,V$19)+SUMIFS(XvY!$G$2:$G27,XvY!$C$2:$C27,$S20,XvY!$D$2:$D27,V$19)) -> 0.909935 | AK20: =SUMIFS(XvY!$F$2:$F27,XvY!$C$2:$C27,$S20,XvY!$D$2:$D27,W$19)/(SUMIFS(XvY!$F$2:$F27,XvY!$C$2:$C27,$S20,XvY!$D$2:$D27,W$19)+SUMIFS(XvY!$G$2:$G27,XvY!$C$2:$C27,$S20,XvY!$D$2:$D27,W$19)) -> 0.98282443 | AL20: =SUMIFS(XvY!$F$2:$F27,XvY!$C$2:$C27,$S20,XvY!$D$2:$D27,X$19)/(SUMIFS(XvY!$F$2:$F27,XvY!$C$2:$C27,$S20,XvY!$D$2:$D27,X$19)+SUMIFS(XvY!$G$2:$G27,XvY!$C$2:$C27,$S20,XvY!$D$2:$D27,X$19)) -> 1
C21: =IFERROR(__xludf.DUMMYFUNCTION("""COMPUTED_VALUE"""),"rexxtoned") -> rexxtoned | D21: =IFERROR(__xludf.DUMMYFUNCTION("arrayformula(xlookup(split(JOIN("","",QUERY(Picks!$A$2:$F27, ""select C where A = '""&C21&""' order by F desc limit 5"")),"",""),Assets!$A$2:$A$28,Assets!$C$2:$C$28,))"),"") | E21: =IFERROR(__xludf.DUMMYFUNCTION("""COMPUTED_VALUE"""),"") | F21: =IFERROR(__xludf.DUMMYFUNCTION("""COMPUTED_VALUE"""),"") | G21: =IFERROR(__xludf.DUMMYFUNCTION("""COMPUTED_VALUE"""),"") | I21: 641 | J21: 1.2779221 | K21: 1.6571429 | L21: 0.75 | M21: 0.071762871 | N21: 0.054602184 | O21: 0.56790123 | P21: 0.12359551 | S21: 4 | T21: =SUMIFS(XvY!$F$2:$F27,XvY!$A$2:$A27,$C$3,XvY!$C$2:$C27,$S21,XvY!$D$2:$D27,T$19)/(SUMIFS(XvY!$F$2:$F27,XvY!$A$2:$A27,$C$3,XvY!$C$2:$C27,$S21,XvY!$D$2:$D27,T$19)+SUMIFS(XvY!$G$2:$G27,XvY!$A$2:$A27,$C$3,XvY!$C$2:$C27,$S21,XvY!$D$2:$D27,T$19)) -> 0.33701657 | U21: =SUMIFS(XvY!$F$2:$F27,XvY!$A$2:$A27,$C$3,XvY!$C$2:$C27,$S21,XvY!$D$2:$D27,U$19)/(SUMIFS(XvY!$F$2:$F27,XvY!$A$2:$A27,$C$3,XvY!$C$2:$C27,$S21,XvY!$D$2:$D27,U$19)+SUMIFS(XvY!$G$2:$G27,XvY!$A$2:$A27,$C$3,XvY!$C$2:$C27,$S21,XvY!$D$2:$D27,U$19)) -> 0.53846154 | V21: =SUMIFS(XvY!$F$2:$F27,XvY!$A$2:$A27,$C$3,XvY!$C$2:$C27,$S21,XvY!$D$2:$D27,V$19)/(SUMIFS(XvY!$F$2:$F27,XvY!$A$2:$A27,$C$3,XvY!$C$2:$C27,$S21,XvY!$D$2:$D27,V$19)+SUMIFS(XvY!$G$2:$G27,XvY!$A$2:$A27,$C$3,XvY!$C$2:$C27,$S21,XvY!$D$2:$D27,V$19)) -> 0.81521739 | W21: =SUMIFS(XvY!$F$2:$F27,XvY!$A$2:$A27,$C$3,XvY!$C$2:$C27,$S21,XvY!$D$2:$D27,W$19)/(SUMIFS(XvY!$F$2:$F27,XvY!$A$2:$A27,$C$3,XvY!$C$2:$C27,$S21,XvY!$D$2:$D27,W$19)+SUMIFS(XvY!$G$2:$G27,XvY!$A$2:$A27,$C$3,XvY!$C$2:$C27,$S21,XvY!$D$2:$D27,W$19)) -> 0.98648649 | X21: =SUMIFS(XvY!$F$2:$F27,XvY!$A$2:$A27,$C$3,XvY!$C$2:$C27,$S21,XvY!$D$2:$D27,X$19)/(SUMIFS(XvY!$F$2:$F27,XvY!$A$2:$A27,$C$3,XvY!$C$2:$C27,$S21,XvY!$D$2:$D27,X$19)+SUMIFS(XvY!$G$2:$G27,XvY!$A$2:$A27,$C$3,XvY!$C$2:$C27,$S21,XvY!$D$2:$D27,X$19)) -> 1 | Z21: 4 | AA21: =T21-AH21 -> 0.024801442 | AB21: =U21-AI21 -> 0.0016928858 | AC21: =V21-AJ21 -> 0.03035982 | AD21: =W21-AK21 -> 0.036116898 | AE21: =X21-AL21 -> 0 | AG21: 4 | AH21: =SUMIFS(XvY!$F$2:$F27,XvY!$C$2:$C27,$S21,XvY!$D$2:$D27,T$19)/(SUMIFS(XvY!$F$2:$F27,XvY!$C$2:$C27,$S21,XvY!$D$2:$D27,T$19)+SUMIFS(XvY!$G$2:$G27,XvY!$C$2:$C27,$S21,XvY!$D$2:$D27,T$19)) -> 0.31221513 | AI21: =SUMIFS(XvY!$F$2:$F27,XvY!$C$2:$C27,$S21,XvY!$D$2:$D27,U$19)/(SUMIFS(XvY!$F$2:$F27,XvY!$C$2:$C27,$S21,XvY!$D$2:$D27,U$19)+SUMIFS(XvY!$G$2:$G27,XvY!$C$2:$C27,$S21,XvY!$D$2:$D27,U$19)) -> 0.53676865 | AJ21: =SUMIFS(XvY!$F$2:$F27,XvY!$C$2:$C27,$S21,XvY!$D$2:$D27,V$19)/(SUMIFS(XvY!$F$2:$F27,XvY!$C$2:$C27,$S21,XvY!$D$2:$D27,V$19)+SUMIFS(XvY!$G$2:$G27,XvY!$C$2:$C27,$S21,XvY!$D$2:$D27,V$19)) -> 0.78485757 | AK21: =SUMIFS(XvY!$F$2:$F27,XvY!$C$2:$C27,$S21,XvY!$D$2:$D27,W$19)/(SUMIFS(XvY!$F$2:$F27,XvY!$C$2:$C27,$S21,XvY!$D$2:$D27,W$19)+SUMIFS(XvY!$G$2:$G27,XvY!$C$2:$C27,$S21,XvY!$D$2:$D27,W$19)) -> 0.95036959 | AL21: =SUMIFS(XvY!$F$2:$F27,XvY!$C$2:$C27,$S21,XvY!$D$2:$D27,X$19)/(SUMIFS(XvY!$F$2:$F27,XvY!$C$2:$C27,$S21,XvY!$D$2:$D27,X$19)+SUMIFS(XvY!$G$2:$G27,XvY!$C$2:$C27,$S21,XvY!$D$2:$D27,X$19)) -> 1
C22: =IFERROR(__xludf.DUMMYFUNCTION("""COMPUTED_VALUE"""),"Donatello") -> Donatello | D22: =IFERROR(__xludf.DUMMYFUNCTION("arrayformula(xlookup(split(JOIN("","",QUERY(Picks!$A$2:$F27, ""select C where A = '""&C22&""' order by F desc limit 5"")),"",""),Assets!$A$2:$A$28,Assets!$C$2:$C$28,))"),"") | E22: =IFERROR(__xludf.DUMMYFUNCTION("""COMPUTED_VALUE"""),"") | F22: =IFERROR(__xludf.DUMMYFUNCTION("""COMPUTED_VALUE"""),"") | G22: =IFERROR(__xludf.DUMMYFUNCTION("""COMPUTED_VALUE"""),"") | H22: =IFERROR(__xludf.DUMMYFUNCTION("""COMPUTED_VALUE"""),"") | I22: 641 | J22: 0.98964803 | K22: 1.2277433 | L22: 0.67 | M22: 0.1700468 | N22: 0.17316693 | O22: 0.49545455 | P22: 0.10810811 | Q22: 0.0234 | S22: 3 | T22: =SUMIFS(XvY!$F$2:$F27,XvY!$A$2:$A27,$C$3,XvY!$C$2:$C27,$S22,XvY!$D$2:$D27,T$19)/(SUMIFS(XvY!$F$2:$F27,XvY!$A$2:$A27,$C$3,XvY!$C$2:$C27,$S22,XvY!$D$2:$D27,T$19)+SUMIFS(XvY!$G$2:$G27,XvY!$A$2:$A27,$C$3,XvY!$C$2:$C27,$S22,XvY!$D$2:$D27,T$19)) -> 0.080645161 | U22: =SUMIFS(XvY!$F$2:$F27,XvY!$A$2:$A27,$C$3,XvY!$C$2:$C27,$S22,XvY!$D$2:$D27,U$19)/(SUMIFS(XvY!$F$2:$F27,XvY!$A$2:$A27,$C$3,XvY!$C$2:$C27,$S22,XvY!$D$2:$D27,U$19)+SUMIFS(XvY!$G$2:$G27,XvY!$A$2:$A27,$C$3,XvY!$C$2:$C27,$S22,XvY!$D$2:$D27,U$19)) -> 0.20792079 | V22: =SUMIFS(XvY!$F$2:$F27,XvY!$A$2:$A27,$C$3,XvY!$C$2:$C27,$S22,XvY!$D$2:$D27,V$19)/(SUMIFS(XvY!$F$2:$F27,XvY!$A$2:$A27,$C$3,XvY!$C$2:$C27,$S22,XvY!$D$2:$D27,V$19)+SUMIFS(XvY!$G$2:$G27,XvY!$A$2:$A27,$C$3,XvY!$C$2:$C27,$S22,XvY!$D$2:$D27,V$19)) -> 0.49504951 | W22: =SUMIFS(XvY!$F$2:$F27,XvY!$A$2:$A27,$C$3,XvY!$C$2:$C27,$S22,XvY!$D$2:$D27,W$19)/(SUMIFS(XvY!$F$2:$F27,XvY!$A$2:$A27,$C$3,XvY!$C$2:$C27,$S22,XvY!$D$2:$D27,W$19)+SUMIFS(XvY!$G$2:$G27,XvY!$A$2:$A27,$C$3,XvY!$C$2:$C27,$S22,XvY!$D$2:$D27,W$19)) -> 0.86153846 | X22: =SUMIFS(XvY!$F$2:$F27,XvY!$A$2:$A27,$C$3,XvY!$C$2:$C27,$S22,XvY!$D$2:$D27,X$19)/(SUMIFS(XvY!$F$2:$F27,XvY!$A$2:$A27,$C$3,XvY!$C$2:$C27,$S22,XvY!$D$2:$D27,X$19)+SUMIFS(XvY!$G$2:$G27,XvY!$A$2:$A27,$C$3,XvY!$C$2:$C27,$S22,XvY!$D$2:$D27,X$19)) -> 0.98630137 | Z22: 3 | AA22: =T22-AH22 -> -0.054122676 | AB22: =U22-AI22 -> -0.071914599 | AC22: =V22-AJ22 -> -0.043610289 | AD22: =W22-AK22 -> 0.058063977 | AE22: =X22-AL22 -> 0.00013784785 | AG22: 3 | AH22: =SUMIFS(XvY!$F$2:$F27,XvY!$C$2:$C27,$S22,XvY!$D$2:$D27,T$19)/(SUMIFS(XvY!$F$2:$F27,XvY!$C$2:$C27,$S22,XvY!$D$2:$D27,T$19)+SUMIFS(XvY!$G$2:$G27,XvY!$C$2:$C27,$S22,XvY!$D$2:$D27,T$19)) -> 0.13476784 | AI22: =SUMIFS(XvY!$F$2:$F27,XvY!$C$2:$C27,$S22,XvY!$D$2:$D27,U$19)/(SUMIFS(XvY!$F$2:$F27,XvY!$C$2:$C27,$S22,XvY!$D$2:$D27,U$19)+SUMIFS(XvY!$G$2:$G27,XvY!$C$2:$C27,$S22,XvY!$D$2:$D27,U$19)) -> 0.27983539 | AJ22: =SUMIFS(XvY!$F$2:$F27,XvY!$C$2:$C27,$S22,XvY!$D$2:$D27,V$19)/(SUMIFS(XvY!$F$2:$F27,XvY!$C$2:$C27,$S22,XvY!$D$2:$D27,V$19)+SUMIFS(XvY!$G$2:$G27,XvY!$C$2:$C27,$S22,XvY!$D$2:$D27,V$19)) -> 0.53865979 | AK22: =SUMIFS(XvY!$F$2:$F27,XvY!$C$2:$C27,$S22,XvY!$D$2:$D27,W$19)/(SUMIFS(XvY!$F$2:$F27,XvY!$C$2:$C27,$S22,XvY!$D$2:$D27,W$19)+SUMIFS(XvY!$G$2:$G27,XvY!$C$2:$C27,$S22,XvY!$D$2:$D27,W$19)) -> 0.80347448 | AL22: =SUMIFS(XvY!$F$2:$F27,XvY!$C$2:$C27,$S22,XvY!$D$2:$D27,X$19)/(SUMIFS(XvY!$F$2:$F27,XvY!$C$2:$C27,$S22,XvY!$D$2:$D27,X$19)+SUMIFS(XvY!$G$2:$G27,XvY!$C$2:$C27,$S22,XvY!$D$2:$D27,X$19)) -> 0.98616352
C23: =IFERROR(__xludf.DUMMYFUNCTION("""COMPUTED_VALUE"""),"NINJA") -> NINJA | D23: =IFERROR(__xludf.DUMMYFUNCTION("arrayformula(xlookup(split(JOIN("","",QUERY(Picks!$A$2:$F27, ""select C where A = '""&C23&""' order by F desc limit 5"")),"",""),Assets!$A$2:$A$28,Assets!$C$2:$C$28,))"),"") | E23: =IFERROR(__xludf.DUMMYFUNCTION("""COMPUTED_VALUE"""),"") | F23: =IFERROR(__xludf.DUMMYFUNCTION("""COMPUTED_VALUE"""),"") | G23: =IFERROR(__xludf.DUMMYFUNCTION("""COMPUTED_VALUE"""),"") | I23: 641 | J23: 1.1167883 | K23: 1.5863747 | L23: 0.75 | M23: 0.070202808 | N23: 0.067082683 | O23: 0.51136364 | P23: 0.13580247 | Q23: 0.0062 | S23: 2 | T23: =SUMIFS(XvY!$F$2:$F27,XvY!$A$2:$A27,$C$3,XvY!$C$2:$C27,$S23,XvY!$D$2:$D27,T$19)/(SUMIFS(XvY!$F$2:$F27,XvY!$A$2:$A27,$C$3,XvY!$C$2:$C27,$S23,XvY!$D$2:$D27,T$19)+SUMIFS(XvY!$G$2:$G27,XvY!$A$2:$A27,$C$3,XvY!$C$2:$C27,$S23,XvY!$D$2:$D27,T$19)) -> 0.03125 | U23: =SUMIFS(XvY!$F$2:$F27,XvY!$A$2:$A27,$C$3,XvY!$C$2:$C27,$S23,XvY!$D$2:$D27,U$19)/(SUMIFS(XvY!$F$2:$F27,XvY!$A$2:$A27,$C$3,XvY!$C$2:$C27,$S23,XvY!$D$2:$D27,U$19)+SUMIFS(XvY!$G$2:$G27,XvY!$A$2:$A27,$C$3,XvY!$C$2:$C27,$S23,XvY!$D$2:$D27,U$19)) -> 0.044117647 | V23: =SUMIFS(XvY!$F$2:$F27,XvY!$A$2:$A27,$C$3,XvY!$C$2:$C27,$S23,XvY!$D$2:$D27,V$19)/(SUMIFS(XvY!$F$2:$F27,XvY!$A$2:$A27,$C$3,XvY!$C$2:$C27,$S23,XvY!$D$2:$D27,V$19)+SUMIFS(XvY!$G$2:$G27,XvY!$A$2:$A27,$C$3,XvY!$C$2:$C27,$S23,XvY!$D$2:$D27,V$19)) -> 0.20987654 | W23: =SUMIFS(XvY!$F$2:$F27,XvY!$A$2:$A27,$C$3,XvY!$C$2:$C27,$S23,XvY!$D$2:$D27,W$19)/(SUMIFS(XvY!$F$2:$F27,XvY!$A$2:$A27,$C$3,XvY!$C$2:$C27,$S23,XvY!$D$2:$D27,W$19)+SUMIFS(XvY!$G$2:$G27,XvY!$A$2:$A27,$C$3,XvY!$C$2:$C27,$S23,XvY!$D$2:$D27,W$19)) -> 0.47945205 | X23: =SUMIFS(XvY!$F$2:$F27,XvY!$A$2:$A27,$C$3,XvY!$C$2:$C27,$S23,XvY!$D$2:$D27,X$19)/(SUMIFS(XvY!$F$2:$F27,XvY!$A$2:$A27,$C$3,XvY!$C$2:$C27,$S23,XvY!$D$2:$D27,X$19)+SUMIFS(XvY!$G$2:$G27,XvY!$A$2:$A27,$C$3,XvY!$C$2:$C27,$S23,XvY!$D$2:$D27,X$19)) -> 0.86666667 | Z23: 2 | AA23: =T23-AH23 -> 0.003277972 | AB23: =U23-AI23 -> -0.026700424 | AC23: =V23-AJ23 -> -0.050251389 | AD23: =W23-AK23 -> -0.075628159 | AE23: =X23-AL23 -> -0.029674797 | AG23: 2 | AH23: =SUMIFS(XvY!$F$2:$F27,XvY!$C$2:$C27,$S23,XvY!$D$2:$D27,T$19)/(SUMIFS(XvY!$F$2:$F27,XvY!$C$2:$C27,$S23,XvY!$D$2:$D27,T$19)+SUMIFS(XvY!$G$2:$G27,XvY!$C$2:$C27,$S23,XvY!$D$2:$D27,T$19)) -> 0.027972028 | AI23: =SUMIFS(XvY!$F$2:$F27,XvY!$C$2:$C27,$S23,XvY!$D$2:$D27,U$19)/(SUMIFS(XvY!$F$2:$F27,XvY!$C$2:$C27,$S23,XvY!$D$2:$D27,U$19)+SUMIFS(XvY!$G$2:$G27,XvY!$C$2:$C27,$S23,XvY!$D$2:$D27,U$19)) -> 0.070818071 | AJ23: =SUMIFS(XvY!$F$2:$F27,XvY!$C$2:$C27,$S23,XvY!$D$2:$D27,V$19)/(SUMIFS(XvY!$F$2:$F27,XvY!$C$2:$C27,$S23,XvY!$D$2:$D27,V$19)+SUMIFS(XvY!$G$2:$G27,XvY!$C$2:$C27,$S23,XvY!$D$2:$D27,V$19)) -> 0.26012793 | AK23: =SUMIFS(XvY!$F$2:$F27,XvY!$C$2:$C27,$S23,XvY!$D$2:$D27,W$19)/(SUMIFS(XvY!$F$2:$F27,XvY!$C$2:$C27,$S23,XvY!$D$2:$D27,W$19)+SUMIFS(XvY!$G$2:$G27,XvY!$C$2:$C27,$S23,XvY!$D$2:$D27,W$19)) -> 0.55508021 | AL23: =SUMIFS(XvY!$F$2:$F27,XvY!$C$2:$C27,$S23,XvY!$D$2:$D27,X$19)/(SUMIFS(XvY!$F$2:$F27,XvY!$C$2:$C27,$S23,XvY!$D$2:$D27,X$19)+SUMIFS(XvY!$G$2:$G27,XvY!$C$2:$C27,$S23,XvY!$D$2:$D27,X$19)) -> 0.89634146
